Workbook

Sheet unimed
AJ1: =SUM(AJ3:AJ8824) -> 24839.42 | AO1: =SUM(AO3:AO8824) -> 20302.693 | AP1: =SUM(AP3:AP8824) -> 19897.653 | AQ1: =SUM(AQ3:AQ8824) -> 4941.7667 | AR1: =AP1+AQ1 -> 24839.42
A2: Titular | E2: Fam. | F2: Carteira | I2: Nome | L2: Data Nascimento | N2: Idade | P2: CPF | S2: Data Inclusão | V2: Plano | W2: Dep | Y2: Parentesco | AC2: Verba | AH2: Qt | AI2: Valor | AJ2: Total | AK2: CPF Titular | AL2: Matricula Titular | AM2: Salário Titular | AN2: Plano Base Atlântico | AO2: Custo | AP2: CUSTO ATLANTICO | AQ2: DESCONTO COLABORADOR | AR2: Código
A3: JOAO | E3: 677 | F3: 0 | I3: Colaborador 1 | L3: 24/03/1991 | N3: 34 | P3: 000.000.000-00 | S3: 26/10/2021 | V3: M11 | W3: T | Y3: TITULAR | AC3: MENSALIDADE SAUDE-14 - MULTIPLAN CE ENFERMARIA SEM COPART COM OBST | AH3: 1 | AI3: 694.48 | AJ3: 694.48 | AK3: 000.000.000-00 | AL3: 1 | AM3: 5826.03 | AN3: =SUMIFS(planos!D:D,planos!B:B,"<="&unimed!N3,planos!C:C,">="&unimed!N3,planos!E:E,"Enfermaria sem coparticipação") -> 694.48106 | AO3: =IF(AJ3=0,0,IF(MID(AC3,1,15)="FATOR MODERADOR",AJ3,IF(AM3>=0,IF(AND(AM3>tabelas!$C$4,AM3<=tabelas!$C$5),(AN3)*tabelas!$D$4,IF(AND(AM3>=tabelas!$C$5,AM3<=tabelas!$C$6),(AN3)*tabelas!$D$5,IF(AND(AM3>=tabelas!$C$6,AM3<=tabelas!$C$7),(AN3)*tabelas!$D$6,IF(AND(AM3>0,AM3>tabelas!$C$7),(AN3)*tabelas!$D$7,0))))))) -> 590.3089 | AP3: =IF(MID(AC3,1,15)="FATOR MODERADOR",0,IF(MID(AC3,1,21)="RECOMPOSIÇÃO REAJUSTE",0,IF(AH3=1,AO3,AO3*AH3/30))) -> 590.3089 | AQ3: =AJ3-AP3 -> 104.1711 | AR3: =IF(IFERROR(SEARCH("PRORATA",AC3),0)=13,2030,IF(IFERROR(SEARCH("FATOR MODERADOR",AC3),0)=1,613,0)) -> 0 | AS3: =AJ3-AP3-AQ3 -> 0
A4: MARIA | E4: 677 | F4: 0 | I4: Colaborador 1 | L4: 17/08/2023 | N4: 2 | P4: 000.000.000-00 | S4: 06/09/2023 | V4: M11 | W4: D | Y4: FILHO(A) | AC4: MENSALIDADE SAUDE-14 - MULTIPLAN CE ENFERMARIA SEM COPART COM OBST | AH4: 1 | AI4: 393.45 | AJ4: 393.45 | AK4: 000.000.000-00 | AL4: 1 | AM4: 1177.21 | AN4: =SUMIFS(planos!D:D,planos!B:B,"<="&unimed!N4,planos!C:C,">="&unimed!N4,planos!E:E,"Enfermaria sem coparticipação") -> 393.4522 | AO4: =IF(AJ4=0,0,IF(MID(AC4,1,15)="FATOR MODERADOR",AJ4,IF(AM4>=0,IF(AND(AM4>tabelas!$C$4,AM4<=tabelas!$C$5),(AN4)*tabelas!$D$4,IF(AND(AM4>=tabelas!$C$5,AM4<=tabelas!$C$6),(AN4)*tabelas!$D$5,IF(AND(AM4>=tabelas!$C$6,AM4<=tabelas!$C$7),(AN4)*tabelas!$D$6,IF(AND(AM4>0,AM4>tabelas!$C$7),(AN4)*tabelas!$D$7,0))))))) -> 365.91055 | AP4: =IF(MID(AC4,1,15)="FATOR MODERADOR",0,IF(MID(AC4,1,21)="RECOMPOSIÇÃO REAJUSTE",0,IF(AH4=1,AO4,AO4*AH4/30))) -> 365.91055 | AQ4: =AJ4-AP4 -> 27.539453 | AR4: =IF(IFERROR(SEARCH("PRORATA",AC4),0)=13,2030,IF(IFERROR(SEARCH("FATOR MODERADOR",AC4),0)=1,613,0)) -> 0 | AS4: =AJ4-AP4-AQ4 -> 0
A5: JOAO | E5: 677 | F5: 0 | I5: Colaborador 1 | L5: 01/07/1992 | N5: 33 | P5: 000.000.000-00 | S5: 26/10/2021 | V5: M11 | W5: D | Y5: ESPOSO(A) | AC5: MENSALIDADE SAUDE-14 - MULTIPLAN CE ENFERMARIA SEM COPART COM OBST | AH5: 1 | AI5: 559.92 | AJ5: 559.92 | AK5: 000.000.000-00 | AL5: 1 | AM5: 1799.49 | AN5: =SUMIFS(planos!D:D,planos!B:B,"<="&unimed!N5,planos!C:C,">="&unimed!N5,planos!E:E,"Enfermaria sem coparticipação") -> 559.91758 | AO5: =IF(AJ5=0,0,IF(MID(AC5,1,15)="FATOR MODERADOR",AJ5,IF(AM5>=0,IF(AND(AM5>tabelas!$C$4,AM5<=tabelas!$C$5),(AN5)*tabelas!$D$4,IF(AND(AM5>=tabelas!$C$5,AM5<=tabelas!$C$6),(AN5)*tabelas!$D$5,IF(AND(AM5>=tabelas!$C$6,AM5<=tabelas!$C$7),(AN5)*tabelas!$D$6,IF(AND(AM5>0,AM5>tabelas!$C$7),(AN5)*tabelas!$D$7,0))))))) -> 520.72335 | AP5: =IF(MID(AC5,1,15)="FATOR MODERADOR",0,IF(MID(AC5,1,21)="RECOMPOSIÇÃO REAJUSTE",0,IF(AH5=1,AO5,AO5*AH5/30))) -> 520.72335 | AQ5: =AJ5-AP5 -> 39.196648 | AR5: =IF(IFERROR(SEARCH("PRORATA",AC5),0)=13,2030,IF(IFERROR(SEARCH("FATOR MODERADOR",AC5),0)=1,613,0)) -> 0 | AS5: =AJ5-AP5-AQ5 -> 0
A6: MARIA | E6: 293 | F6: 0 | I6: Colaborador 2 | L6: 10/03/1995 | N6: 30 | P6: 000.000.000-00 | S6: 28/10/2020 | V6: M11 | W6: T | Y6: TITULAR | AC6: MENSALIDADE SAUDE-14 - MULTIPLAN CE ENFERMARIA SEM COPART COM OBST | AH6: 1 | AI6: 559.92 | AJ6: 559.92 | AK6: 000.000.000-00 | AL6: 2 | AM6: 4332.22 | AN6: =SUMIFS(planos!D:D,planos!B:B,"<="&unimed!N6,planos!C:C,">="&unimed!N6,planos!E:E,"Enfermaria sem coparticipação") -> 559.91758 | AO6: =IF(AJ6=0,0,IF(MID(AC6,1,15)="FATOR MODERADOR",AJ6,IF(AM6>=0,IF(AND(AM6>tabelas!$C$4,AM6<=tabelas!$C$5),(AN6)*tabelas!$D$4,IF(AND(AM6>=tabelas!$C$5,AM6<=tabelas!$C$6),(AN6)*tabelas!$D$5,IF(AND(AM6>=tabelas!$C$6,AM6<=tabelas!$C$7),(AN6)*tabelas!$D$6,IF(AND(AM6>0,AM6>tabelas!$C$7),(AN6)*tabelas!$D$7,0))))))) -> 475.92995 | AP6: =IF(MID(AC6,1,15)="FATOR MODERADOR",0,IF(MID(AC6,1,21)="RECOMPOSIÇÃO REAJUSTE",0,IF(AH6=1,AO6,AO6*AH6/30))) -> 475.92995 | AQ6: =AJ6-AP6 -> 83.990054 | AR6: =IF(IFERROR(SEARCH("PRORATA",AC6),0)=13,2030,IF(IFERROR(SEARCH("FATOR MODERADOR",AC6),0)=1,613,0)) -> 0 | AS6: =AJ6-AP6-AQ6 -> 0
A7: JOAO | E7: 293 | F7: 0 | I7: Colaborador 2 | L7: 27/09/1996 | N7: 29 | P7: 000.000.000-00 | S7: 15/02/2021 | V7: M11 | W7: D | Y7: ESPOSO(A) | AC7: MENSALIDADE SAUDE-14 - MULTIPLAN CE ENFERMARIA SEM COPART COM OBST | AH7: 1 | AI7: 559.92 | AJ7: 559.92 | AK7: 000.000.000-00 | AL7: 2 | AM7: 4178.46 | AN7: =SUMIFS(planos!D:D,planos!B:B,"<="&unimed!N7,planos!C:C,">="&unimed!N7,planos!E:E,"Enfermaria sem coparticipação") -> 559.91758 | AO7: =IF(AJ7=0,0,IF(MID(AC7,1,15)="FATOR MODERADOR",AJ7,IF(AM7>=0,IF(AND(AM7>tabelas!$C$4,AM7<=tabelas!$C$5),(AN7)*tabelas!$D$4,IF(AND(AM7>=tabelas!$C$5,AM7<=tabelas!$C$6),(AN7)*tabelas!$D$5,IF(AND(AM7>=tabelas!$C$6,AM7<=tabelas!$C$7),(AN7)*tabelas!$D$6,IF(AND(AM7>0,AM7>tabelas!$C$7),(AN7)*tabelas!$D$7,0))))))) -> 475.92995 | AP7: =IF(MID(AC7,1,15)="FATOR MODERADOR",0,IF(MID(AC7,1,21)="RECOMPOSIÇÃO REAJUSTE",0,IF(AH7=1,AO7,AO7*AH7/30))) -> 475.92995 | AQ7: =AJ7-AP7 -> 83.990054 | AR7: =IF(IFERROR(SEARCH("PRORATA",AC7),0)=13,2030,IF(IFERROR(SEARCH("FATOR MODERADOR",AC7),0)=1,613,0)) -> 0 | AS7: =AJ7-AP7-AQ7 -> 0
A8: MARIA | E8: 925 | F8: 0 | I8: Colaborador 3 | L8: 09/05/2000 | N8: 25 | P8: 000.000.000-00 | S8: 21/11/2022 | V8: M11 | W8: T | Y8: TITULAR | AC8: MENSALIDADE SAUDE-14 - MULTIPLAN CE ENFERMARIA SEM COPART COM OBST | AH8: 1 | AI8: 559.92 | AJ8: 559.92 | AK8: 000.000.000-00 | AL8: 3 | AM8: 4714.12 | AN8: =SUMIFS(planos!D:D,planos!B:B,"<="&unimed!N8,planos!C:C,">="&unimed!N8,planos!E:E,"Enfermaria sem coparticipação") -> 559.91758 | AO8: =IF(AJ8=0,0,IF(MID(AC8,1,15)="FATOR MODERADOR",AJ8,IF(AM8>=0,IF(AND(AM8>tabelas!$C$4,AM8<=tabelas!$C$5),(AN8)*tabelas!$D$4,IF(AND(AM8>=tabelas!$C$5,AM8<=tabelas!$C$6),(AN8)*tabelas!$D$5,IF(AND(AM8>=tabelas!$C$6,AM8<=tabelas!$C$7),(AN8)*tabelas!$D$6,IF(AND(AM8>0,AM8>tabelas!$C$7),(AN8)*tabelas!$D$7,0))))))) -> 475.92995 | AP8: =IF(MID(AC8,1,15)="FATOR MODERADOR",0,IF(MID(AC8,1,21)="RECOMPOSIÇÃO REAJUSTE",0,IF(AH8=1,AO8,AO8*AH8/30))) -> 475.92995 | AQ8: =AJ8-AP8 -> 83.990054 | AR8: =IF(IFERROR(SEARCH("PRORATA",AC8),0)=13,2030,IF(IFERROR(SEARCH("FATOR MODERADOR",AC8),0)=1,613,0)) -> 0 | AS8: =AJ8-AP8-AQ8 -> 0
A9: JOAO | E9: 694 | F9: 0 | I9: Colaborador 4 | L9: 01/10/1987 | N9: 38 | P9: 000.000.000-00 | S9: 26/11/2021 | V9: M51 | W9: T | Y9: TITULAR | AC9: MENSALIDADE SAUDE-15 - MULTIPLAN CE APARTAMENTO SEM COPART COM OBST | AH9: 1 | AI9: 937.56 | AJ9: 937.56 | AK9: 000.000.000-00 | AL9: 4 | AM9: 7685.13 | AN9: =SUMIFS(planos!D:D,planos!B:B,"<="&unimed!N9,planos!C:C,">="&unimed!N9,planos!E:E,"Enfermaria sem coparticipação") -> 694.48106 | AO9: =IF(AJ9=0,0,IF(MID(AC9,1,15)="FATOR MODERADOR",AJ9,IF(AM9>=0,IF(AND(AM9>tabelas!$C$4,AM9<=tabelas!$C$5),(AN9)*tabelas!$D$4,IF(AND(AM9>=tabelas!$C$5,AM9<=tabelas!$C$6),(AN9)*tabelas!$D$5,IF(AND(AM9>=tabelas!$C$6,AM9<=tabelas!$C$7),(AN9)*tabelas!$D$6,IF(AND(AM9>0,AM9>tabelas!$C$7),(AN9)*tabelas!$D$7,0))))))) -> 534.75041 | AP9: =IF(MID(AC9,1,15)="FATOR MODERADOR",0,IF(MID(AC9,1,21)="RECOMPOSIÇÃO REAJUSTE",0,IF(AH9=1,AO9,AO9*AH9/30))) -> 534.75041 | AQ9: =AJ9-AP9 -> 402.80959 | AR9: =IF(IFERROR(SEARCH("PRORATA",AC9),0)=13,2030,IF(IFERROR(SEARCH("FATOR MODERADOR",AC9),0)=1,613,0)) -> 0 | AS9: =AJ9-AP9-AQ9 -> 0
A10: MARIA | E10: 9 | F10: 0 | I10: Colaborador 5 | L10: 15/12/1981 | N10: 44 | P10: 000.000.000-00 | S10: 15/01/2020 | V10: M52 | W10: T | Y10: TITULAR | AC10: MENSALIDADE SAUDE-152 | AH10: 1 | AI10: 1201.83 | AJ10: 1201.83 | AK10: 000.000.000-00 | AL10: 5 | AM10: 3652.6 | AN10: =SUMIFS(planos!D:D,planos!B:B,"<="&unimed!N10,planos!C:C,">="&unimed!N10,planos!E:E,"Enfermaria sem coparticipação") -> 1123.0245 | AO10: =IF(AJ10=0,0,IF(MID(AC10,1,15)="FATOR MODERADOR",AJ10,IF(AM10>=0,IF(AND(AM10>tabelas!$C$4,AM10<=tabelas!$C$5),(AN10)*tabelas!$D$4,IF(AND(AM10>=tabelas!$C$5,AM10<=tabelas!$C$6),(AN10)*tabelas!$D$5,IF(AND(AM10>=tabelas!$C$6,AM10<=tabelas!$C$7),(AN10)*tabelas!$D$6,IF(AND(AM10>0,AM10>tabelas!$C$7),(AN10)*tabelas!$D$7,0))))))) -> 1044.4128 | AP10: =IF(MID(AC10,1,15)="FATOR MODERADOR",0,IF(MID(AC10,1,21)="RECOMPOSIÇÃO REAJUSTE",0,IF(AH10=1,AO10,AO10*AH10/30))) -> 1044.4128 | AQ10: =AJ10-AP10 -> 157.41721 | AR10: =IF(IFERROR(SEARCH("PRORATA",AC10),0)=13,2030,IF(IFERROR(SEARCH("FATOR MODERADOR",AC10),0)=1,613,0)) -> 0 | AS10: =AJ10-AP10-AQ10 -> 0
A11: JOAO | E11: 9 | F11: 0 | I11: Colaborador 5 | L11: 23/11/2014 | N11: 11 | P11: 000.000.000-00 | S11: 15/01/2020 | V11: M52 | W11: D | Y11: FILHO(A) | AC11: MENSALIDADE SAUDE-152 | AH11: 1 | AI11: 421.06 | AJ11: 421.06 | AK11: 000.000.000-00 | AL11: 5 | AM11: 3579 | AN11: =SUMIFS(planos!D:D,planos!B:B,"<="&unimed!N11,planos!C:C,">="&unimed!N11,planos!E:E,"Enfermaria sem coparticipação") -> 393.4522 | AO11: =IF(AJ11=0,0,IF(MID(AC11,1,15)="FATOR MODERADOR",AJ11,IF(AM11>=0,IF(AND(AM11>tabelas!$C$4,AM11<=tabelas!$C$5),(AN11)*tabelas!$D$4,IF(AND(AM11>=tabelas!$C$5,AM11<=tabelas!$C$6),(AN11)*tabelas!$D$5,IF(AND(AM11>=tabelas!$C$6,AM11<=tabelas!$C$7),(AN11)*tabelas!$D$6,IF(AND(AM11>0,AM11>tabelas!$C$7),(AN11)*tabelas!$D$7,0))))))) -> 365.91055 | AP11: =IF(MID(AC11,1,15)="FATOR MODERADOR",0,IF(MID(AC11,1,21)="RECOMPOSIÇÃO REAJUSTE",0,IF(AH11=1,AO11,AO11*AH11/30))) -> 365.91055 | AQ11: =AJ11-AP11 -> 55.149453 | AR11: =IF(IFERROR(SEARCH("PRORATA",AC11),0)=13,2030,IF(IFERROR(SEARCH("FATOR MODERADOR",AC11),0)=1,613,0)) -> 0 | AS11: =AJ11-AP11-AQ11 -> 0
A12: MARIA | E12: 9 | F12: 0 | I12: Colaborador 5 | L12: 22/10/2012 | N12: 13 | P12: 000.000.000-00 | S12: 15/01/2020 | V12: M52 | W12: D | Y12: ESPOSO(A) | AC12: FATOR MODERADOR SAUDE-152 | AH12: 1 | AI12: 43.74 | AJ12: 43.74 | AK12: 000.000.000-00 | AL12: 5 | AM12: 3043.68 | AN12: =SUMIFS(planos!D:D,planos!B:B,"<="&unimed!N12,planos!C:C,">="&unimed!N12,planos!E:E,"Enfermaria sem coparticipação") -> 393.4522 | AO12: =IF(AJ12=0,0,IF(MID(AC12,1,15)="FATOR MODERADOR",AJ12,IF(AM12>=0,IF(AND(AM12>tabelas!$C$4,AM12<=tabelas!$C$5),(AN12)*tabelas!$D$4,IF(AND(AM12>=tabelas!$C$5,AM12<=tabelas!$C$6),(AN12)*tabelas!$D$5,IF(AND(AM12>=tabelas!$C$6,AM12<=tabelas!$C$7),(AN12)*tabelas!$D$6,IF(AND(AM12>0,AM12>tabelas!$C$7),(AN12)*tabelas!$D$7,0))))))) -> 43.74 | AP12: =IF(MID(AC12,1,15)="FATOR MODERADOR",0,IF(MID(AC12,1,21)="RECOMPOSIÇÃO REAJUSTE",0,IF(AH12=1,AO12,AO12*AH12/30))) -> 0 | AQ12: =AJ12-AP12 -> 43.74 | AR12: 350 | AS12: =AJ12-AP12-AQ12 -> 0
A13: JOAO | E13: 9 | F13: 0 | I13: Colaborador 5 | L13: 22/10/2012 | N13: 13 | P13: 000.000.000-00 | S13: 15/01/2020 | V13: M52 | W13: D | Y13: ESPOSO(A) | AC13: FATOR MODERADOR SAUDE-152 | AH13: 1 | AI13: 39.75 | AJ13: 39.75 | AK13: 000.000.000-00 | AL13: 5 | AM13: 2052.13 | AN13: =SUMIFS(planos!D:D,planos!B:B,"<="&unimed!N13,planos!C:C,">="&unimed!N13,planos!E:E,"Enfermaria sem coparticipação") -> 393.4522 | AO13: =IF(AJ13=0,0,IF(MID(AC13,1,15)="FATOR MODERADOR",AJ13,IF(AM13>=0,IF(AND(AM13>tabelas!$C$4,AM13<=tabelas!$C$5),(AN13)*tabelas!$D$4,IF(AND(AM13>=tabelas!$C$5,AM13<=tabelas!$C$6),(AN13)*tabelas!$D$5,IF(AND(AM13>=tabelas!$C$6,AM13<=tabelas!$C$7),(AN13)*tabelas!$D$6,IF(AND(AM13>0,AM13>tabelas!$C$7),(AN13)*tabelas!$D$7,0))))))) -> 39.75 | AP13: =IF(MID(AC13,1,15)="FATOR MODERADOR",0,IF(MID(AC13,1,21)="RECOMPOSIÇÃO REAJUSTE",0,IF(AH13=1,AO13,AO13*AH13/30))) -> 0 | AQ13: =AJ13-AP13 -> 39.75 | AR13: 350 | AS13: =AJ13-AP13-AQ13 -> 0
A14: MARIA | E14: 9 | F14: 0 | I14: Colaborador 5 | L14: 22/10/2012 | N14: 13 | P14: 000.000.000-00 | S14: 15/01/2020 | V14: M52 | W14: D | Y14: ESPOSO(A) | AC14: FATOR MODERADOR SAUDE-152 | AH14: 1 | AI14: 26.37 | AJ14: 26.37 | AK14: 000.000.000-00 | AL14: 5 | AM14: 4636.88 | AN14: =SUMIFS(planos!D:D,planos!B:B,"<="&unimed!N14,planos!C:C,">="&unimed!N14,planos!E:E,"Enfermaria sem coparticipação") -> 393.4522 | AO14: =IF(AJ14=0,0,IF(MID(AC14,1,15)="FATOR MODERADOR",AJ14,IF(AM14>=0,IF(AND(AM14>tabelas!$C$4,AM14<=tabelas!$C$5),(AN14)*tabelas!$D$4,IF(AND(AM14>=tabelas!$C$5,AM14<=tabelas!$C$6),(AN14)*tabelas!$D$5,IF(AND(AM14>=tabelas!$C$6,AM14<=tabelas!$C$7),(AN14)*tabelas!$D$6,IF(AND(AM14>0,AM14>tabelas!$C$7),(AN14)*tabelas!$D$7,0))))))) -> 26.37 | AP14: =IF(MID(AC14,1,15)="FATOR MODERADOR",0,IF(MID(AC14,1,21)="RECOMPOSIÇÃO REAJUSTE",0,IF(AH14=1,AO14,AO14*AH14/30))) -> 0 | AQ14: =AJ14-AP14 -> 26.37 | AR14: 350 | AS14: =AJ14-AP14-AQ14 -> 0
A15: JOAO | E15: 9 | F15: 0 | I15: Colaborador 5 | L15: 22/10/2012 | N15: 13 | P15: 000.000.000-00 | S15: 15/01/2020 | V15: M52 | W15: D | Y15: ESPOSO(A) | AC15: FATOR MODERADOR SAUDE-152 | AH15: 1 | AI15: 24.05 | AJ15: 24.05 | AK15: 000.000.000-00 | AL15: 5 | AM15: 2528.58 | AN15: =SUMIFS(planos!D:D,planos!B:B,"<="&unimed!N15,planos!C:C,">="&unimed!N15,planos!E:E,"Enfermaria sem coparticipação") -> 393.4522 | AO15: =IF(AJ15=0,0,IF(MID(AC15,1,15)="FATOR MODERADOR",AJ15,IF(AM15>=0,IF(AND(AM15>tabelas!$C$4,AM15<=tabelas!$C$5),(AN15)*tabelas!$D$4,IF(AND(AM15>=tabelas!$C$5,AM15<=tabelas!$C$6),(AN15)*tabelas!$D$5,IF(AND(AM15>=tabelas!$C$6,AM15<=tabelas!$C$7),(AN15)*tabelas!$D$6,IF(AND(AM15>0,AM15>tabelas!$C$7),(AN15)*tabelas!$D$7,0))))))) -> 24.05 | AP15: =IF(MID(AC15,1,15)="FATOR MODERADOR",0,IF(MID(AC15,1,21)="RECOMPOSIÇÃO REAJUSTE",0,IF(AH15=1,AO15,AO15*AH15/30))) -> 0 | AQ15: =AJ15-AP15 -> 24.05 | AR15: 350 | AS15: =AJ15-AP15-AQ15 -> 0
A16: MARIA | E16: 9 | F16: 0 | I16: Colaborador 5 | L16: 22/10/2012 | N16: 13 | P16: 000.000.000-00 | S16: 15/01/2020 | V16: M52 | W16: D | Y16: ESPOSO(A) | AC16: FATOR MODERADOR SAUDE-152 | AH16: 1 | AI16: 23.3 | AJ16: 23.3 | AK16: 000.000.000-00 | AL16: 5 | AM16: 1252.48 | AN16: =SUMIFS(planos!D:D,planos!B:B,"<="&unimed!N16,planos!C:C,">="&unimed!N16,planos!E:E,"Enfermaria sem coparticipação") -> 393.4522 | AO16: =IF(AJ16=0,0,IF(MID(AC16,1,15)="FATOR MODERADOR",AJ16,IF(AM16>=0,IF(AND(AM16>tabelas!$C$4,AM16<=tabelas!$C$5),(AN16)*tabelas!$D$4,IF(AND(AM16>=tabelas!$C$5,AM16<=tabelas!$C$6),(AN16)*tabelas!$D$5,IF(AND(AM16>=tabelas!$C$6,AM16<=tabelas!$C$7),(AN16)*tabelas!$D$6,IF(AND(AM16>0,AM16>tabelas!$C$7),(AN16)*tabelas!$D$7,0))))))) -> 23.3 | AP16: =IF(MID(AC16,1,15)="FATOR MODERADOR",0,IF(MID(AC16,1,21)="RECOMPOSIÇÃO REAJUSTE",0,IF(AH16=1,AO16,AO16*AH16/30))) -> 0 | AQ16: =AJ16-AP16 -> 23.3 | AR16: 350 | AS16: =AJ16-AP16-AQ16 -> 0
A17: JOAO | E17: 9 | F17: 0 | I17: Colaborador 5 | L17: 22/10/2012 | N17: 13 | P17: 000.000.000-00 | S17: 15/01/2020 | V17: M52 | W17: D | Y17: ESPOSO(A) | AC17: MENSALIDADE SAUDE-152 | AH17: 1 | AI17: 421.06 | AJ17: 421.06 | AK17: 000.000.000-00 | AL17: 5 | AM17: 5599.77 | AN17: =SUMIFS(planos!D:D,planos!B:B,"<="&unimed!N17,planos!C:C,">="&unimed!N17,planos!E:E,"Enfermaria sem coparticipação") -> 393.4522 | AO17: =IF(AJ17=0,0,IF(MID(AC17,1,15)="FATOR MODERADOR",AJ17,IF(AM17>=0,IF(AND(AM17>tabelas!$C$4,AM17<=tabelas!$C$5),(AN17)*tabelas!$D$4,IF(AND(AM17>=tabelas!$C$5,AM17<=tabelas!$C$6),(AN17)*tabelas!$D$5,IF(AND(AM17>=tabelas!$C$6,AM17<=tabelas!$C$7),(AN17)*tabelas!$D$6,IF(AND(AM17>0,AM17>tabelas!$C$7),(AN17)*tabelas!$D$7,0))))))) -> 334.43437 | AP17: =IF(MID(AC17,1,15)="FATOR MODERADOR",0,IF(MID(AC17,1,21)="RECOMPOSIÇÃO REAJUSTE",0,IF(AH17=1,AO17,AO17*AH17/30))) -> 334.43437 | AQ17: =AJ17-AP17 -> 86.625629 | AR17: =IF(IFERROR(SEARCH("PRORATA",AC17),0)=13,2030,IF(IFERROR(SEARCH("FATOR MODERADOR",AC17),0)=1,613,0)) -> 0 | AS17: =AJ17-AP17-AQ17 -> 0
A18: MARIA | E18: 9 | F18: 0 | I18: Colaborador 5 | L18: 27/01/1981 | N18: 44 | P18: 000.000.000-00 | S18: 15/01/2020 | V18: M52 | W18: D | Y18: OUTROS | AC18: FATOR MODERADOR SAUDE-152 | AH18: 1 | AI18: 26.37 | AJ18: 26.37 | AK18: 000.000.000-00 | AL18: 5 | AM18: 7322.38 | AN18: =SUMIFS(planos!D:D,planos!B:B,"<="&unimed!N18,planos!C:C,">="&unimed!N18,planos!E:E,"Enfermaria sem coparticipação") -> 1123.0245 | AO18: =IF(AJ18=0,0,IF(MID(AC18,1,15)="FATOR MODERADOR",AJ18,IF(AM18>=0,IF(AND(AM18>tabelas!$C$4,AM18<=tabelas!$C$5),(AN18)*tabelas!$D$4,IF(AND(AM18>=tabelas!$C$5,AM18<=tabelas!$C$6),(AN18)*tabelas!$D$5,IF(AND(AM18>=tabelas!$C$6,AM18<=tabelas!$C$7),(AN18)*tabelas!$D$6,IF(AND(AM18>0,AM18>tabelas!$C$7),(AN18)*tabelas!$D$7,0))))))) -> 26.37 | AP18: =IF(MID(AC18,1,15)="FATOR MODERADOR",0,IF(MID(AC18,1,21)="RECOMPOSIÇÃO REAJUSTE",0,IF(AH18=1,AO18,AO18*AH18/30))) -> 0 | AQ18: =AJ18-AP18 -> 26.37 | AR18: 350 | AS18: =AJ18-AP18-AQ18 -> 0
A19: JOAO | E19: 9 | F19: 0 | I19: Colaborador 5 | L19: 27/01/1981 | N19: 44 | P19: 000.000.000-00 | S19: 15/01/2020 | V19: M52 | W19: D | Y19: OUTROS | AC19: FATOR MODERADOR SAUDE-152 | AH19: 1 | AI19: 13.16 | AJ19: 13.16 | AK19: 000.000.000-00 | AL19: 5 | AM19: 2799.33 | AN19: =SUMIFS(planos!D:D,planos!B:B,"<="&unimed!N19,planos!C:C,">="&unimed!N19,planos!E:E,"Enfermaria sem coparticipação") -> 1123.0245 | AO19: =IF(AJ19=0,0,IF(MID(AC19,1,15)="FATOR MODERADOR",AJ19,IF(AM19>=0,IF(AND(AM19>tabelas!$C$4,AM19<=tabelas!$C$5),(AN19)*tabelas!$D$4,IF(AND(AM19>=tabelas!$C$5,AM19<=tabelas!$C$6),(AN19)*tabelas!$D$5,IF(AND(AM19>=tabelas!$C$6,AM19<=tabelas!$C$7),(AN19)*tabelas!$D$6,IF(AND(AM19>0,AM19>tabelas!$C$7),(AN19)*tabelas!$D$7,0))))))) -> 13.16 | AP19: =IF(MID(AC19,1,15)="FATOR MODERADOR",0,IF(MID(AC19,1,21)="RECOMPOSIÇÃO REAJUSTE",0,IF(AH19=1,AO19,AO19*AH19/30))) -> 0 | AQ19: =AJ19-AP19 -> 13.16 | AR19: 350 | AS19: =AJ19-AP19-AQ19 -> 0
A20: MARIA | E20: 9 | F20: 0 | I20: Colaborador 5 | L20: 27/01/1981 | N20: 44 | P20: 000.000.000-00 | S20: 15/01/2020 | V20: M52 | W20: D | Y20: OUTROS | AC20: FATOR MODERADOR SAUDE-152 | AH20: 1 | AI20: 10.13 | AJ20: 10.13 | AK20: 000.000.000-00 | AL20: 5 | AM20: 6948.27 | AN20: =SUMIFS(planos!D:D,planos!B:B,"<="&unimed!N20,planos!C:C,">="&unimed!N20,planos!E:E,"Enfermaria sem coparticipação") -> 1123.0245 | AO20: =IF(AJ20=0,0,IF(MID(AC20,1,15)="FATOR MODERADOR",AJ20,IF(AM20>=0,IF(AND(AM20>tabelas!$C$4,AM20<=tabelas!$C$5),(AN20)*tabelas!$D$4,IF(AND(AM20>=tabelas!$C$5,AM20<=tabelas!$C$6),(AN20)*tabelas!$D$5,IF(AND(AM20>=tabelas!$C$6,AM20<=tabelas!$C$7),(AN20)*tabelas!$D$6,IF(AND(AM20>0,AM20>tabelas!$C$7),(AN20)*tabelas!$D$7,0))))))) -> 10.13 | AP20: =IF(MID(AC20,1,15)="FATOR MODERADOR",0,IF(MID(AC20,1,21)="RECOMPOSIÇÃO REAJUSTE",0,IF(AH20=1,AO20,AO20*AH20/30))) -> 0 | AQ20: =AJ20-AP20 -> 10.13 | AR20: 350 | AS20: =AJ20-AP20-AQ20 -> 0
A21: JOAO | E21: 9 | F21: 0 | I21: Colaborador 5 | L21: 27/01/1981 | N21: 44 | P21: 000.000.000-00 | S21: 15/01/2020 | V21: M52 | W21: D | Y21: OUTROS | AC21: FATOR MODERADOR SAUDE-152 | AH21: 1 | AI21: 3.6 | AJ21: 3.6 | AK21: 000.000.000-00 | AL21: 5 | AM21: 6863.34 | AN21: =SUMIFS(planos!D:D,planos!B:B,"<="&unimed!N21,planos!C:C,">="&unimed!N21,planos!E:E,"Enfermaria sem coparticipação") -> 1123.0245 | AO21: =IF(AJ21=0,0,IF(MID(AC21,1,15)="FATOR MODERADOR",AJ21,IF(AM21>=0,IF(AND(AM21>tabelas!$C$4,AM21<=tabelas!$C$5),(AN21)*tabelas!$D$4,IF(AND(AM21>=tabelas!$C$5,AM21<=tabelas!$C$6),(AN21)*tabelas!$D$5,IF(AND(AM21>=tabelas!$C$6,AM21<=tabelas!$C$7),(AN21)*tabelas!$D$6,IF(AND(AM21>0,AM21>tabelas!$C$7),(AN21)*tabelas!$D$7,0))))))) -> 3.6 | AP21: =IF(MID(AC21,1,15)="FATOR MODERADOR",0,IF(MID(AC21,1,21)="RECOMPOSIÇÃO REAJUSTE",0,IF(AH21=1,AO21,AO21*AH21/30))) -> 0 | AQ21: =AJ21-AP21 -> 3.6 | AR21: 350 | AS21: =AJ21-AP21-AQ21 -> 0
A22: MARIA | E22: 9 | F22: 0 | I22: Colaborador 5 | L22: 23/11/2014 | N22: 11 | P22: 000.000.000-00 | S22: 15/01/2020 | V22: M52 | W22: D | Y22: FILHO(A) | AC22: FATOR MODERADOR SAUDE-152 | AH22: 1 | AI22: 19.19 | AJ22: 19.19 | AK22: 000.000.000-00 | AL22: 5 | AM22: 3517.02 | AN22: =SUMIFS(planos!D:D,planos!B:B,"<="&unimed!N22,planos!C:C,">="&unimed!N22,planos!E:E,"Enfermaria sem coparticipação") -> 393.4522 | AO22: =IF(AJ22=0,0,IF(MID(AC22,1,15)="FATOR MODERADOR",AJ22,IF(AM22>=0,IF(AND(AM22>tabelas!$C$4,AM22<=tabelas!$C$5),(AN22)*tabelas!$D$4,IF(AND(AM22>=tabelas!$C$5,AM22<=tabelas!$C$6),(AN22)*tabelas!$D$5,IF(AND(AM22>=tabelas!$C$6,AM22<=tabelas!$C$7),(AN22)*tabelas!$D$6,IF(AND(AM22>0,AM22>tabelas!$C$7),(AN22)*tabelas!$D$7,0))))))) -> 19.19 | AP22: =IF(MID(AC22,1,15)="FATOR MODERADOR",0,IF(MID(AC22,1,21)="RECOMPOSIÇÃO REAJUSTE",0,IF(AH22=1,AO22,AO22*AH22/30))) -> 0 | AQ22: =AJ22-AP22 -> 19.19 | AR22: 350 | AS22: =AJ22-AP22-AQ22 -> 0
A23: JOAO | E23: 9 | F23: 0 | I23: Colaborador 5 | L23: 23/11/2014 | N23: 11 | P23: 000.000.000-00 | S23: 15/01/2020 | V23: M52 | W23: D | Y23: FILHO(A) | AC23: FATOR MODERADOR SAUDE-152 | AH23: 1 | AI23: 21.11 | AJ23: 21.11 | AK23: 000.000.000-00 | AL23: 5 | AM23: 2513.3 | AN23: =SUMIFS(planos!D:D,planos!B:B,"<="&unimed!N23,planos!C:C,">="&unimed!N23,planos!E:E,"Enfermaria sem coparticipação") -> 393.4522 | AO23: =IF(AJ23=0,0,IF(MID(AC23,1,15)="FATOR MODERADOR",AJ23,IF(AM23>=0,IF(AND(AM23>tabelas!$C$4,AM23<=tabelas!$C$5),(AN23)*tabelas!$D$4,IF(AND(AM23>=tabelas!$C$5,AM23<=tabelas!$C$6),(AN23)*tabelas!$D$5,IF(AND(AM23>=tabelas!$C$6,AM23<=tabelas!$C$7),(AN23)*tabelas!$D$6,IF(AND(AM23>0,AM23>tabelas!$C$7),(AN23)*tabelas!$D$7,0))))))) -> 21.11 | AP23: =IF(MID(AC23,1,15)="FATOR MODERADOR",0,IF(MID(AC23,1,21)="RECOMPOSIÇÃO REAJUSTE",0,IF(AH23=1,AO23,AO23*AH23/30))) -> 0 | AQ23: =AJ23-AP23 -> 21.11 | AR23: 350 | AS23: =AJ23-AP23-AQ23 -> 0
A24: MARIA | E24: 9 | F24: 0 | I24: Colaborador 5 | L24: 23/11/2014 | N24: 11 | P24: 000.000.000-00 | S24: 15/01/2020 | V24: M52 | W24: D | Y24: FILHO(A) | AC24: FATOR MODERADOR SAUDE-152 | AH24: 1 | AI24: 24.45 | AJ24: 24.45 | AK24: 000.000.000-00 | AL24: 5 | AM24: 1358.44 | AN24: =SUMIFS(planos!D:D,planos!B:B,"<="&unimed!N24,planos!C:C,">="&unimed!N24,planos!E:E,"Enfermaria sem coparticipação") -> 393.4522 | AO24: =IF(AJ24=0,0,IF(MID(AC24,1,15)="FATOR MODERADOR",AJ24,IF(AM24>=0,IF(AND(AM24>tabelas!$C$4,AM24<=tabelas!$C$5),(AN24)*tabelas!$D$4,IF(AND(AM24>=tabelas!$C$5,AM24<=tabelas!$C$6),(AN24)*tabelas!$D$5,IF(AND(AM24>=tabelas!$C$6,AM24<=tabelas!$C$7),(AN24)*tabelas!$D$6,IF(AND(AM24>0,AM24>tabelas!$C$7),(AN24)*tabelas!$D$7,0))))))) -> 24.45 | AP24: =IF(MID(AC24,1,15)="FATOR MODERADOR",0,IF(MID(AC24,1,21)="RECOMPOSIÇÃO REAJUSTE",0,IF(AH24=1,AO24,AO24*AH24/30))) -> 0 | AQ24: =AJ24-AP24 -> 24.45 | AR24: 350 | AS24: =AJ24-AP24-AQ24 -> 0
A25: JOAO | E25: 9 | F25: 0 | I25: Colaborador 5 | L25: 23/11/2014 | N25: 11 | P25: 000.000.000-00 | S25: 15/01/2020 | V25: M52 | W25: D | Y25: FILHO(A) | AC25: FATOR MODERADOR SAUDE-152 | AH25: 1 | AI25: 48.86 | AJ25: 48.86 | AK25: 000.000.000-00 | AL25: 5 | AM25: 1498.86 | AN25: =SUMIFS(planos!D:D,planos!B:B,"<="&unimed!N25,planos!C:C,">="&unimed!N25,planos!E:E,"Enfermaria sem coparticipação") -> 393.4522 | AO25: =IF(AJ25=0,0,IF(MID(AC25,1,15)="FATOR MODERADOR",AJ25,IF(AM25>=0,IF(AND(AM25>tabelas!$C$4,AM25<=tabelas!$C$5),(AN25)*tabelas!$D$4,IF(AND(AM25>=tabelas!$C$5,AM25<=tabelas!$C$6),(AN25)*tabelas!$D$5,IF(AND(AM25>=tabelas!$C$6,AM25<=tabelas!$C$7),(AN25)*tabelas!$D$6,IF(AND(AM25>0,AM25>tabelas!$C$7),(AN25)*tabelas!$D$7,0))))))) -> 48.86 | AP25: =IF(MID(AC25,1,15)="FATOR MODERADOR",0,IF(MID(AC25,1,21)="RECOMPOSIÇÃO REAJUSTE",0,IF(AH25=1,AO25,AO25*AH25/30))) -> 0 | AQ25: =AJ25-AP25 -> 48.86 | AR25: 350 | AS25: =AJ25-AP25-AQ25 -> 0
A26: MARIA | E26: 9 | F26: 0 | I26: Colaborador 5 | L26: 27/01/1981 | N26: 44 | P26: 000.000.000-00 | S26: 15/01/2020 | V26: M52 | W26: D | Y26: OUTROS | AC26: MENSALIDADE SAUDE-152 | AH26: 1 | AI26: 1201.83 | AJ26: 1201.83 | AK26: 000.000.000-00 | AL26: 5 | AM26: 5250.54 | AN26: =SUMIFS(planos!D:D,planos!B:B,"<="&unimed!N26,planos!C:C,">="&unimed!N26,planos!E:E,"Enfermaria sem coparticipação") -> 1123.0245 | AO26: =IF(AJ26=0,0,IF(MID(AC26,1,15)="FATOR MODERADOR",AJ26,IF(AM26>=0,IF(AND(AM26>tabelas!$C$4,AM26<=tabelas!$C$5),(AN26)*tabelas!$D$4,IF(AND(AM26>=tabelas!$C$5,AM26<=tabelas!$C$6),(AN26)*tabelas!$D$5,IF(AND(AM26>=tabelas!$C$6,AM26<=tabelas!$C$7),(AN26)*tabelas!$D$6,IF(AND(AM26>0,AM26>tabelas!$C$7),(AN26)*tabelas!$D$7,0))))))) -> 954.57083 | AP26: =IF(MID(AC26,1,15)="FATOR MODERADOR",0,IF(MID(AC26,1,21)="RECOMPOSIÇÃO REAJUSTE",0,IF(AH26=1,AO26,AO26*AH26/30))) -> 954.57083 | AQ26: =AJ26-AP26 -> 247.25917 | AR26: =IF(IFERROR(SEARCH("PRORATA",AC26),0)=13,2030,IF(IFERROR(SEARCH("FATOR MODERADOR",AC26),0)=1,613,0)) -> 0 | AS26: =AJ26-AP26-AQ26 -> 0
A27: JOAO | E27: 9 | F27: 0 | I27: Colaborador 5 | L27: 23/11/2014 | N27: 11 | P27: 000.000.000-00 | S27: 15/01/2020 | V27: M52 | W27: D | Y27: FILHO(A) | AC27: FATOR MODERADOR SAUDE-152 | AH27: 1 | AI27: 54.59 | AJ27: 54.59 | AK27: 000.000.000-00 | AL27: 5 | AM27: 3814.48 | AN27: =SUMIFS(planos!D:D,planos!B:B,"<="&unimed!N27,planos!C:C,">="&unimed!N27,planos!E:E,"Enfermaria sem coparticipação") -> 393.4522 | AO27: =IF(AJ27=0,0,IF(MID(AC27,1,15)="FATOR MODERADOR",AJ27,IF(AM27>=0,IF(AND(AM27>tabelas!$C$4,AM27<=tabelas!$C$5),(AN27)*tabelas!$D$4,IF(AND(AM27>=tabelas!$C$5,AM27<=tabelas!$C$6),(AN27)*tabelas!$D$5,IF(AND(AM27>=tabelas!$C$6,AM27<=tabelas!$C$7),(AN27)*tabelas!$D$6,IF(AND(AM27>0,AM27>tabelas!$C$7),(AN27)*tabelas!$D$7,0))))))) -> 54.59 | AP27: =IF(MID(AC27,1,15)="FATOR MODERADOR",0,IF(MID(AC27,1,21)="RECOMPOSIÇÃO REAJUSTE",0,IF(AH27=1,AO27,AO27*AH27/30))) -> 0 | AQ27: =AJ27-AP27 -> 54.59 | AR27: 350 | AS27: =AJ27-AP27-AQ27 -> 0
A28: MARIA | E28: 703 | F28: 0 | I28: Colaborador 6 | L28: 14/03/1987 | N28: 38 | P28: 000.000.000-00 | S28: 21/12/2021 | V28: M11 | W28: T | Y28: TITULAR | AC28: MENSALIDADE SAUDE-14 - MULTIPLAN CE ENFERMARIA SEM COPART COM OBST | AH28: 1 | AI28: 694.48 | AJ28: 694.48 | AK28: 000.000.000-00 | AL28: 6 | AM28: 7943.86 | AN28: =SUMIFS(planos!D:D,planos!B:B,"<="&unimed!N28,planos!C:C,">="&unimed!N28,planos!E:E,"Enfermaria sem coparticipação") -> 694.48106 | AO28: =IF(AJ28=0,0,IF(MID(AC28,1,15)="FATOR MODERADOR",AJ28,IF(AM28>=0,IF(AND(AM28>tabelas!$C$4,AM28<=tabelas!$C$5),(AN28)*tabelas!$D$4,IF(AND(AM28>=tabelas!$C$5,AM28<=tabelas!$C$6),(AN28)*tabelas!$D$5,IF(AND(AM28>=tabelas!$C$6,AM28<=tabelas!$C$7),(AN28)*tabelas!$D$6,IF(AND(AM28>0,AM28>tabelas!$C$7),(AN28)*tabelas!$D$7,0))))))) -> 534.75041 | AP28: =IF(MID(AC28,1,15)="FATOR MODERADOR",0,IF(MID(AC28,1,21)="RECOMPOSIÇÃO REAJUSTE",0,IF(AH28=1,AO28,AO28*AH28/30))) -> 534.75041 | AQ28: =AJ28-AP28 -> 159.72959 | AR28: =IF(IFERROR(SEARCH("PRORATA",AC28),0)=13,2030,IF(IFERROR(SEARCH("FATOR MODERADOR",AC28),0)=1,613,0)) -> 0 | AS28: =AJ28-AP28-AQ28 -> 0
A29: JOAO | E29: 703 | F29: 0 | I29: Colaborador 6 | L29: 30/11/2015 | N29: 10 | P29: 000.000.000-00 | S29: 21/01/2022 | V29: M11 | W29: D | Y29: FILHO(A) | AC29: MENSALIDADE SAUDE-14 - MULTIPLAN CE ENFERMARIA SEM COPART COM OBST | AH29: 1 | AI29: 393.45 | AJ29: 393.45 | AK29: 000.000.000-00 | AL29: 6 | AM29: 1102.82 | AN29: =SUMIFS(planos!D:D,planos!B:B,"<="&unimed!N29,planos!C:C,">="&unimed!N29,planos!E:E,"Enfermaria sem coparticipação") -> 393.4522 | AO29: =IF(AJ29=0,0,IF(MID(AC29,1,15)="FATOR MODERADOR",AJ29,IF(AM29>=0,IF(AND(AM29>tabelas!$C$4,AM29<=tabelas!$C$5),(AN29)*tabelas!$D$4,IF(AND(AM29>=tabelas!$C$5,AM29<=tabelas!$C$6),(AN29)*tabelas!$D$5,IF(AND(AM29>=tabelas!$C$6,AM29<=tabelas!$C$7),(AN29)*tabelas!$D$6,IF(AND(AM29>0,AM29>tabelas!$C$7),(AN29)*tabelas!$D$7,0))))))) -> 365.91055 | AP29: =IF(MID(AC29,1,15)="FATOR MODERADOR",0,IF(MID(AC29,1,21)="RECOMPOSIÇÃO REAJUSTE",0,IF(AH29=1,AO29,AO29*AH29/30))) -> 365.91055 | AQ29: =AJ29-AP29 -> 27.539453 | AR29: =IF(IFERROR(SEARCH("PRORATA",AC29),0)=13,2030,IF(IFERROR(SEARCH("FATOR MODERADOR",AC29),0)=1,613,0)) -> 0 | AS29: =AJ29-AP29-AQ29 -> 0
A30: MARIA | E30: 703 | F30: 0 | I30: Colaborador 6 | L30: 07/09/2013 | N30: 12 | P30: 000.000.000-00 | S30: 21/01/2022 | V30: M11 | W30: D | Y30: FILHO(A) | AC30: MENSALIDADE SAUDE-14 - MULTIPLAN CE ENFERMARIA SEM COPART COM OBST | AH30: 1 | AI30: 393.45 | AJ30: 393.45 | AK30: 000.000.000-00 | AL30: 6 | AM30: 5901.7 | AN30: =SUMIFS(planos!D:D,planos!B:B,"<="&unimed!N30,planos!C:C,">="&unimed!N30,planos!E:E,"Enfermaria sem coparticipação") -> 393.4522 | AO30: =IF(AJ30=0,0,IF(MID(AC30,1,15)="FATOR MODERADOR",AJ30,IF(AM30>=0,IF(AND(AM30>tabelas!$C$4,AM30<=tabelas!$C$5),(AN30)*tabelas!$D$4,IF(AND(AM30>=tabelas!$C$5,AM30<=tabelas!$C$6),(AN30)*tabelas!$D$5,IF(AND(AM30>=tabelas!$C$6,AM30<=tabelas!$C$7),(AN30)*tabelas!$D$6,IF(AND(AM30>0,AM30>tabelas!$C$7),(AN30)*tabelas!$D$7,0))))))) -> 334.43437 | AP30: =IF(MID(AC30,1,15)="FATOR MODERADOR",0,IF(MID(AC30,1,21)="RECOMPOSIÇÃO REAJUSTE",0,IF(AH30=1,AO30,AO30*AH30/30))) -> 334.43437 | AQ30: =AJ30-AP30 -> 59.015629 | AR30: =IF(IFERROR(SEARCH("PRORATA",AC30),0)=13,2030,IF(IFERROR(SEARCH("FATOR MODERADOR",AC30),0)=1,613,0)) -> 0 | AS30: =AJ30-AP30-AQ30 -> 0
A31: JOAO | E31: 703 | F31: 0 | I31: Colaborador 6 | L31: 30/05/2011 | N31: 14 | P31: 000.000.000-00 | S31: 21/01/2022 | V31: M11 | W31: D | Y31: FILHO(A) | AC31: MENSALIDADE SAUDE-14 - MULTIPLAN CE ENFERMARIA SEM COPART COM OBST | AH31: 1 | AI31: 393.45 | AJ31: 393.45 | AK31: 000.000.000-00 | AL31: 6 | AM31: 3010.18 | AN31: =SUMIFS(planos!D:D,planos!B:B,"<="&unimed!N31,planos!C:C,">="&unimed!N31,planos!E:E,"Enfermaria sem coparticipação") -> 393.4522 | AO31: =IF(AJ31=0,0,IF(MID(AC31,1,15)="FATOR MODERADOR",AJ31,IF(AM31>=0,IF(AND(AM31>tabelas!$C$4,AM31<=tabelas!$C$5),(AN31)*tabelas!$D$4,IF(AND(AM31>=tabelas!$C$5,AM31<=tabelas!$C$6),(AN31)*tabelas!$D$5,IF(AND(AM31>=tabelas!$C$6,AM31<=tabelas!$C$7),(AN31)*tabelas!$D$6,IF(AND(AM31>0,AM31>tabelas!$C$7),(AN31)*tabelas!$D$7,0))))))) -> 365.91055 | AP31: =IF(MID(AC31,1,15)="FATOR MODERADOR",0,IF(MID(AC31,1,21)="RECOMPOSIÇÃO REAJUSTE",0,IF(AH31=1,AO31,AO31*AH31/30))) -> 365.91055 | AQ31: =AJ31-AP31 -> 27.539453 | AR31: =IF(IFERROR(SEARCH("PRORATA",AC31),0)=13,2030,IF(IFERROR(SEARCH("FATOR MODERADOR",AC31),0)=1,613,0)) -> 0 | AS31: =AJ31-AP31-AQ31 -> 0
A32: MARIA | E32: 703 | F32: 0 | I32: Colaborador 6 | L32: 07/08/2008 | N32: 17 | P32: 000.000.000-00 | S32: 21/01/2022 | V32: M11 | W32: D | Y32: FILHO(A) | AC32: MENSALIDADE SAUDE-14 - MULTIPLAN CE ENFERMARIA SEM COPART COM OBST | AH32: 1 | AI32: 393.45 | AJ32: 393.45 | AK32: 000.000.000-00 | AL32: 6 | AM32: 3603.46 | AN32: =SUMIFS(planos!D:D,planos!B:B,"<="&unimed!N32,planos!C:C,">="&unimed!N32,planos!E:E,"Enfermaria sem coparticipação") -> 393.4522 | AO32: =IF(AJ32=0,0,IF(MID(AC32,1,15)="FATOR MODERADOR",AJ32,IF(AM32>=0,IF(AND(AM32>tabelas!$C$4,AM32<=tabelas!$C$5),(AN32)*tabelas!$D$4,IF(AND(AM32>=tabelas!$C$5,AM32<=tabelas!$C$6),(AN32)*tabelas!$D$5,IF(AND(AM32>=tabelas!$C$6,AM32<=tabelas!$C$7),(AN32)*tabelas!$D$6,IF(AND(AM32>0,AM32>tabelas!$C$7),(AN32)*tabelas!$D$7,0))))))) -> 365.91055 | AP32: =IF(MID(AC32,1,15)="FATOR MODERADOR",0,IF(MID(AC32,1,21)="RECOMPOSIÇÃO REAJUSTE",0,IF(AH32=1,AO32,AO32*AH32/30))) -> 365.91055 | AQ32: =AJ32-AP32 -> 27.539453 | AR32: =IF(IFERROR(SEARCH("PRORATA",AC32),0)=13,2030,IF(IFERROR(SEARCH("FATOR MODERADOR",AC32),0)=1,613,0)) -> 0 | AS32: =AJ32-AP32-AQ32 -> 0
A33: JOAO | E33: 703 | F33: 0 | I33: Colaborador 6 | L33: 06/01/1993 | N33: 32 | P33: 000.000.000-00 | S33: 21/01/2022 | V33: M11 | W33: D | Y33: ESPOSO(A) | AC33: MENSALIDADE SAUDE-14 - MULTIPLAN CE ENFERMARIA SEM COPART COM OBST | AH33: 1 | AI33: 559.92 | AJ33: 559.92 | AK33: 000.000.000-00 | AL33: 6 | AM33: 6032.51 | AN33: =SUMIFS(planos!D:D,planos!B:B,"<="&unimed!N33,planos!C:C,">="&unimed!N33,planos!E:E,"Enfermaria sem coparticipação") -> 559.91758 | AO33: =IF(AJ33=0,0,IF(MID(AC33,1,15)="FATOR MODERADOR",AJ33,IF(AM33>=0,IF(AND(AM33>tabelas!$C$4,AM33<=tabelas!$C$5),(AN33)*tabelas!$D$4,IF(AND(AM33>=tabelas!$C$5,AM33<=tabelas!$C$6),(AN33)*tabelas!$D$5,IF(AND(AM33>=tabelas!$C$6,AM33<=tabelas!$C$7),(AN33)*tabelas!$D$6,IF(AND(AM33>0,AM33>tabelas!$C$7),(AN33)*tabelas!$D$7,0))))))) -> 475.92995 | AP33: =IF(MID(AC33,1,15)="FATOR MODERADOR",0,IF(MID(AC33,1,21)="RECOMPOSIÇÃO REAJUSTE",0,IF(AH33=1,AO33,AO33*AH33/30))) -> 475.92995 | AQ33: =AJ33-AP33 -> 83.990054 | AR33: =IF(IFERROR(SEARCH("PRORATA",AC33),0)=13,2030,IF(IFERROR(SEARCH("FATOR MODERADOR",AC33),0)=1,613,0)) -> 0 | AS33: =AJ33-AP33-AQ33 -> 0
A34: MARIA | E34: 703 | F34: 0 | I34: Colaborador 6 | L34: 15/10/2024 | N34: 1 | P34: 000.000.000-00 | S34: 28/10/2024 | V34: M11 | W34: D | Y34: FILHO(A) | AC34: MENSALIDADE SAUDE-14 - MULTIPLAN CE ENFERMARIA SEM COPART COM OBST | AH34: 1 | AI34: 393.45 | AJ34: 393.45 | AK34: 000.000.000-00 | AL34: 6 | AM34: 7742.75 | AN34: =SUMIFS(planos!D:D,planos!B:B,"<="&unimed!N34,planos!C:C,">="&unimed!N34,planos!E:E,"Enfermaria sem coparticipação") -> 393.4522 | AO34: =IF(AJ34=0,0,IF(MID(AC34,1,15)="FATOR MODERADOR",AJ34,IF(AM34>=0,IF(AND(AM34>tabelas!$C$4,AM34<=tabelas!$C$5),(AN34)*tabelas!$D$4,IF(AND(AM34>=tabelas!$C$5,AM34<=tabelas!$C$6),(AN34)*tabelas!$D$5,IF(AND(AM34>=tabelas!$C$6,AM34<=tabelas!$C$7),(AN34)*tabelas!$D$6,IF(AND(AM34>0,AM34>tabelas!$C$7),(AN34)*tabelas!$D$7,0))))))) -> 302.9582 | AP34: =IF(MID(AC34,1,15)="FATOR MODERADOR",0,IF(MID(AC34,1,21)="RECOMPOSIÇÃO REAJUSTE",0,IF(AH34=1,AO34,AO34*AH34/30))) -> 302.9582 | AQ34: =AJ34-AP34 -> 90.491805 | AR34: =IF(IFERROR(SEARCH("PRORATA",AC34),0)=13,2030,IF(IFERROR(SEARCH("FATOR MODERADOR",AC34),0)=1,613,0)) -> 0 | AS34: =AJ34-AP34-AQ34 -> 0
A35: JOAO | E35: 827 | F35: 0 | I35: Colaborador 7 | L35: 24/08/1992 | N35: 33 | P35: 000.000.000-00 | S35: 23/05/2022 | V35: M11 | W35: T | Y35: TITULAR | AC35: MENSALIDADE SAUDE-14 - MULTIPLAN CE ENFERMARIA SEM COPART COM OBST | AH35: 1 | AI35: 559.92 | AJ35: 559.92 | AK35: 000.000.000-00 | AL35: 7 | AM35: 7131.14 | AN35: =SUMIFS(planos!D:D,planos!B:B,"<="&unimed!N35,planos!C:C,">="&unimed!N35,planos!E:E,"Enfermaria sem coparticipação") -> 559.91758 | AO35: =IF(AJ35=0,0,IF(MID(AC35,1,15)="FATOR MODERADOR",AJ35,IF(AM35>=0,IF(AND(AM35>tabelas!$C$4,AM35<=tabelas!$C$5),(AN35)*tabelas!$D$4,IF(AND(AM35>=tabelas!$C$5,AM35<=tabelas!$C$6),(AN35)*tabelas!$D$5,IF(AND(AM35>=tabelas!$C$6,AM35<=tabelas!$C$7),(AN35)*tabelas!$D$6,IF(AND(AM35>0,AM35>tabelas!$C$7),(AN35)*tabelas!$D$7,0))))))) -> 475.92995 | AP35: =IF(MID(AC35,1,15)="FATOR MODERADOR",0,IF(MID(AC35,1,21)="RECOMPOSIÇÃO REAJUSTE",0,IF(AH35=1,AO35,AO35*AH35/30))) -> 475.92995 | AQ35: =AJ35-AP35 -> 83.990054 | AR35: =IF(IFERROR(SEARCH("PRORATA",AC35),0)=13,2030,IF(IFERROR(SEARCH("FATOR MODERADOR",AC35),0)=1,613,0)) -> 0 | AS35: =AJ35-AP35-AQ35 -> 0
A36: MARIA | E36: 827 | F36: 0 | I36: Colaborador 7 | L36: 28/03/1997 | N36: 28 | P36: 000.000.000-00 | S36: 23/05/2022 | V36: M11 | W36: D | Y36: ESPOSO(A) | AC36: MENSALIDADE SAUDE-14 - MULTIPLAN CE ENFERMARIA SEM COPART COM OBST | AH36: 1 | AI36: 559.92 | AJ36: 559.92 | AK36: 000.000.000-00 | AL36: 7 | AM36: 7364.72 | AN36: =SUMIFS(planos!D:D,planos!B:B,"<="&unimed!N36,planos!C:C,">="&unimed!N36,planos!E:E,"Enfermaria sem coparticipação") -> 559.91758 | AO36: =IF(AJ36=0,0,IF(MID(AC36,1,15)="FATOR MODERADOR",AJ36,IF(AM36>=0,IF(AND(AM36>tabelas!$C$4,AM36<=tabelas!$C$5),(AN36)*tabelas!$D$4,IF(AND(AM36>=tabelas!$C$5,AM36<=tabelas!$C$6),(AN36)*tabelas!$D$5,IF(AND(AM36>=tabelas!$C$6,AM36<=tabelas!$C$7),(AN36)*tabelas!$D$6,IF(AND(AM36>0,AM36>tabelas!$C$7),(AN36)*tabelas!$D$7,0))))))) -> 475.92995 | AP36: =IF(MID(AC36,1,15)="FATOR MODERADOR",0,IF(MID(AC36,1,21)="RECOMPOSIÇÃO REAJUSTE",0,IF(AH36=1,AO36,AO36*AH36/30))) -> 475.92995 | AQ36: =AJ36-AP36 -> 83.990054 | AR36: =IF(IFERROR(SEARCH("PRORATA",AC36),0)=13,2030,IF(IFERROR(SEARCH("FATOR MODERADOR",AC36),0)=1,613,0)) -> 0 | AS36: =AJ36-AP36-AQ36 -> 0
A37: JOAO | E37: 764 | F37: 0 | I37: Colaborador 8 | L37: 12/05/1990 | N37: 35 | P37: 000.000.000-00 | S37: 26/02/2022 | V37: M11 | W37: T | Y37: TITULAR | AC37: MENSALIDADE SAUDE-14 - MULTIPLAN CE ENFERMARIA SEM COPART COM OBST | AH37: 1 | AI37: 694.48 | AJ37: 694.48 | AK37: 000.000.000-00 | AL37: 8 | AM37: 5245.5 | AN37: =SUMIFS(planos!D:D,planos!B:B,"<="&unimed!N37,planos!C:C,">="&unimed!N37,planos!E:E,"Enfermaria sem coparticipação") -> 694.48106 | AO37: =IF(AJ37=0,0,IF(MID(AC37,1,15)="FATOR MODERADOR",AJ37,IF(AM37>=0,IF(AND(AM37>tabelas!$C$4,AM37<=tabelas!$C$5),(AN37)*tabelas!$D$4,IF(AND(AM37>=tabelas!$C$5,AM37<=tabelas!$C$6),(AN37)*tabelas!$D$5,IF(AND(AM37>=tabelas!$C$6,AM37<=tabelas!$C$7),(AN37)*tabelas!$D$6,IF(AND(AM37>0,AM37>tabelas!$C$7),(AN37)*tabelas!$D$7,0))))))) -> 590.3089 | AP37: =IF(MID(AC37,1,15)="FATOR MODERADOR",0,IF(MID(AC37,1,21)="RECOMPOSIÇÃO REAJUSTE",0,IF(AH37=1,AO37,AO37*AH37/30))) -> 590.3089 | AQ37: =AJ37-AP37 -> 104.1711 | AR37: =IF(IFERROR(SEARCH("PRORATA",AC37),0)=13,2030,IF(IFERROR(SEARCH("FATOR MODERADOR",AC37),0)=1,613,0)) -> 0 | AS37: =AJ37-AP37-AQ37 -> 0
A38: MARIA | E38: 715 | F38: 0 | I38: Colaborador 9 | L38: 02/04/1991 | N38: 34 | P38: 000.000.000-00 | S38: 21/01/2022 | V38: M11 | W38: T | Y38: TITULAR | AC38: MENSALIDADE SAUDE-14 - MULTIPLAN CE ENFERMARIA SEM COPART COM OBST | AH38: 1 | AI38: 694.48 | AJ38: 694.48 | AK38: 000.000.000-00 | AL38: 9 | AM38: 4229.32 | AN38: =SUMIFS(planos!D:D,planos!B:B,"<="&unimed!N38,planos!C:C,">="&unimed!N38,planos!E:E,"Enfermaria sem coparticipação") -> 694.48106 | AO38: =IF(AJ38=0,0,IF(MID(AC38,1,15)="FATOR MODERADOR",AJ38,IF(AM38>=0,IF(AND(AM38>tabelas!$C$4,AM38<=tabelas!$C$5),(AN38)*tabelas!$D$4,IF(AND(AM38>=tabelas!$C$5,AM38<=tabelas!$C$6),(AN38)*tabelas!$D$5,IF(AND(AM38>=tabelas!$C$6,AM38<=tabelas!$C$7),(AN38)*tabelas!$D$6,IF(AND(AM38>0,AM38>tabelas!$C$7),(AN38)*tabelas!$D$7,0))))))) -> 590.3089 | AP38: =IF(MID(AC38,1,15)="FATOR MODERADOR",0,IF(MID(AC38,1,21)="RECOMPOSIÇÃO REAJUSTE",0,IF(AH38=1,AO38,AO38*AH38/30))) -> 590.3089 | AQ38: =AJ38-AP38 -> 104.1711 | AR38: =IF(IFERROR(SEARCH("PRORATA",AC38),0)=13,2030,IF(IFERROR(SEARCH("FATOR MODERADOR",AC38),0)=1,613,0)) -> 0 | AS38: =AJ38-AP38-AQ38 -> 0
A39: JOAO | E39: 715 | F39: 0 | I39: Colaborador 9 | L39: 04/10/1992 | N39: 33 | P39: 000.000.000-00 | S39: 01/01/2026 | V39: M51 | W39: D | Y39: ESPOSO(A) | AC39: MENSALIDADE SAUDE-15 - MULTIPLAN CE APARTAMENTO SEM COPART COM OBST | AH39: 1 | AI39: 755.88 | AJ39: 755.88 | AK39: 000.000.000-00 | AL39: 9 | AM39: 7034.3 | AN39: =SUMIFS(planos!D:D,planos!B:B,"<="&unimed!N39,planos!C:C,">="&unimed!N39,planos!E:E,"Enfermaria sem coparticipação") -> 559.91758 | AO39: =IF(AJ39=0,0,IF(MID(AC39,1,15)="FATOR MODERADOR",AJ39,IF(AM39>=0,IF(AND(AM39>tabelas!$C$4,AM39<=tabelas!$C$5),(AN39)*tabelas!$D$4,IF(AND(AM39>=tabelas!$C$5,AM39<=tabelas!$C$6),(AN39)*tabelas!$D$5,IF(AND(AM39>=tabelas!$C$6,AM39<=tabelas!$C$7),(AN39)*tabelas!$D$6,IF(AND(AM39>0,AM39>tabelas!$C$7),(AN39)*tabelas!$D$7,0))))))) -> 475.92995 | AP39: =IF(MID(AC39,1,15)="FATOR MODERADOR",0,IF(MID(AC39,1,21)="RECOMPOSIÇÃO REAJUSTE",0,IF(AH39=1,AO39,AO39*AH39/30))) -> 475.92995 | AQ39: =AJ39-AP39 -> 279.95005 | AR39: =IF(IFERROR(SEARCH("PRORATA",AC39),0)=13,2030,IF(IFERROR(SEARCH("FATOR MODERADOR",AC39),0)=1,613,0)) -> 0 | AS39: =AJ39-AP39-AQ39 -> 0
... A55: JOAO | E55: 540 | F55: 0 | I55: Colaborador 15 | L55: 25/06/1999 | N55: 26 | P55: 000.000.000-00 | S55: 04/05/2022 | V55: M51 | W55: D | Y55: COMPANHEIRO(A) | AC55: MENSALIDADE SAUDE-15 - MULTIPLAN CE APARTAMENTO SEM COPART COM OBST | AH55: 1 | AI55: 755.88 | AJ55: 755.88 | AK55: 000.000.000-00 | AL55: 15 | AM55: 6375.93 | AN55: =SUMIFS(planos!D:D,planos!B:B,"<="&unimed!N55,planos!C:C,">="&unimed!N55,planos!E:E,"Enfermaria sem coparticipação") -> 559.91758 | AO55: =IF(AJ55=0,0,IF(MID(AC55,1,15)="FATOR MODERADOR",AJ55,IF(AM55>=0,IF(AND(AM55>tabelas!$C$4,AM55<=tabelas!$C$5),(AN55)*tabelas!$D$4,IF(AND(AM55>=tabelas!$C$5,AM55<=tabelas!$C$6),(AN55)*tabelas!$D$5,IF(AND(AM55>=tabelas!$C$6,AM55<=tabelas!$C$7),(AN55)*tabelas!$D$6,IF(AND(AM55>0,AM55>tabelas!$C$7),(AN55)*tabelas!$D$7,0))))))) -> 475.92995 | AP55: =IF(MID(AC55,1,15)="FATOR MODERADOR",0,IF(MID(AC55,1,21)="RECOMPOSIÇÃO REAJUSTE",0,IF(AH55=1,AO55,AO55*AH55/30))) -> 475.92995 | AQ55: =AJ55-AP55 -> 279.95005 | AR55: =IF(IFERROR(SEARCH("PRORATA",AC55),0)=13,2030,IF(IFERROR(SEARCH("FATOR MODERADOR",AC55),0)=1,613,0)) -> 0 | AS55: =AJ55-AP55-AQ55 -> 0
...

Sheet planos
B2: Faixa Etária | D2: Valor individual | E2: Tipo Plano | F2: 0.0935
B3: 0 | C3: 18 | D3: 393.4522 | E3: Enfermaria sem coparticipação
B4: =C3+1 -> 19 | C4: 23 | D4: 452.45118 | E4: Enfermaria sem coparticipação
B5: =C4+1 -> 24 | C5: 28 | D5: 559.91758 | E5: Enfermaria sem coparticipação
B6: =C5+1 -> 29 | C6: 33 | D6: 559.91758 | E6: Enfermaria sem coparticipação
B7: =C6+1 -> 34 | C7: 38 | D7: 694.48106 | E7: Enfermaria sem coparticipação
B8: =C7+1 -> 39 | C8: 43 | D8: 694.48106 | E8: Enfermaria sem coparticipação
B9: =C8+1 -> 44 | C9: 48 | D9: 1123.0245 | E9: Enfermaria sem coparticipação
B10: =C9+1 -> 49 | C10: 53 | D10: 1123.0245 | E10: Enfermaria sem coparticipação
B11: =C10+1 -> 54 | C11: 58 | D11: 1705.1458 | E11: Enfermaria sem coparticipação
B12: 59 | C12: 100 | D12: 2360.5596 | E12: Enfermaria sem coparticipação
B13: 0 | C13: 18 | D13: 531.20028 | E13: Apartamento sem coparticipação
B14: =C13+1 -> 19 | C14: 23 | D14: 610.78744 | E14: Apartamento sem coparticipação
B15: =C14+1 -> 24 | C15: 28 | D15: 755.88245 | E15: Apartamento sem coparticipação
B16: =C15+1 -> 29 | C16: 33 | D16: 755.88245 | E16: Apartamento sem coparticipação
B17: =C16+1 -> 34 | C17: 38 | D17: 937.55851 | E17: Apartamento sem coparticipação
B18: =C17+1 -> 39 | C18: 43 | D18: 937.55851 | E18: Apartamento sem coparticipação
B19: =C18+1 -> 44 | C19: 48 | D19: 1516.1 | E19: Apartamento sem coparticipação
B20: =C19+1 -> 49 | C20: 53 | D20: 1516.1 | E20: Apartamento sem coparticipação
B21: =C20+1 -> 54 | C21: 58 | D21: 2301.9517 | E21: Apartamento sem coparticipação
B22: 59 | C22: 100 | D22: 3186.7547 | E22: Apartamento sem coparticipação
B23: 0 | C23: 18 | D23: 421.06311 | E23: Apartamento com coparticipação
B24: =C23+1 -> 19 | C24: 23 | D24: 484.19907 | E24: Apartamento com coparticipação
B25: =C24+1 -> 24 | C25: 28 | D25: 599.21 | E25: Apartamento com coparticipação
B26: =C25+1 -> 29 | C26: 33 | D26: 599.21 | E26: Apartamento com coparticipação
B27: =C26+1 -> 34 | C27: 38 | D27: 743.19727 | E27: Apartamento com coparticipação
B28: =C27+1 -> 39 | C28: 43 | D28: 743.19727 | E28: Apartamento com coparticipação
B29: =C28+1 -> 44 | C29: 48 | D29: 1201.833 | E29: Apartamento com coparticipação
B30: =C29+1 -> 49 | C30: 53 | D30: 1201.833 | E30: Apartamento com coparticipação
B31: =C30+1 -> 54 | C31: 58 | D31: 1824.7781 | E31: Apartamento com coparticipação
B32: 59 | C32: 100 | D32: 2526.1818 | E32: Apartamento com coparticipação
B33: 0 | C33: 18 | D33: 311.91716 | E33: Enfermaria com coparticipação
B34: =C33+1 -> 19 | C34: 23 | D34: 358.668 | E34: Enfermaria com coparticipação
B35: =C34+1 -> 24 | C35: 28 | D35: 443.84071 | E35: Enfermaria com coparticipação
B36: =C35+1 -> 29 | C36: 33 | D36: 443.84071 | E36: Enfermaria com coparticipação
B37: =C36+1 -> 34 | C37: 38 | D37: 550.51 | E37: Enfermaria com coparticipação
B38: =C37+1 -> 39 | C38: 43 | D38: 550.51 | E38: Enfermaria com coparticipação
B39: =C38+1 -> 44 | C39: 48 | D39: 890.26209 | E39: Enfermaria com coparticipação
B40: =C39+1 -> 49 | C40: 53 | D40: 890.26209 | E40: Enfermaria com coparticipação
B41: =C40+1 -> 54 | C41: 58 | D41: 1351.6863 | E41: Enfermaria com coparticipação
...

Sheet tabelas
C2: TABELA DESCONTO UNIMED
C3: FAIXA SALARIAL | D3: ATLANTICO | E3: COLABORADOR
C4: 0 | D4: 0.93 | E4: 0.07
C5: 3712.1375 | D5: 0.85 | E5: 0.15
C6: 7411.3001 | D6: 0.77 | E6: 0.23
C7: 15265.628 | D7: 0.69 | E7: 0.31
