Workbook

Sheet bradesco
M2: =SUM(M5:M168) -> 4818.73 | O2: 46022
B3: Certif. | C3: MAT | D3: Nome Segurado | E3: Data Nascimento | F3: Sexo | G3: Est. Civil | H3: Paren. | I3: Plano | J3: Data Início | K3: M o v. | L3: Lançamento | M3: X | N3: Y | O3: idade | P3: CPF Titular | Q3: Matricula Titular | R3: Salário Titular | S3: Plano Base Atlântico | T3: Custo | V3: DESCONTO COLABORADOR
B5: 0000019/00 | C5: 1 | D5: Colaborador 5 | E5: 25869 | F5: MAS | G5: CAS | I5: TNEE | J5: 44531 | L5: 01/2026 | M5: 29.93 | O5: 0 | P5: 000.000.000-00 | R5: 7392.51 | S5: 29.93 | T5: =IF(R5>=0,IF(AND(R5>tabelas!$C$4,R5<=tabelas!$C$5),(S5)*tabelas!$D$4,IF(AND(R5>=tabelas!$C$5,R5<=tabelas!$C$6),(S5)*tabelas!$D$5,IF(AND(R5>=tabelas!$C$6,R5<=tabelas!$C$7),(S5)*tabelas!$D$6,IF(AND(R5>0,R5>tabelas!$C$7),(S5)*tabelas!$D$7,0))))) -> 25.4405 | V5: =M5-T5 -> 4.4895
B6: 0000019/01 | C6: 2 | D6: Colaborador 6 | E6: 26545 | F6: FEM | G6: CAS | H6: CONJ | I6: TNEE | J6: 44531 | L6: 01/2026 | M6: 29.93 | O6: 0 | P6: 000.000.000-00 | R6: 5535.35 | S6: 29.93 | T6: =IF(R6>=0,IF(AND(R6>tabelas!$C$4,R6<=tabelas!$C$5),(S6)*tabelas!$D$4,IF(AND(R6>=tabelas!$C$5,R6<=tabelas!$C$6),(S6)*tabelas!$D$5,IF(AND(R6>=tabelas!$C$6,R6<=tabelas!$C$7),(S6)*tabelas!$D$6,IF(AND(R6>0,R6>tabelas!$C$7),(S6)*tabelas!$D$7,0))))) -> 25.4405 | V6: =M6-T6 -> 4.4895
B7: 0000019/02 | C7: 3 | D7: Colaborador 7 | E7: 43238 | F7: FEM | G7: SOLT | H7: FILH | I7: TNEE | J7: 44531 | L7: 01/2026 | M7: 29.93 | O7: 0 | P7: 000.000.000-00 | R7: 4675.68 | S7: 29.93 | T7: =IF(R7>=0,IF(AND(R7>tabelas!$C$4,R7<=tabelas!$C$5),(S7)*tabelas!$D$4,IF(AND(R7>=tabelas!$C$5,R7<=tabelas!$C$6),(S7)*tabelas!$D$5,IF(AND(R7>=tabelas!$C$6,R7<=tabelas!$C$7),(S7)*tabelas!$D$6,IF(AND(R7>0,R7>tabelas!$C$7),(S7)*tabelas!$D$7,0))))) -> 25.4405 | V7: =M7-T7 -> 4.4895
B8: 0000019/03 | C8: 4 | D8: Colaborador 8 | E8: 40070 | F8: MAS | G8: SOLT | H8: FILH | I8: TNEE | J8: 44531 | L8: 01/2026 | M8: 29.93 | O8: 0 | P8: 000.000.000-00 | R8: 7718.11 | S8: 29.93 | T8: =IF(R8>=0,IF(AND(R8>tabelas!$C$4,R8<=tabelas!$C$5),(S8)*tabelas!$D$4,IF(AND(R8>=tabelas!$C$5,R8<=tabelas!$C$6),(S8)*tabelas!$D$5,IF(AND(R8>=tabelas!$C$6,R8<=tabelas!$C$7),(S8)*tabelas!$D$6,IF(AND(R8>0,R8>tabelas!$C$7),(S8)*tabelas!$D$7,0))))) -> 23.0461 | V8: =M8-T8 -> 6.8839
B9: 0000019/04 | C9: 5 | D9: Colaborador 9 | E9: 33646 | F9: MAS | G9: CAS | I9: TNQQ | J9: 44531 | L9: 01/2026 | M9: 29.93 | O9: 0 | P9: 000.000.000-00 | R9: 6012.94 | S9: 29.93 | T9: =IF(R9>=0,IF(AND(R9>tabelas!$C$4,R9<=tabelas!$C$5),(S9)*tabelas!$D$4,IF(AND(R9>=tabelas!$C$5,R9<=tabelas!$C$6),(S9)*tabelas!$D$5,IF(AND(R9>=tabelas!$C$6,R9<=tabelas!$C$7),(S9)*tabelas!$D$6,IF(AND(R9>0,R9>tabelas!$C$7),(S9)*tabelas!$D$7,0))))) -> 25.4405 | V9: =M9-T9 -> 4.4895
B10: 0000027/00 | C10: 6 | D10: Colaborador 10 | E10: 33671 | F10: FEM | G10: CAS | H10: CONJ | I10: TNQQ | J10: 44531 | L10: 01/2026 | M10: 29.93 | O10: 0 | P10: 000.000.000-00 | R10: 6226.87 | S10: 29.93 | T10: =IF(R10>=0,IF(AND(R10>tabelas!$C$4,R10<=tabelas!$C$5),(S10)*tabelas!$D$4,IF(AND(R10>=tabelas!$C$5,R10<=tabelas!$C$6),(S10)*tabelas!$D$5,IF(AND(R10>=tabelas!$C$6,R10<=tabelas!$C$7),(S10)*tabelas!$D$6,IF(AND(R10>0,R10>tabelas!$C$7),(S10)*tabelas!$D$7,0))))) -> 25.4405 | V10: =M10-T10 -> 4.4895
B11: 0000027/01 | C11: 7 | D11: Colaborador 11 | E11: 41597 | F11: MAS | G11: SOLT | H11: FILH | I11: TNQQ | J11: 44531 | L11: 01/2026 | M11: 29.93 | O11: 0 | P11: 000.000.000-00 | R11: 6382.49 | S11: 29.93 | T11: =IF(R11>=0,IF(AND(R11>tabelas!$C$4,R11<=tabelas!$C$5),(S11)*tabelas!$D$4,IF(AND(R11>=tabelas!$C$5,R11<=tabelas!$C$6),(S11)*tabelas!$D$5,IF(AND(R11>=tabelas!$C$6,R11<=tabelas!$C$7),(S11)*tabelas!$D$6,IF(AND(R11>0,R11>tabelas!$C$7),(S11)*tabelas!$D$7,0))))) -> 25.4405 | V11: =M11-T11 -> 4.4895
B12: 0000027/02 | C12: 8 | D12: Colaborador 12 | E12: 43027 | F12: MAS | G12: SOLT | H12: FILH | I12: TNQQ | J12: 44531 | L12: 01/2026 | M12: 29.93 | O12: 0 | P12: 000.000.000-00 | R12: 7725.51 | S12: 29.93 | T12: =IF(R12>=0,IF(AND(R12>tabelas!$C$4,R12<=tabelas!$C$5),(S12)*tabelas!$D$4,IF(AND(R12>=tabelas!$C$5,R12<=tabelas!$C$6),(S12)*tabelas!$D$5,IF(AND(R12>=tabelas!$C$6,R12<=tabelas!$C$7),(S12)*tabelas!$D$6,IF(AND(R12>0,R12>tabelas!$C$7),(S12)*tabelas!$D$7,0))))) -> 23.0461 | V12: =M12-T12 -> 6.8839
B13: 0000027/03 | C13: 9 | D13: Colaborador 13 | E13: 44093 | F13: MAS | G13: SOLT | H13: FILH | I13: TNQQ | J13: 44531 | L13: 01/2026 | M13: 29.93 | O13: 0 | P13: 000.000.000-00 | R13: 5442.99 | S13: 29.93 | T13: =IF(R13>=0,IF(AND(R13>tabelas!$C$4,R13<=tabelas!$C$5),(S13)*tabelas!$D$4,IF(AND(R13>=tabelas!$C$5,R13<=tabelas!$C$6),(S13)*tabelas!$D$5,IF(AND(R13>=tabelas!$C$6,R13<=tabelas!$C$7),(S13)*tabelas!$D$6,IF(AND(R13>0,R13>tabelas!$C$7),(S13)*tabelas!$D$7,0))))) -> 25.4405 | V13: =M13-T13 -> 4.4895
B14: 0000027/04 | C14: 10 | D14: Colaborador 14 | E14: 31960 | F14: FEM | G14: SOLT | I14: TNEE | J14: 44531 | L14: 01/2026 | M14: 29.93 | O14: 0 | P14: 000.000.000-00 | R14: 2741.17 | S14: 29.93 | T14: =IF(R14>=0,IF(AND(R14>tabelas!$C$4,R14<=tabelas!$C$5),(S14)*tabelas!$D$4,IF(AND(R14>=tabelas!$C$5,R14<=tabelas!$C$6),(S14)*tabelas!$D$5,IF(AND(R14>=tabelas!$C$6,R14<=tabelas!$C$7),(S14)*tabelas!$D$6,IF(AND(R14>0,R14>tabelas!$C$7),(S14)*tabelas!$D$7,0))))) -> 27.8349 | V14: =M14-T14 -> 2.0951
B15: 0000035/00 | C15: 11 | D15: Colaborador 15 | E15: 32851 | F15: FEM | G15: CAS | H15: CONJ | I15: TNEE | J15: 44944 | L15: 01/2026 | M15: 29.93 | O15: 0 | P15: 000.000.000-00 | R15: 7930.49 | S15: 29.93 | T15: =IF(R15>=0,IF(AND(R15>tabelas!$C$4,R15<=tabelas!$C$5),(S15)*tabelas!$D$4,IF(AND(R15>=tabelas!$C$5,R15<=tabelas!$C$6),(S15)*tabelas!$D$5,IF(AND(R15>=tabelas!$C$6,R15<=tabelas!$C$7),(S15)*tabelas!$D$6,IF(AND(R15>0,R15>tabelas!$C$7),(S15)*tabelas!$D$7,0))))) -> 23.0461 | V15: =M15-T15 -> 6.8839
B16: 0000051/00 | C16: 12 | D16: Colaborador 16 | E16: 35494 | F16: MAS | G16: CAS | I16: TNQQ | J16: 44531 | L16: 01/2026 | M16: 29.93 | O16: 0 | P16: 000.000.000-00 | R16: 7094.63 | S16: 29.93 | T16: =IF(R16>=0,IF(AND(R16>tabelas!$C$4,R16<=tabelas!$C$5),(S16)*tabelas!$D$4,IF(AND(R16>=tabelas!$C$5,R16<=tabelas!$C$6),(S16)*tabelas!$D$5,IF(AND(R16>=tabelas!$C$6,R16<=tabelas!$C$7),(S16)*tabelas!$D$6,IF(AND(R16>0,R16>tabelas!$C$7),(S16)*tabelas!$D$7,0))))) -> 25.4405 | V16: =M16-T16 -> 4.4895
B17: 0000060/00 | C17: 13 | D17: Colaborador 17 | E17: 36298 | F17: FEM | G17: CAS | H17: CONJ | I17: TNQQ | J17: 44531 | L17: 01/2026 | M17: 29.93 | O17: 0 | P17: 000.000.000-00 | R17: 3011.43 | S17: 29.93 | T17: =IF(R17>=0,IF(AND(R17>tabelas!$C$4,R17<=tabelas!$C$5),(S17)*tabelas!$D$4,IF(AND(R17>=tabelas!$C$5,R17<=tabelas!$C$6),(S17)*tabelas!$D$5,IF(AND(R17>=tabelas!$C$6,R17<=tabelas!$C$7),(S17)*tabelas!$D$6,IF(AND(R17>0,R17>tabelas!$C$7),(S17)*tabelas!$D$7,0))))) -> 27.8349 | V17: =M17-T17 -> 2.0951
B18: 0000078/00 | C18: 14 | D18: Colaborador 18 | E18: 30548 | F18: MAS | G18: SOLT | I18: TNEE | J18: 44531 | L18: 01/2026 | M18: 29.93 | O18: 0 | P18: 000.000.000-00 | R18: 3956.56 | S18: 29.93 | T18: =IF(R18>=0,IF(AND(R18>tabelas!$C$4,R18<=tabelas!$C$5),(S18)*tabelas!$D$4,IF(AND(R18>=tabelas!$C$5,R18<=tabelas!$C$6),(S18)*tabelas!$D$5,IF(AND(R18>=tabelas!$C$6,R18<=tabelas!$C$7),(S18)*tabelas!$D$6,IF(AND(R18>0,R18>tabelas!$C$7),(S18)*tabelas!$D$7,0))))) -> 25.4405 | V18: =M18-T18 -> 4.4895
B19: 0000078/01 | C19: 15 | D19: Colaborador 19 | E19: 41079 | F19: MAS | G19: SOLT | H19: FILH | I19: TNEE | J19: 44531 | L19: 01/2026 | M19: 29.93 | O19: 0 | P19: 000.000.000-00 | R19: 2358.33 | S19: 29.93 | T19: =IF(R19>=0,IF(AND(R19>tabelas!$C$4,R19<=tabelas!$C$5),(S19)*tabelas!$D$4,IF(AND(R19>=tabelas!$C$5,R19<=tabelas!$C$6),(S19)*tabelas!$D$5,IF(AND(R19>=tabelas!$C$6,R19<=tabelas!$C$7),(S19)*tabelas!$D$6,IF(AND(R19>0,R19>tabelas!$C$7),(S19)*tabelas!$D$7,0))))) -> 27.8349 | V19: =M19-T19 -> 2.0951
B20: 0000086/00 | C20: 16 | D20: Colaborador 20 | E20: 44136 | F20: FEM | G20: SOLT | H20: FILH | I20: TNEE | J20: 44531 | L20: 01/2026 | M20: 29.93 | O20: 0 | P20: 000.000.000-00 | R20: 5569.64 | S20: 29.93 | T20: =IF(R20>=0,IF(AND(R20>tabelas!$C$4,R20<=tabelas!$C$5),(S20)*tabelas!$D$4,IF(AND(R20>=tabelas!$C$5,R20<=tabelas!$C$6),(S20)*tabelas!$D$5,IF(AND(R20>=tabelas!$C$6,R20<=tabelas!$C$7),(S20)*tabelas!$D$6,IF(AND(R20>0,R20>tabelas!$C$7),(S20)*tabelas!$D$7,0))))) -> 25.4405 | V20: =M20-T20 -> 4.4895
B21: 0000094/00 | C21: 17 | D21: Colaborador 21 | E21: 44136 | F21: FEM | G21: SOLT | H21: FILH | I21: TNEE | J21: 44531 | L21: 01/2026 | M21: 29.93 | O21: 0 | P21: 000.000.000-00 | R21: 7534.26 | S21: 29.93 | T21: =IF(R21>=0,IF(AND(R21>tabelas!$C$4,R21<=tabelas!$C$5),(S21)*tabelas!$D$4,IF(AND(R21>=tabelas!$C$5,R21<=tabelas!$C$6),(S21)*tabelas!$D$5,IF(AND(R21>=tabelas!$C$6,R21<=tabelas!$C$7),(S21)*tabelas!$D$6,IF(AND(R21>0,R21>tabelas!$C$7),(S21)*tabelas!$D$7,0))))) -> 23.0461 | V21: =M21-T21 -> 6.8839
B22: 0000094/01 | C22: 18 | D22: Colaborador 22 | E22: 32714 | F22: MAS | G22: SOLT | I22: TNQQ | J22: 44531 | L22: 01/2026 | M22: 29.93 | O22: 0 | P22: 000.000.000-00 | R22: 6139.28 | S22: 29.93 | T22: =IF(R22>=0,IF(AND(R22>tabelas!$C$4,R22<=tabelas!$C$5),(S22)*tabelas!$D$4,IF(AND(R22>=tabelas!$C$5,R22<=tabelas!$C$6),(S22)*tabelas!$D$5,IF(AND(R22>=tabelas!$C$6,R22<=tabelas!$C$7),(S22)*tabelas!$D$6,IF(AND(R22>0,R22>tabelas!$C$7),(S22)*tabelas!$D$7,0))))) -> 25.4405 | V22: =M22-T22 -> 4.4895
B23: 0000094/02 | C23: 19 | D23: Colaborador 23 | E23: 33973 | F23: FEM | G23: SOLT | I23: TNQQ | J23: 44531 | L23: 01/2026 | M23: 29.93 | O23: 0 | P23: 000.000.000-00 | R23: 5923.96 | S23: 29.93 | T23: =IF(R23>=0,IF(AND(R23>tabelas!$C$4,R23<=tabelas!$C$5),(S23)*tabelas!$D$4,IF(AND(R23>=tabelas!$C$5,R23<=tabelas!$C$6),(S23)*tabelas!$D$5,IF(AND(R23>=tabelas!$C$6,R23<=tabelas!$C$7),(S23)*tabelas!$D$6,IF(AND(R23>0,R23>tabelas!$C$7),(S23)*tabelas!$D$7,0))))) -> 25.4405 | V23: =M23-T23 -> 4.4895
B24: 0000094/03 | C24: 20 | D24: Colaborador 24 | E24: 31799 | F24: FEM | G24: CAS | I24: TNEE | J24: 44531 | L24: 01/2026 | M24: 29.93 | O24: 0 | P24: 000.000.000-00 | R24: 5231.86 | S24: 29.93 | T24: =IF(R24>=0,IF(AND(R24>tabelas!$C$4,R24<=tabelas!$C$5),(S24)*tabelas!$D$4,IF(AND(R24>=tabelas!$C$5,R24<=tabelas!$C$6),(S24)*tabelas!$D$5,IF(AND(R24>=tabelas!$C$6,R24<=tabelas!$C$7),(S24)*tabelas!$D$6,IF(AND(R24>0,R24>tabelas!$C$7),(S24)*tabelas!$D$7,0))))) -> 25.4405 | V24: =M24-T24 -> 4.4895
B25: 0000108/00 | C25: 21 | D25: Colaborador 25 | E25: 31497 | F25: MAS | G25: SOLT | I25: TNEE | J25: 44531 | L25: 01/2026 | M25: 29.93 | O25: 0 | P25: 000.000.000-00 | R25: 1691 | S25: 29.93 | T25: =IF(R25>=0,IF(AND(R25>tabelas!$C$4,R25<=tabelas!$C$5),(S25)*tabelas!$D$4,IF(AND(R25>=tabelas!$C$5,R25<=tabelas!$C$6),(S25)*tabelas!$D$5,IF(AND(R25>=tabelas!$C$6,R25<=tabelas!$C$7),(S25)*tabelas!$D$6,IF(AND(R25>0,R25>tabelas!$C$7),(S25)*tabelas!$D$7,0))))) -> 27.8349 | V25: =M25-T25 -> 2.0951
B26: 0000116/00 | C26: 22 | D26: Colaborador 26 | E26: 30575 | F26: FEM | G26: CAS | H26: CONJ | I26: TNEE | J26: 44544 | L26: 01/2026 | M26: 29.93 | O26: 0 | P26: 000.000.000-00 | R26: 6905.09 | S26: 29.93 | T26: =IF(R26>=0,IF(AND(R26>tabelas!$C$4,R26<=tabelas!$C$5),(S26)*tabelas!$D$4,IF(AND(R26>=tabelas!$C$5,R26<=tabelas!$C$6),(S26)*tabelas!$D$5,IF(AND(R26>=tabelas!$C$6,R26<=tabelas!$C$7),(S26)*tabelas!$D$6,IF(AND(R26>0,R26>tabelas!$C$7),(S26)*tabelas!$D$7,0))))) -> 25.4405 | V26: =M26-T26 -> 4.4895
B27: 0000124/00 | C27: 23 | D27: Colaborador 27 | E27: 45097 | F27: MAS | G27: SOLT | H27: FILH | I27: TNEE | J27: 45108 | L27: 01/2026 | M27: 29.93 | O27: 0 | P27: 000.000.000-00 | R27: 1322.8 | S27: 29.93 | T27: =IF(R27>=0,IF(AND(R27>tabelas!$C$4,R27<=tabelas!$C$5),(S27)*tabelas!$D$4,IF(AND(R27>=tabelas!$C$5,R27<=tabelas!$C$6),(S27)*tabelas!$D$5,IF(AND(R27>=tabelas!$C$6,R27<=tabelas!$C$7),(S27)*tabelas!$D$6,IF(AND(R27>0,R27>tabelas!$C$7),(S27)*tabelas!$D$7,0))))) -> 27.8349 | V27: =M27-T27 -> 2.0951
B28: 0000132/00 | C28: 24 | D28: Colaborador 28 | E28: 33721 | F28: MAS | G28: SOLT | I28: TNEE | J28: 44602 | L28: 01/2026 | M28: 29.93 | O28: 0 | P28: 000.000.000-00 | R28: 3477.96 | S28: 29.93 | T28: =IF(R28>=0,IF(AND(R28>tabelas!$C$4,R28<=tabelas!$C$5),(S28)*tabelas!$D$4,IF(AND(R28>=tabelas!$C$5,R28<=tabelas!$C$6),(S28)*tabelas!$D$5,IF(AND(R28>=tabelas!$C$6,R28<=tabelas!$C$7),(S28)*tabelas!$D$6,IF(AND(R28>0,R28>tabelas!$C$7),(S28)*tabelas!$D$7,0))))) -> 27.8349 | V28: =M28-T28 -> 2.0951
B29: 0000132/01 | C29: 25 | D29: Colaborador 29 | E29: 34943 | F29: MAS | G29: SOLT | I29: TNQQ | J29: 44627 | L29: 01/2026 | M29: 29.93 | O29: 0 | P29: 000.000.000-00 | R29: 2584.41 | S29: 29.93 | T29: =IF(R29>=0,IF(AND(R29>tabelas!$C$4,R29<=tabelas!$C$5),(S29)*tabelas!$D$4,IF(AND(R29>=tabelas!$C$5,R29<=tabelas!$C$6),(S29)*tabelas!$D$5,IF(AND(R29>=tabelas!$C$6,R29<=tabelas!$C$7),(S29)*tabelas!$D$6,IF(AND(R29>0,R29>tabelas!$C$7),(S29)*tabelas!$D$7,0))))) -> 27.8349 | V29: =M29-T29 -> 2.0951
B30: 0000132/02 | C30: 26 | D30: Colaborador 30 | E30: 33366 | F30: MAS | G30: SOLT | I30: TNEE | J30: 44659 | L30: 01/2026 | M30: 29.93 | O30: 0 | P30: 000.000.000-00 | R30: 1961.89 | S30: 29.93 | T30: =IF(R30>=0,IF(AND(R30>tabelas!$C$4,R30<=tabelas!$C$5),(S30)*tabelas!$D$4,IF(AND(R30>=tabelas!$C$5,R30<=tabelas!$C$6),(S30)*tabelas!$D$5,IF(AND(R30>=tabelas!$C$6,R30<=tabelas!$C$7),(S30)*tabelas!$D$6,IF(AND(R30>0,R30>tabelas!$C$7),(S30)*tabelas!$D$7,0))))) -> 27.8349 | V30: =M30-T30 -> 2.0951
B31: 0000140/00 | C31: 27 | D31: Colaborador 31 | E31: 34288 | F31: MAS | G31: SOLT | H31: CONJ | I31: TNEE | J31: 45413 | L31: 01/2026 | M31: 29.93 | O31: 0 | P31: 000.000.000-00 | R31: 3406 | S31: 29.93 | T31: =IF(R31>=0,IF(AND(R31>tabelas!$C$4,R31<=tabelas!$C$5),(S31)*tabelas!$D$4,IF(AND(R31>=tabelas!$C$5,R31<=tabelas!$C$6),(S31)*tabelas!$D$5,IF(AND(R31>=tabelas!$C$6,R31<=tabelas!$C$7),(S31)*tabelas!$D$6,IF(AND(R31>0,R31>tabelas!$C$7),(S31)*tabelas!$D$7,0))))) -> 27.8349 | V31: =M31-T31 -> 2.0951
B32: 0000159/00 | C32: 28 | D32: Colaborador 32 | E32: 33143 | F32: FEM | G32: SOLT | I32: FCQX | J32: 44655 | L32: 01/2026 | M32: 29.93 | O32: 0 | P32: 000.000.000-00 | R32: 6180.88 | S32: 29.93 | T32: =IF(R32>=0,IF(AND(R32>tabelas!$C$4,R32<=tabelas!$C$5),(S32)*tabelas!$D$4,IF(AND(R32>=tabelas!$C$5,R32<=tabelas!$C$6),(S32)*tabelas!$D$5,IF(AND(R32>=tabelas!$C$6,R32<=tabelas!$C$7),(S32)*tabelas!$D$6,IF(AND(R32>0,R32>tabelas!$C$7),(S32)*tabelas!$D$7,0))))) -> 25.4405 | V32: =M32-T32 -> 4.4895
B33: 0000175/00 | C33: 29 | D33: Colaborador 33 | E33: 31352 | F33: FEM | G33: CAS | I33: TNEE | J33: 44697 | L33: 01/2026 | M33: 29.93 | O33: 0 | P33: 000.000.000-00 | R33: 4238.79 | S33: 29.93 | T33: =IF(R33>=0,IF(AND(R33>tabelas!$C$4,R33<=tabelas!$C$5),(S33)*tabelas!$D$4,IF(AND(R33>=tabelas!$C$5,R33<=tabelas!$C$6),(S33)*tabelas!$D$5,IF(AND(R33>=tabelas!$C$6,R33<=tabelas!$C$7),(S33)*tabelas!$D$6,IF(AND(R33>0,R33>tabelas!$C$7),(S33)*tabelas!$D$7,0))))) -> 25.4405 | V33: =M33-T33 -> 4.4895
B34: 0000175/01 | C34: 30 | D34: Colaborador 34 | E34: 34301 | F34: MAS | G34: CAS | H34: CONJ | I34: TNEE | J34: 44697 | L34: 01/2026 | M34: 29.93 | O34: 0 | P34: 000.000.000-00 | R34: 5556.85 | S34: 29.93 | T34: =IF(R34>=0,IF(AND(R34>tabelas!$C$4,R34<=tabelas!$C$5),(S34)*tabelas!$D$4,IF(AND(R34>=tabelas!$C$5,R34<=tabelas!$C$6),(S34)*tabelas!$D$5,IF(AND(R34>=tabelas!$C$6,R34<=tabelas!$C$7),(S34)*tabelas!$D$6,IF(AND(R34>0,R34>tabelas!$C$7),(S34)*tabelas!$D$7,0))))) -> 25.4405 | V34: =M34-T34 -> 4.4895
B35: 0000175/02 | C35: 31 | D35: Colaborador 35 | E35: 43481 | F35: MAS | G35: SOLT | H35: FILH | I35: TNEE | J35: 44697 | L35: 01/2026 | M35: 29.93 | O35: 0 | P35: 000.000.000-00 | R35: 7645.71 | S35: 29.93 | T35: =IF(R35>=0,IF(AND(R35>tabelas!$C$4,R35<=tabelas!$C$5),(S35)*tabelas!$D$4,IF(AND(R35>=tabelas!$C$5,R35<=tabelas!$C$6),(S35)*tabelas!$D$5,IF(AND(R35>=tabelas!$C$6,R35<=tabelas!$C$7),(S35)*tabelas!$D$6,IF(AND(R35>0,R35>tabelas!$C$7),(S35)*tabelas!$D$7,0))))) -> 23.0461 | V35: =M35-T35 -> 6.8839
B36: 0000183/00 | C36: 32 | D36: Colaborador 36 | E36: 30373 | F36: MAS | G36: CAS | I36: TNQQ | J36: 44697 | L36: 01/2026 | M36: 29.93 | O36: 0 | P36: 000.000.000-00 | R36: 2782.34 | S36: 29.93 | T36: =IF(R36>=0,IF(AND(R36>tabelas!$C$4,R36<=tabelas!$C$5),(S36)*tabelas!$D$4,IF(AND(R36>=tabelas!$C$5,R36<=tabelas!$C$6),(S36)*tabelas!$D$5,IF(AND(R36>=tabelas!$C$6,R36<=tabelas!$C$7),(S36)*tabelas!$D$6,IF(AND(R36>0,R36>tabelas!$C$7),(S36)*tabelas!$D$7,0))))) -> 27.8349 | V36: =M36-T36 -> 2.0951
B37: 0000183/01 | C37: 33 | D37: Colaborador 37 | E37: 40124 | F37: FEM | G37: SOLT | H37: FILH | I37: TNQQ | J37: 44697 | L37: 01/2026 | M37: 29.93 | O37: 0 | P37: 000.000.000-00 | R37: 1741.37 | S37: 29.93 | T37: =IF(R37>=0,IF(AND(R37>tabelas!$C$4,R37<=tabelas!$C$5),(S37)*tabelas!$D$4,IF(AND(R37>=tabelas!$C$5,R37<=tabelas!$C$6),(S37)*tabelas!$D$5,IF(AND(R37>=tabelas!$C$6,R37<=tabelas!$C$7),(S37)*tabelas!$D$6,IF(AND(R37>0,R37>tabelas!$C$7),(S37)*tabelas!$D$7,0))))) -> 27.8349 | V37: =M37-T37 -> 2.0951
B38: 0000183/02 | C38: 34 | D38: Colaborador 38 | E38: 44529 | F38: MAS | G38: SOLT | H38: FILH | I38: TNQQ | J38: 44697 | L38: 01/2026 | M38: 29.93 | O38: 0 | P38: 000.000.000-00 | R38: 6507.02 | S38: 29.93 | T38: =IF(R38>=0,IF(AND(R38>tabelas!$C$4,R38<=tabelas!$C$5),(S38)*tabelas!$D$4,IF(AND(R38>=tabelas!$C$5,R38<=tabelas!$C$6),(S38)*tabelas!$D$5,IF(AND(R38>=tabelas!$C$6,R38<=tabelas!$C$7),(S38)*tabelas!$D$6,IF(AND(R38>0,R38>tabelas!$C$7),(S38)*tabelas!$D$7,0))))) -> 25.4405 | V38: =M38-T38 -> 4.4895
B39: 0000191/00 | C39: 35 | D39: Colaborador 39 | E39: 34095 | F39: MAS | G39: CAS | I39: TNQQ | J39: 44662 | L39: 01/2026 | M39: 29.93 | O39: 0 | P39: 000.000.000-00 | R39: 1463.11 | S39: 29.93 | T39: =IF(R39>=0,IF(AND(R39>tabelas!$C$4,R39<=tabelas!$C$5),(S39)*tabelas!$D$4,IF(AND(R39>=tabelas!$C$5,R39<=tabelas!$C$6),(S39)*tabelas!$D$5,IF(AND(R39>=tabelas!$C$6,R39<=tabelas!$C$7),(S39)*tabelas!$D$6,IF(AND(R39>0,R39>tabelas!$C$7),(S39)*tabelas!$D$7,0))))) -> 27.8349 | V39: =M39-T39 -> 2.0951
B40: 0000205/00 | C40: 36 | D40: Colaborador 40 | E40: 34435 | F40: FEM | G40: CAS | H40: CONJ | I40: TNQQ | J40: 44662 | L40: 01/2026 | M40: 29.93 | O40: 0 | P40: 000.000.000-00 | R40: 6190.63 | S40: 29.93 | T40: =IF(R40>=0,IF(AND(R40>tabelas!$C$4,R40<=tabelas!$C$5),(S40)*tabelas!$D$4,IF(AND(R40>=tabelas!$C$5,R40<=tabelas!$C$6),(S40)*tabelas!$D$5,IF(AND(R40>=tabelas!$C$6,R40<=tabelas!$C$7),(S40)*tabelas!$D$6,IF(AND(R40>0,R40>tabelas!$C$7),(S40)*tabelas!$D$7,0))))) -> 25.4405 | V40: =M40-T40 -> 4.4895
B41: 0000213/00 | C41: 37 | D41: Colaborador 41 | E41: 33532 | F41: MAS | G41: SOLT | I41: TNQQ | J41: 44704 | L41: 01/2026 | M41: 29.93 | O41: 0 | P41: 000.000.000-00 | R41: 3295.14 | S41: 29.93 | T41: =IF(R41>=0,IF(AND(R41>tabelas!$C$4,R41<=tabelas!$C$5),(S41)*tabelas!$D$4,IF(AND(R41>=tabelas!$C$5,R41<=tabelas!$C$6),(S41)*tabelas!$D$5,IF(AND(R41>=tabelas!$C$6,R41<=tabelas!$C$7),(S41)*tabelas!$D$6,IF(AND(R41>0,R41>tabelas!$C$7),(S41)*tabelas!$D$7,0))))) -> 27.8349 | V41: =M41-T41 -> 2.0951
B42: 0000230/00 | C42: 38 | D42: Colaborador 42 | E42: 33361 | F42: FEM | G42: CAS | I42: FCQX | J42: 44655 | L42: 01/2026 | M42: 29.93 | O42: 0 | P42: 000.000.000-00 | R42: 6890.29 | S42: 29.93 | T42: =IF(R42>=0,IF(AND(R42>tabelas!$C$4,R42<=tabelas!$C$5),(S42)*tabelas!$D$4,IF(AND(R42>=tabelas!$C$5,R42<=tabelas!$C$6),(S42)*tabelas!$D$5,IF(AND(R42>=tabelas!$C$6,R42<=tabelas!$C$7),(S42)*tabelas!$D$6,IF(AND(R42>0,R42>tabelas!$C$7),(S42)*tabelas!$D$7,0))))) -> 25.4405 | V42: =M42-T42 -> 4.4895
...

Sheet Planilha2
B3: Código | C3: Faixa Etária | E3: Valor individual | F3: Bradesco FLEX
A4: Flex | B4: FCEX | C4: 0 | D4: 18 | E4: 332.85 | F4: Enfermaria sem coparticipação | I4: FCEX | J4: Flex | K4: enfermaria
B5: FCEX | C5: =D4+1 -> 19 | D5: 23 | E5: 392.75 | F5: Enfermaria sem coparticipação | I5: FCQX | J5: Flex | K5: apartamento
B6: FCEX | C6: =D5+1 -> 24 | D6: 28 | E6: 475.24 | F6: Enfermaria sem coparticipação | I6: TNEE | J6: Nacional | K6: enfermaria
B7: FCEX | C7: =D6+1 -> 29 | D7: 33 | E7: 570.29 | F7: Enfermaria sem coparticipação | I7: TNQQ | J7: Nacional | K7: apartamento
B8: FCEX | C8: =D7+1 -> 34 | D8: 38 | E8: 650.14 | F8: Enfermaria sem coparticipação
B9: FCEX | C9: =D8+1 -> 39 | D9: 43 | E9: 669.63 | F9: Enfermaria sem coparticipação | I9: FCEX | J9: FCEX
B10: FCEX | C10: =D9+1 -> 44 | D10: 48 | E10: 815.32 | F10: Enfermaria sem coparticipação | I10: FCQX | J10: FCEX
B11: FCEX | C11: =D10+1 -> 49 | D11: 53 | E11: 958.98 | F11: Enfermaria sem coparticipação | I11: TNEE | J11: TNEE
B12: FCEX | C12: =D11+1 -> 54 | D12: 58 | E12: 1141.2 | F12: Enfermaria sem coparticipação | I12: TNQQ | J12: TNEE
B13: FCEX | C13: 59 | D13: 100 | E13: 1997.1 | F13: Enfermaria sem coparticipação
A14: Flex | B14: FCQX | C14: 0 | D14: 18 | E14: 369.83 | F14: Apartamento sem coparticipação
B15: FCQX | C15: =D14+1 -> 19 | D15: 23 | E15: 436.4 | F15: Apartamento sem coparticipação
B16: FCQX | C16: =D15+1 -> 24 | D16: 28 | E16: 528.04 | F16: Apartamento sem coparticipação
B17: FCQX | C17: =D16+1 -> 29 | D17: 33 | E17: 633.65 | F17: Apartamento sem coparticipação
B18: FCQX | C18: =D17+1 -> 34 | D18: 38 | E18: 722.37 | F18: Apartamento sem coparticipação
B19: FCQX | C19: =D18+1 -> 39 | D19: 43 | E19: 744.05 | F19: Apartamento sem coparticipação
B20: FCQX | C20: =D19+1 -> 44 | D20: 48 | E20: 905.91 | F20: Apartamento sem coparticipação
B21: FCQX | C21: =D20+1 -> 49 | D21: 53 | E21: 1065.53 | F21: Apartamento sem coparticipação
B22: FCQX | C22: =D21+1 -> 54 | D22: 58 | E22: 1267.99 | F22: Apartamento sem coparticipação
B23: FCQX | C23: 59 | D23: 100 | E23: 1739.11 | F23: Apartamento sem coparticipação
A24: Nacional | B24: TNEE | C24: 0 | D24: 18 | E24: 339.64 | F24: Nac Enfermaria sem coparticipação
B25: TNEE | C25: =D24+1 -> 19 | D25: 23 | E25: 400.78 | F25: Nac Enfermaria sem coparticipação
B26: TNEE | C26: =D25+1 -> 24 | D26: 28 | E26: 484.94 | F26: Nac Enfermaria sem coparticipação
B27: TNEE | C27: =D26+1 -> 29 | D27: 33 | E27: 581.93 | F27: Nac Enfermaria sem coparticipação
B28: TNEE | C28: =D27+1 -> 34 | D28: 38 | E28: 663.41 | F28: Nac Enfermaria sem coparticipação
B29: TNEE | C29: =D28+1 -> 39 | D29: 43 | E29: 683.3 | F29: Nac Enfermaria sem coparticipação
B30: TNEE | C30: =D29+1 -> 44 | D30: 48 | E30: 831.96 | F30: Nac Enfermaria sem coparticipação
B31: TNEE | C31: =D30+1 -> 49 | D31: 53 | E31: 978.55 | F31: Nac Enfermaria sem coparticipação
B32: TNEE | C32: =D31+1 -> 54 | D32: 58 | E32: 1164.48 | F32: Nac Enfermaria sem coparticipação
B33: TNEE | C33: 59 | D33: 100 | E33: 2037.85 | F33: Nac Enfermaria sem coparticipação
A34: Nacional | B34: TNQQ | C34: 0 | D34: 18 | E34: 376.65 | F34: Nac Apartamento sem coparticipação
B35: TNQQ | C35: =D34+1 -> 19 | D35: 23 | E35: 444.44 | F35: Nac Apartamento sem coparticipação
B36: TNQQ | C36: =D35+1 -> 24 | D36: 28 | E36: 537.78 | F36: Nac Apartamento sem coparticipação
B37: TNQQ | C37: =D36+1 -> 29 | D37: 33 | E37: 645.34 | F37: Nac Apartamento sem coparticipação
B38: TNQQ | C38: =D37+1 -> 34 | D38: 38 | E38: 735.69 | F38: Nac Apartamento sem coparticipação
B39: TNQQ | C39: =D38+1 -> 39 | D39: 43 | E39: 757.76 | F39: Nac Apartamento sem coparticipação
B40: TNQQ | C40: =D39+1 -> 44 | D40: 48 | E40: 922.61 | F40: Nac Apartamento sem coparticipação
B41: TNQQ | C41: =D40+1 -> 49 | D41: 53 | E41: 1085.18 | F41: Nac Apartamento sem coparticipação
B42: TNQQ | C42: =D41+1 -> 54 | D42: 58 | E42: 1291.37 | F42: Nac Apartamento sem coparticipação
...

Sheet tabelas
C2: TABELA DESCONTO
C3: FAIXA SALARIAL | D3: ATLANTICO | E3: COLABORADOR
C4: 0 | D4: 0.93 | E4: 0.07
C5: 3712.1375 | D5: 0.85 | E5: 0.15
C6: 7411.3001 | D6: 0.77 | E6: 0.23
C7: 15265.628 | D7: 0.69 | E7: 0.31
