Workbook

Sheet Sheet
A1: Recebimento
A3: Unimed Fatura | B3: Unimed Desc | C3: Unimed Custo | D3: Uniodonto Fatura | E3: Uniodonto Desc | F3: Uniodonto Custo | G3: Caju Fatura | H3: Caju Desc | J3: Caju Custo | K3: Seguro de Vida Fatura | L3: Seguro de Vida Desc | M3: Seguro de Vida Custo | N3: Sistel Folha | O3: Sistel Emprestimo | P3: Sistel Custo | Q3: Claro | R3: Auxílio creche | S3: Reembolso Funcionários | T3: Vale Transporte Fatura | U3: Vale Transporte Desc | V3: Vale Transporte Custo | W3: Pensão Alimenticia | X3: Gratificação | Y3: Auxílio Pós Graduação | Z3: Auxílio HO | AA3: ASO | AB3: Auxilio Funeral | AC3: Indicação Premiada | AD3: Assistencia Saude Fatura | AE3: Assistencia Saude Desc | AF3: Assistencia Saude Custo | AG3: Auxilio Transporte | AH3: Inglês Tim Fatura | AI3: Inglês Tim Desc | AJ3: Inglês Tim Custo | AK3: Zenklub Fatura | AL3: Zenklub Desc | AM3: Zenklub Custo | AN3: Bradesco Saude Fatura | AO3: Bradesco Saude Desc | AP3: Bradesco Saude Custo | AQ3: Bradesco Dental Fatura | AR3: Bradesco Dental Desc | AS3: Bradesco Dental Custo | AT3: Ascan | AU3: Comissao | AV3: Academy | AW3: Diárias de Viagem | AX3: Caju Extra Fatura | AY3: Caju Extra Desc | AZ3: Caju Extra Custo | BA3: Open English Fatura | BC3: Open English Desc | BD3: Open English Custo | BE3: Gympass | BF3: Caju Intermitentes Fatura | BG3: Caju Intermitentes Desc | BH3: Caju Intermitentes Custo | BI3: Creche - Intermitente | BJ3: Auxílio HO - Intermitente | BK3: AGIEL
BM4: Total Geral
A5: Matrícula | L5: Nome | BB5: Salário | BM5: Unimed Fatura | BN5: Unimed Desc | BO5: Unimed Custo | BP5: Uniodonto Fatura | BQ5: Uniodonto Desc | BR5: Uniodonto Custo | BS5: Caju Fatura | BT5: Caju Desc | BU5: Caju Custo | BV5: Seguro de Vida Fatura | BW5: Seguro de Vida Desc | BX5: Seguro de Vida Custo | BY5: Sistel Folha | BZ5: Sistel Emprestimo | CA5: Sistel Custo | CB5: Claro | CC5: Auxílio creche | CD5: Reembolso Funcionários | CE5: Vale Transporte Fatura | CF5: Vale Transporte Desc | CG5: Vale Transporte Custo | CH5: Pensão Alimenticia | CI5: Gratificação | CJ5: Auxílio Pós Graduação | CK5: Auxílio HO | CL5: ASO | CM5: Auxilio Funeral | CN5: Indicação Premiada | CO5: Assistencia Saude Fatura | CP5: Assistencia Saude Desc | CQ5: Assistencia Saude Custo | CR5: Auxilio Transporte | CS5: Inglês Tim Fatura | CT5: Inglês Tim Desc | CU5: Inglês Tim Custo | CV5: Zenklub Fatura | CW5: Zenklub Desc | CX5: Zenklub Custo | CY5: Bradesco Saude Fatura | CZ5: Bradesco Saude Desc | DA5: Bradesco Saude Custo | DB5: Bradesco Dental Fatura | DC5: Bradesco Dental Desc | DD5: Bradesco Dental Custo | DE5: Ascan | DF5: Comissao | DG5: Academy | DH5: Diárias de Viagem | DI5: Caju Extra Fatura | DJ5: Caju Extra Desc | DK5: Caju Extra Custo | DL5: Open English Fatura | DM5: Open English Desc | DN5: Open English Custo | DO5: Gympass | DP5: Caju Intermitentes Fatura | DQ5: Caju Intermitentes Desc | DR5: Caju Intermitentes Custo | DS5: Creche - Intermitente | DT5: Auxílio HO - Intermitente | DU5: AGIEL

Sheet cubo
A1: Evento
A2: 1 | B2: 3 | C2: 4 | D2: 5 | E2: 6 | F2: 7 | G2: 8 | H2: 9 | I2: 10 | J2: 11 | K2: 12 | L2: 13 | M2: 14 | N2: 15 | O2: 16 | P2: 17 | Q2: 18 | R2: 19 | S2: 20 | T2: 21 | U2: 22 | V2: 23 | W2: 24 | X2: 25 | Y2: 26 | Z2: 27 | AA2: 28 | AB2: 29 | AC2: 30 | AD2: 31 | AE2: 32 | AF2: 33 | AG2: 34 | AH2: 35 | AI2: 36 | AJ2: 37 | AK2: 38 | AL2: 39 | AM2: 40 | AN2: 41 | AO2: 42 | AP2: 43 | AQ2: 44 | AR2: 45 | AS2: 46 | AT2: 47 | AU2: 48 | AV2: 49 | AW2: 50 | AX2: 51 | AY2: 52 | AZ2: 53 | BA2: 54 | BB2: 55 | BC2: 56 | BD2: 57 | BE2: 58 | BF2: 59 | BG2: 60 | BH2: 61 | BI2: 62 | BJ2: 63 | BK2: 64
A3: Unimed Fatura | C3: 4 | D3: 5 | E3: 6 | F3: 7 | G3: 8 | H3: 9 | I3: 10 | J3: 11 | K3: 12 | L3: 13 | M3: 14 | N3: 15 | O3: 16 | P3: 17 | Q3: 18 | R3: 19 | S3: 20 | T3: 21 | U3: 22 | V3: 23 | W3: 24 | X3: 25 | Y3: 26 | Z3: 27 | AA3: 28 | AB3: 29 | AC3: 30 | AD3: 31 | AE3: 32 | AF3: 33 | AG3: 34 | AH3: 35 | AI3: 36 | AJ3: 37 | AK3: 38 | AL3: 39 | AM3: 40 | AN3: 41 | AO3: 42 | AP3: 43 | AQ3: 44 | AR3: 45 | AS3: 46 | AT3: 47 | AU3: 48 | AV3: 49 | AW3: 50 | AX3: 51 | AY3: 52 | AZ3: 53 | BA3: 54 | BB3: 55 | BC3: 56 | BD3: 57 | BE3: 58 | BF3: 59 | BG3: 60 | BH3: 61 | BI3: 62 | BJ3: 63 | BK3: 64
C4: Total Geral
A5: Mat | B5: Nome | C5: Salário | D5: Unimed | G5: Uniodonto | J5: Caju | M5: Seguro de Vida | P5: Sistel | S5: Claro | T5: Auxílio Creche | U5: Reembolso Func | V5: Transporte | Y5: Pensão Alimentícia | Z5: Gratificação | AA5: Auxílio Pós Graduação | AB5: Auxílio HO | AC5: ASO | AD5: Auxílio Funeral | AE5: Indicação Premiada | AF5: Assistência Saúde | AI5: Auxílio Transporte | AJ5: Inglês Tim | AM5: Zenklub | AO5: Zenklub | AP5: Bradesco Saúde | AS5: Bradesco Dental | AV5: Ascan | AW5: Comissão | AX5: Academy | AY5: Diária de Viagem | AZ5: Caju Extra | BC5: Open English | BF5: Gympass | BG5: Agiel | BH5: Caju Intermitentes | BK5: Diferença Sistel | BM5: Auxílio HO - Intermitente | BN5: Creche - Intermitente
D6: Fatura | E6: Desconto | F6: Custo | G6: Fatura | H6: Desconto | I6: Custo | J6: Fatura | K6: Desconto | L6: Custo | M6: Fatura | N6: Desconto | O6: Custo | P6: Folha | Q6: Empresti | R6: Custo | T6: Custo | V6: Fatura | W6: Desconto | X6: Custo | Y6: Desconto | Z6: Custo | AF6: Fatura | AG6: Desconto | AH6: Custo | AJ6: Fatura | AK6: Desconto | AL6: Custo | AM6: Fatura | AN6: Desconto | AO6: Custo | AP6: Fatura | AQ6: Desconto | AR6: Custo | AS6: Fatura | AT6: Desconto | AU6: Custo | AZ6: Fatura | BA6: Desconto | BB6: Custo | BC6: Fatura | BD6: Desconto | BE6: Custo | BF6: Custo | BG6: Custo | BH6: Fatura | BI6: Desconto | BJ6: Custo | BK6: Folha | BL6: Custo
A7: 1 | B7: =VLOOKUP(A7,[1]salario!$A$3:$C$195,3,0) -> Colaborador 1 | C7: 5826.03 | D7: 1647.85 | E7: 170.9072 | F7: 1476.9428 | G7: 84.38 | H7: 12.657 | I7: 71.723 | J7: 500 | K7: 30 | L7: 470 | M7: 18.614166 | N7: 9.3070829 | O7: 9.3070829 | T7: 0 | U7: #REF! | V7: 0 | W7: 0 | X7: 0 | Y7: 0 | Z7: 0 | AA7: 0 | AB7: 275 | AC7: 0 | AD7: 0 | AE7: 0 | AI7: 0 | AJ7: 165 | AK7: 65 | AL7: 100 | AM7: 90.566667 | AN7: 23.9 | AO7: 66.666667 | AP7: 1580.29 | AQ7: 263.9035 | AR7: 1336.2949 | AS7: 29.93 | AT7: 4.4895 | AU7: 25.4405 | AV7: 0 | AW7: 0 | AX7: 0 | AY7: 0 | AZ7: 0 | BA7: 0 | BB7: 0 | BC7: 138.88889 | BD7: 96.56 | BE7: 42.328889 | BF7: 166.66667 | BG7: - | BH7: 0 | BI7: 0 | BJ7: 0 | BK7: 0 | BL7: 0 | BM7: 0 | BN7: 0
A8: 2 | B8: =VLOOKUP(A8,[1]salario!$A$3:$C$195,3,0) -> Colaborador 2 | C8: 4332.22 | D8: 1119.84 | E8: 167.98011 | F8: 951.85989 | G8: 210.95 | H8: 31.6425 | I8: 179.3075 | J8: 500 | K8: 30 | L8: 470 | M8: 13.841443 | N8: 6.9207215 | O8: 6.9207215 | T8: 0 | U8: #REF! | V8: 0 | W8: 0 | X8: 0 | Y8: 0 | Z8: 0 | AA8: 0 | AB8: 275 | AC8: 0 | AD8: 0 | AE8: 0 | AI8: 0 | AJ8: 165 | AK8: 65 | AL8: 100 | AM8: 90.566667 | AN8: 23.9 | AO8: 66.666667 | AP8: 1327.97 | AQ8: 221.78 | AR8: 1126.0984 | AS8: 29.93 | AT8: 4.4895 | AU8: 25.4405 | AV8: 0 | AW8: 0 | AX8: 0 | AY8: 0 | AZ8: 0 | BA8: 0 | BB8: 0 | BC8: 138.88889 | BD8: 96.56 | BE8: 42.328889 | BF8: 166.66667 | BG8: - | BH8: 0 | BI8: 0 | BJ8: 0 | BK8: 0 | BL8: 0 | BM8: 0 | BN8: 0
A9: 3 | B9: =VLOOKUP(A9,[1]salario!$A$3:$C$195,3,0) -> Colaborador 3 | C9: 4714.12 | D9: 559.92 | E9: 83.990054 | F9: 475.92995 | G9: 253.14 | H9: 37.971 | I9: 215.169 | J9: 500 | K9: 30 | L9: 470 | M9: 15.061613 | N9: 7.5308067 | O9: 7.5308067 | T9: 0 | U9: #REF! | V9: 0 | W9: 0 | X9: 0 | Y9: 0 | Z9: 0 | AA9: 0 | AB9: 275 | AC9: 0 | AD9: 0 | AE9: 0 | AI9: 0 | AJ9: 165 | AK9: 65 | AL9: 100 | AM9: 90.566667 | AN9: 23.9 | AO9: 66.666667 | AP9: 460.91 | AQ9: 76.965 | AR9: 403.85345 | AS9: 29.93 | AT9: 4.4895 | AU9: 25.4405 | AV9: 0 | AW9: 0 | AX9: 0 | AY9: 0 | AZ9: 0 | BA9: 0 | BB9: 0 | BC9: 138.88889 | BD9: 96.56 | BE9: 42.328889 | BF9: 166.66667 | BG9: - | BH9: 0 | BI9: 0 | BJ9: 0 | BK9: 0 | BL9: 0 | BM9: 0 | BN9: 0
A10: 4 | B10: =VLOOKUP(A10,[1]salario!$A$3:$C$195,3,0) -> Colaborador 4 | C10: 7685.13 | D10: 937.56 | E10: 402.80959 | F10: 534.75041 | G10: 42.19 | H10: 9.7037 | I10: 32.4863 | J10: 500 | K10: 50 | L10: 450 | M10: 24.55399 | N10: 12.276995 | O10: 12.276995 | T10: 0 | U10: #REF! | V10: 0 | W10: 0 | X10: 0 | Y10: 0 | Z10: 0 | AA10: 0 | AB10: 275 | AC10: 0 | AD10: 0 | AE10: 0 | AI10: 0 | AJ10: 165 | AK10: 65 | AL10: 100 | AM10: 90.566667 | AN10: 23.9 | AO10: 66.666667 | AP10: 460.91 | AQ10: 113.101 | AR10: 367.71745 | AS10: 29.93 | AT10: 6.8839 | AU10: 23.0461 | AV10: 0 | AW10: 0 | AX10: 0 | AY10: 0 | AZ10: 0 | BA10: 0 | BB10: 0 | BC10: 138.88889 | BD10: 96.56 | BE10: 42.328889 | BF10: 166.66667 | BG10: - | BH10: 0 | BI10: 0 | BJ10: 0 | BK10: 0 | BL10: 0 | BM10: 0 | BN10: 0
A11: 5 | B11: =VLOOKUP(A11,[1]salario!$A$3:$C$195,3,0) -> Colaborador 5 | C11: 3652.6 | D11: 3624.45 | E11: 925.12147 | F11: 2699.3285 | G11: 253.14 | H11: 17.7198 | I11: 235.4202 | J11: 500 | K11: 10 | L11: 490 | M11: 11.670057 | N11: 5.8350285 | O11: 5.8350285 | T11: 0 | U11: #REF! | V11: 0 | W11: 0 | X11: 0 | Y11: 0 | Z11: 0 | AA11: 0 | AB11: 275 | AC11: 0 | AD11: 0 | AE11: 0 | AI11: 0 | AJ11: 165 | AK11: 65 | AL11: 100 | AM11: 90.566667 | AN11: 23.9 | AO11: 66.666667 | AP11: 875.77 | AQ11: 217.9295 | AR11: 677.74895 | AS11: 29.93 | AT11: 4.4895 | AU11: 25.4405 | AV11: 0 | AW11: 0 | AX11: 0 | AY11: 0 | AZ11: 0 | BA11: 0 | BB11: 0 | BC11: 138.88889 | BD11: 96.56 | BE11: 42.328889 | BF11: 166.66667 | BG11: - | BH11: 0 | BI11: 0 | BJ11: 0 | BK11: 0 | BL11: 0 | BM11: 0 | BN11: 0
A12: 6 | B12: =VLOOKUP(A12,[1]salario!$A$3:$C$195,3,0) -> Colaborador 6 | C12: 7943.86 | D12: 3221.65 | E12: 475.84543 | F12: 2745.8046 | G12: 168.76 | H12: 38.8148 | I12: 129.9452 | J12: 500 | K12: 50 | L12: 450 | M12: 25.380633 | N12: 12.690316 | O12: 12.690316 | T12: 0 | U12: #REF! | V12: 0 | W12: 0 | X12: 0 | Y12: 0 | Z12: 0 | AA12: 0 | AB12: 275 | AC12: 0 | AD12: 0 | AE12: 0 | AI12: 0 | AJ12: 165 | AK12: 65 | AL12: 100 | AM12: 90.566667 | AN12: 23.9 | AO12: 66.666667 | AP12: 875.77 | AQ12: 217.9295 | AR12: 677.74895 | AS12: 29.93 | AT12: 4.4895 | AU12: 25.4405 | AV12: 0 | AW12: 0 | AX12: 0 | AY12: 0 | AZ12: 0 | BA12: 0 | BB12: 0 | BC12: 138.88889 | BD12: 96.56 | BE12: 42.328889 | BF12: 166.66667 | BG12: - | BH12: 0 | BI12: 0 | BJ12: 0 | BK12: 0 | BL12: 0 | BM12: 0 | BN12: 0
A13: 7 | B13: =VLOOKUP(A13,[1]salario!$A$3:$C$195,3,0) -> Colaborador 7 | C13: 7131.14 | D13: 1119.84 | E13: 167.98011 | F13: 951.85989 | G13: 168.76 | H13: 25.314 | I13: 143.446 | J13: 500 | K13: 30 | L13: 470 | M13: 22.783992 | N13: 11.391996 | O13: 11.391996 | T13: 0 | U13: #REF! | V13: 0 | W13: 0 | X13: 0 | Y13: 0 | Z13: 0 | AA13: 0 | AB13: 275 | AC13: 0 | AD13: 0 | AE13: 0 | AI13: 0 | AJ13: 165 | AK13: 65 | AL13: 100 | AM13: 90.566667 | AN13: 23.9 | AO13: 66.666667 | AP13: 511.15 | AQ13: 127.205 | AR13: 403.85345 | AS13: 29.93 | AT13: 4.4895 | AU13: 25.4405 | AV13: 0 | AW13: 0 | AX13: 0 | AY13: 0 | AZ13: 0 | BA13: 0 | BB13: 0 | BC13: 138.88889 | BD13: 96.56 | BE13: 42.328889 | BF13: 166.66667 | BG13: - | BH13: 0 | BI13: 0 | BJ13: 0 | BK13: 0 | BL13: 0 | BM13: 0 | BN13: 0
A14: 8 | B14: =VLOOKUP(A14,[1]salario!$A$3:$C$195,3,0) -> Colaborador 8 | C14: 5245.5 | D14: 694.48 | E14: 104.1711 | F14: 590.3089 | G14: 168.76 | H14: 25.314 | I14: 143.446 | J14: 500 | K14: 30 | L14: 470 | M14: 16.759373 | N14: 8.3796863 | O14: 8.3796863 | T14: 0 | U14: #REF! | V14: 0 | W14: 0 | X14: 0 | Y14: 0 | Z14: 0 | AA14: 0 | AB14: 275 | AC14: 0 | AD14: 0 | AE14: 0 | AI14: 0 | AJ14: 165 | AK14: 65 | AL14: 100 | AM14: 90.566667 | AN14: 23.9 | AO14: 66.666667 | AP14: 511.15 | AQ14: 163.341 | AR14: 367.71745 | AS14: 29.93 | AT14: 6.8839 | AU14: 23.0461 | AV14: 0 | AW14: 0 | AX14: 0 | AY14: 0 | AZ14: 0 | BA14: 0 | BB14: 0 | BC14: 138.88889 | BD14: 96.56 | BE14: 42.328889 | BF14: 166.66667 | BG14: - | BH14: 0 | BI14: 0 | BJ14: 0 | BK14: 0 | BL14: 0 | BM14: 0 | BN14: 0
A15: 9 | B15: =VLOOKUP(A15,[1]salario!$A$3:$C$195,3,0) -> Colaborador 9 | C15: 4229.32 | D15: 1450.36 | E15: 384.12116 | F15: 1066.2388 | G15: 126.57 | H15: 18.9855 | I15: 107.5845 | J15: 500 | K15: 30 | L15: 470 | M15: 13.512677 | N15: 6.7563387 | O15: 6.7563387 | T15: 0 | U15: #REF! | V15: 0 | W15: 0 | X15: 0 | Y15: 0 | Z15: 0 | AA15: 0 | AB15: 275 | AC15: 0 | AD15: 0 | AE15: 0 | AI15: 0 | AJ15: - | AK15: 0 | AL15: - | AM15: 90.566667 | AN15: 23.9 | AO15: 66.666667 | AP15: 511.15 | AQ15: 127.205 | AR15: 403.85345 | AS15: 29.93 | AT15: 4.4895 | AU15: 25.4405 | AV15: 0 | AW15: 0 | AX15: 0 | AY15: 0 | AZ15: 0 | BA15: 0 | BB15: 0 | BC15: 138.88889 | BD15: 96.56 | BE15: 42.328889 | BF15: 166.66667 | BG15: - | BH15: 0 | BI15: 0 | BJ15: 0 | BK15: 0 | BL15: 0 | BM15: 0 | BN15: 0
A16: 10 | B16: =VLOOKUP(A16,[1]salario!$A$3:$C$195,3,0) -> Colaborador 10 | C16: 2404.84 | D16: 1557.86 | E16: 80.917201 | F16: 1476.9428 | G16: 126.57 | H16: 8.8599 | I16: 117.7101 | J16: 500 | K16: 10 | L16: 490 | M16: 7.6834638 | N16: 3.8417319 | O16: 3.8417319 | T16: 0 | U16: #REF! | V16: 0 | W16: 0 | X16: 0 | Y16: 0 | Z16: 0 | AA16: 0 | AB16: 275 | AC16: 0 | AD16: 0 | AE16: 0 | AI16: 0 | AJ16: - | AK16: 0 | AL16: - | AM16: 90.566667 | AN16: 23.9 | AO16: 66.666667 | AP16: 900.29 | AQ16: 79.7696 | AR16: 840.42885 | AS16: 29.93 | AT16: 2.0951 | AU16: 27.8349 | AV16: 0 | AW16: 0 | AX16: 0 | AY16: 0 | AZ16: 0 | BA16: 0 | BB16: 0 | BC16: 138.88889 | BD16: 96.56 | BE16: 42.328889 | BF16: 166.66667 | BG16: - | BH16: 0 | BI16: 0 | BJ16: 0 | BK16: 0 | BL16: 0 | BM16: 0 | BN16: 0
A17: 11 | B17: =VLOOKUP(A17,[1]salario!$A$3:$C$195,3,0) -> Colaborador 11 | C17: 2335.03 | D17: 1087.93 | E17: 107.62825 | F17: 980.30175 | G17: 126.57 | H17: 8.8599 | I17: 117.7101 | J17: 500 | K17: 10 | L17: 490 | M17: 7.4604209 | N17: 3.7302104 | O17: 3.7302104 | T17: 0 | U17: #REF! | V17: 0 | W17: 0 | X17: 0 | Y17: 0 | Z17: 0 | AA17: 0 | AB17: 275 | AC17: 0 | AD17: 0 | AE17: 0 | AI17: 0 | AJ17: - | AK17: 0 | AL17: - | AM17: 90.566667 | AN17: 23.9 | AO17: 66.666667 | AP17: 900.29 | AQ17: 220.9344 | AR17: 699.26405 | AS17: 29.93 | AT17: 6.8839 | AU17: 23.0461 | AV17: 0 | AW17: 0 | AX17: 0 | AY17: 0 | AZ17: 0 | BA17: 0 | BB17: 0 | BC17: 138.88889 | BD17: 96.56 | BE17: 42.328889 | BF17: 166.66667 | BG17: - | BH17: 0 | BI17: 0 | BJ17: 0 | BK17: 0 | BL17: 0 | BM17: 0 | BN17: 0
A18: 12 | B18: =VLOOKUP(A18,[1]salario!$A$3:$C$195,3,0) -> Colaborador 12 | C18: 3290.79 | D18: 3032.94 | E18: 306.72186 | F18: 2726.2181 | G18: 42.19 | H18: 2.9533 | I18: 39.2367 | J18: 500 | K18: 10 | L18: 490 | M18: 10.514074 | N18: 5.257037 | O18: 5.257037 | T18: 0 | U18: #REF! | V18: 0 | W18: 0 | X18: 0 | Y18: 0 | Z18: 0 | AA18: 0 | AB18: 275 | AC18: 0 | AD18: 0 | AE18: 0 | AI18: 0 | AJ18: - | AK18: 0 | AL18: - | AM18: 90.566667 | AN18: 23.9 | AO18: 66.666667 | AP18: 729.81 | AQ18: 181.611 | AR18: 568.10745 | AS18: 29.93 | AT18: 4.4895 | AU18: 25.4405 | AV18: 0 | AW18: 0 | AX18: 0 | AY18: 0 | AZ18: 0 | BA18: 0 | BB18: 0 | BC18: 138.88889 | BD18: 96.56 | BE18: 42.328889 | BF18: 166.66667 | BG18: - | BH18: 0 | BI18: 0 | BJ18: 0 | BK18: 0 | BL18: 0 | BM18: 0 | BN18: 0
A19: 13 | B19: =VLOOKUP(A19,[1]salario!$A$3:$C$195,3,0) -> Colaborador 13 | C19: 1102.16 | D19: 694.48 | E19: 48.612616 | F19: 645.86738 | G19: 210.95 | H19: 14.7665 | I19: 196.1835 | J19: 500 | K19: 10 | L19: 490 | M19: 3.5214012 | N19: 1.7607006 | O19: 1.7607006 | T19: 0 | U19: #REF! | V19: 0 | W19: 0 | X19: 0 | Y19: 0 | Z19: 0 | AA19: 0 | AB19: 275 | AC19: 0 | AD19: 0 | AE19: 0 | AI19: 0 | AJ19: 165 | AK19: 65 | AL19: 100 | AM19: 90.566667 | AN19: 23.9 | AO19: 66.666667 | AP19: 729.81 | AQ19: 130.0158 | AR19: 619.70265 | AS19: 29.93 | AT19: 2.0951 | AU19: 27.8349 | AV19: 0 | AW19: 0 | AX19: 0 | AY19: 0 | AZ19: 0 | BA19: 0 | BB19: 0 | BC19: 138.88889 | BD19: 96.56 | BE19: 42.328889 | BF19: 166.66667 | BG19: - | BH19: 0 | BI19: 0 | BJ19: 0 | BK19: 0 | BL19: 0 | BM19: 0 | BN19: 0
A20: 14 | B20: =VLOOKUP(A20,[1]salario!$A$3:$C$195,3,0) -> Colaborador 14 | C20: 5617.18 | D20: 2578.5 | E20: 955.06043 | F20: 1623.4396 | G20: 210.95 | H20: 31.6425 | I20: 179.3075 | J20: 550 | K20: 33 | L20: 517 | M20: 17.94689 | N20: 8.9734451 | O20: 8.9734451 | T20: 0 | U20: #REF! | V20: 0 | W20: 0 | X20: 0 | Y20: 0 | Z20: 0 | AA20: 0 | AB20: 275 | AC20: 0 | AD20: 0 | AE20: 0 | AI20: 0 | AJ20: 165 | AK20: 65 | AL20: 100 | AM20: 90.566667 | AN20: 23.9 | AO20: 66.666667 | AP20: 927.29 | AQ20: 154.861 | AR20: 792.33745 | AS20: 29.93 | AT20: 4.4895 | AU20: 25.4405 | AV20: 0 | AW20: 0 | AX20: 0 | AY20: 0 | AZ20: 0 | BA20: 0 | BB20: 0 | BC20: 138.88889 | BD20: 96.56 | BE20: 42.328889 | BF20: 166.66667 | BG20: - | BH20: 0 | BI20: 0 | BJ20: 0 | BK20: 0 | BL20: 0 | BM20: 0 | BN20: 0
A21: 15 | B21: =VLOOKUP(A21,[1]salario!$A$3:$C$195,3,0) -> Colaborador 15 | C21: 5591.86 | D21: 1511.76 | E21: 559.90011 | F21: 951.85989 | G21: 42.19 | H21: 6.3285 | I21: 35.8615 | J21: 500 | K21: 30 | L21: 470 | M21: 17.865993 | N21: 8.9329963 | O21: 8.9329963 | T21: 0 | U21: #REF! | V21: 0 | W21: 0 | X21: 0 | Y21: 0 | Z21: 0 | AA21: 0 | AB21: 275 | AC21: 0 | AD21: 0 | AE21: 0 | AI21: 0 | AJ21: 165 | AK21: 65 | AL21: 100 | AM21: 90.566667 | AN21: 23.9 | AO21: 66.666667 | AP21: 460.91 | AQ21: 40.829 | AR21: 439.98945 | AS21: 29.93 | AT21: 2.0951 | AU21: 27.8349 | AV21: 0 | AW21: 0 | AX21: 0 | AY21: 0 | AZ21: 0 | BA21: 0 | BB21: 0 | BC21: 138.88889 | BD21: 96.56 | BE21: 42.328889 | BF21: 166.66667 | BG21: - | BH21: 0 | BI21: 0 | BJ21: 0 | BK21: 0 | BL21: 0 | BM21: 0 | BN21: 0
A22: 16 | B22: =VLOOKUP(A22,[1]salario!$A$3:$C$195,3,0) -> Colaborador 16 | C22: 7685.13 | D22: 0 | E22: 0 | F22: 0 | G22: 210.95 | H22: 48.5185 | I22: 162.4315 | J22: 500 | K22: 50 | L22: 450 | M22: 24.55399 | N22: 12.276995 | O22: 12.276995 | T22: 0 | U22: #REF! | V22: 0 | W22: 0 | X22: 0 | Y22: 0 | Z22: 0 | AA22: 0 | AB22: 275 | AC22: 0 | AD22: 0 | AE22: 0 | AI22: 0 | AJ22: 165 | AK22: 65 | AL22: 100 | AM22: 90.566667 | AN22: 23.9 | AO22: 66.666667 | AP22: 460.91 | AQ22: 76.965 | AR22: 403.85345 | AS22: 29.93 | AT22: 4.4895 | AU22: 25.4405 | AV22: 0 | AW22: 0 | AX22: 0 | AY22: 0 | AZ22: 0 | BA22: 0 | BB22: 0 | BC22: 138.88889 | BD22: 96.56 | BE22: 42.328889 | BF22: 166.66667 | BG22: - | BH22: 0 | BI22: 0 | BJ22: 0 | BK22: 0 | BL22: 0 | BM22: 0 | BN22: 0
A23: 17 | B23: =VLOOKUP(A23,[1]salario!$A$3:$C$195,3,0) -> Colaborador 17 | C23: 3652.6 | D23: 0 | E23: 0 | F23: 0 | G23: 126.57 | H23: 8.8599 | I23: 117.7101 | J23: 500 | K23: 10 | L23: 490 | M23: 11.670057 | N23: 5.8350285 | O23: 5.8350285 | T23: 0 | U23: #REF! | V23: 0 | W23: 0 | X23: 0 | Y23: 0 | Z23: 0 | AA23: 0 | AB23: 275 | AC23: 0 | AD23: 0 | AE23: 0 | AI23: 0 | AJ23: 165 | AK23: 65 | AL23: 100 | AM23: 90.566667 | AN23: 23.9 | AO23: 66.666667 | AP23: 460.91 | AQ23: 113.101 | AR23: 367.71745 | AS23: 29.93 | AT23: 6.8839 | AU23: 23.0461 | AV23: 0 | AW23: 0 | AX23: 0 | AY23: 0 | AZ23: 0 | BA23: 0 | BB23: 0 | BC23: 138.88889 | BD23: 96.56 | BE23: 42.328889 | BF23: 166.66667 | BG23: - | BH23: 0 | BI23: 0 | BJ23: 0 | BK23: 0 | BL23: 0 | BM23: 0 | BN23: 0
A24: 18 | B24: =VLOOKUP(A24,[1]salario!$A$3:$C$195,3,0) -> Colaborador 18 | C24: 7943.86 | D24: 0 | E24: 0 | F24: 0 | G24: 168.76 | H24: 38.8148 | I24: 129.9452 | J24: 500 | K24: 50 | L24: 450 | M24: 25.380633 | N24: 12.690316 | O24: 12.690316 | T24: 0 | U24: #REF! | V24: 0 | W24: 0 | X24: 0 | Y24: 0 | Z24: 0 | AA24: 0 | AB24: 275 | AC24: 0 | AD24: 0 | AE24: 0 | AI24: 0 | AJ24: 165 | AK24: 65 | AL24: 100 | AM24: 90.566667 | AN24: 23.9 | AO24: 66.666667 | AP24: 998.38 | AQ24: 248.442 | AR24: 769.84645 | AS24: 29.93 | AT24: 4.4895 | AU24: 25.4405 | AV24: 0 | AW24: 0 | AX24: 0 | AY24: 0 | AZ24: 0 | BA24: 0 | BB24: 0 | BC24: 138.88889 | BD24: 96.56 | BE24: 42.328889 | BF24: 166.66667 | BG24: - | BH24: 0 | BI24: 0 | BJ24: 0 | BK24: 0 | BL24: 0 | BM24: 0 | BN24: 0
A25: 19 | B25: =VLOOKUP(A25,[1]salario!$A$3:$C$195,3,0) -> Colaborador 19 | C25: 7131.14 | D25: 0 | E25: 0 | F25: 0 | G25: 84.38 | H25: 12.657 | I25: 71.723 | J25: 500 | K25: 30 | L25: 470 | M25: 22.783992 | N25: 11.391996 | O25: 11.391996 | T25: 0 | U25: #REF! | V25: 0 | W25: 0 | X25: 0 | Y25: 0 | Z25: 0 | AA25: 0 | AB25: 275 | AC25: 0 | AD25: 0 | AE25: 0 | AI25: 0 | AJ25: 165 | AK25: 65 | AL25: 100 | AM25: 90.566667 | AN25: 23.9 | AO25: 66.666667 | AP25: 875.77 | AQ25: 217.9295 | AR25: 677.74895 | AS25: 29.93 | AT25: 4.4895 | AU25: 25.4405 | AV25: 0 | AW25: 0 | AX25: 0 | AY25: 0 | AZ25: 0 | BA25: 0 | BB25: 0 | BC25: 138.88889 | BD25: 96.56 | BE25: 42.328889 | BF25: 166.66667 | BG25: - | BH25: 0 | BI25: 0 | BJ25: 0 | BK25: 0 | BL25: 0 | BM25: 0 | BN25: 0
A26: 20 | B26: =VLOOKUP(A26,[1]salario!$A$3:$C$195,3,0) -> Colaborador 20 | C26: 5245.5 | D26: 0 | E26: 0 | F26: 0 | G26: 168.76 | H26: 25.314 | I26: 143.446 | J26: 500 | K26: 30 | L26: 470 | M26: 16.759373 | N26: 8.3796863 | O26: 8.3796863 | T26: 0 | U26: #REF! | V26: 0 | W26: 0 | X26: 0 | Y26: 0 | Z26: 0 | AA26: 0 | AB26: 275 | AC26: 0 | AD26: 0 | AE26: 0 | AI26: 0 | AJ26: 165 | AK26: 65 | AL26: 100 | AM26: 90.566667 | AN26: 23.9 | AO26: 66.666667 | AP26: 900.29 | AQ26: 150.352 | AR26: 769.84645 | AS26: 29.93 | AT26: 4.4895 | AU26: 25.4405 | AV26: 0 | AW26: 0 | AX26: 0 | AY26: 0 | AZ26: 0 | BA26: 0 | BB26: 0 | BC26: 138.88889 | BD26: 96.56 | BE26: 42.328889 | BF26: 166.66667 | BG26: - | BH26: 0 | BI26: 0 | BJ26: 0 | BK26: 0 | BL26: 0 | BM26: 0 | BN26: 0
A27: 21 | B27: =VLOOKUP(A27,[1]salario!$A$3:$C$195,3,0) -> Colaborador 21 | C27: 4229.32 | D27: 0 | E27: 0 | F27: 0 | G27: 210.95 | H27: 31.6425 | I27: 179.3075 | J27: 500 | K27: 30 | L27: 470 | M27: 13.512677 | N27: 6.7563387 | O27: 6.7563387 | T27: 0 | U27: #REF! | V27: 0 | W27: 0 | X27: 0 | Y27: 0 | Z27: 0 | AA27: 0 | AB27: 275 | AC27: 0 | AD27: 0 | AE27: 0 | AI27: 0 | AJ27: - | AK27: 0 | AL27: - | AM27: 90.566667 | AN27: 23.9 | AO27: 66.666667 | AP27: 927.29 | AQ27: 82.1618 | AR27: 865.03665 | AS27: 29.93 | AT27: 2.0951 | AU27: 27.8349 | AV27: 0 | AW27: 0 | AX27: 0 | AY27: 0 | AZ27: 0 | BA27: 0 | BB27: 0 | BC27: 138.88889 | BD27: 96.56 | BE27: 42.328889 | BF27: 166.66667 | BG27: - | BH27: 0 | BI27: 0 | BJ27: 0 | BK27: 0 | BL27: 0 | BM27: 0 | BN27: 0
A28: 22 | B28: =VLOOKUP(A28,[1]salario!$A$3:$C$195,3,0) -> Colaborador 22 | C28: 2404.84 | D28: 0 | E28: 0 | F28: 0 | G28: 168.76 | H28: 11.8132 | I28: 156.9468 | J28: 500 | K28: 10 | L28: 490 | M28: 7.6834638 | N28: 3.8417319 | O28: 3.8417319 | T28: 0 | U28: #REF! | V28: 0 | W28: 0 | X28: 0 | Y28: 0 | Z28: 0 | AA28: 0 | AB28: 275 | AC28: 0 | AD28: 0 | AE28: 0 | AI28: 0 | AJ28: - | AK28: 0 | AL28: - | AM28: 90.566667 | AN28: 23.9 | AO28: 66.666667 | AP28: 927.29 | AQ28: 154.861 | AR28: 792.33745 | AS28: 29.93 | AT28: 4.4895 | AU28: 25.4405 | AV28: 0 | AW28: 0 | AX28: 0 | AY28: 0 | AZ28: 0 | BA28: 0 | BB28: 0 | BC28: 138.88889 | BD28: 96.56 | BE28: 42.328889 | BF28: 166.66667 | BG28: - | BH28: 0 | BI28: 0 | BJ28: 0 | BK28: 0 | BL28: 0 | BM28: 0 | BN28: 0
A29: 23 | B29: =VLOOKUP(A29,[1]salario!$A$3:$C$195,3,0) -> Colaborador 23 | C29: 2335.03 | D29: 0 | E29: 0 | F29: 0 | G29: 126.57 | H29: 8.8599 | I29: 117.7101 | J29: 550 | K29: 11 | L29: 539 | M29: 7.4604209 | N29: 3.7302104 | O29: 3.7302104 | T29: 0 | U29: #REF! | V29: 0 | W29: 0 | X29: 0 | Y29: 0 | Z29: 0 | AA29: 0 | AB29: 275 | AC29: 0 | AD29: 0 | AE29: 0 | AI29: 0 | AJ29: - | AK29: 0 | AL29: - | AM29: 90.566667 | AN29: 23.9 | AO29: 66.666667 | AP29: 460.91 | AQ29: 40.829 | AR29: 439.98945 | AS29: 29.93 | AT29: 2.0951 | AU29: 27.8349 | AV29: 0 | AW29: 0 | AX29: 0 | AY29: 0 | AZ29: 0 | BA29: 0 | BB29: 0 | BC29: 138.88889 | BD29: 96.56 | BE29: 42.328889 | BF29: 166.66667 | BG29: - | BH29: 0 | BI29: 0 | BJ29: 0 | BK29: 0 | BL29: 0 | BM29: 0 | BN29: 0
A30: 24 | B30: =VLOOKUP(A30,[1]salario!$A$3:$C$195,3,0) -> Colaborador 24 | C30: 3290.79 | D30: 0 | E30: 0 | F30: 0 | G30: 84.38 | H30: 5.9066 | I30: 78.4734 | J30: 500 | K30: 10 | L30: 490 | M30: 10.514074 | N30: 5.257037 | O30: 5.257037 | T30: 0 | U30: #REF! | V30: 0 | W30: 0 | X30: 0 | Y30: 0 | Z30: 0 | AA30: 0 | AB30: 275 | AC30: 0 | AD30: 0 | AE30: 0 | AI30: 0 | AJ30: - | AK30: 0 | AL30: - | AM30: 90.566667 | AN30: 23.9 | AO30: 66.666667 | AP30: 789.72 | AQ30: 69.9651 | AR30: 739.66335 | AS30: 29.93 | AT30: 2.0951 | AU30: 27.8349 | AV30: 0 | AW30: 0 | AX30: 0 | AY30: 0 | AZ30: 0 | BA30: 0 | BB30: 0 | BC30: 138.88889 | BD30: 96.56 | BE30: 42.328889 | BF30: 166.66667 | BG30: - | BH30: 0 | BI30: 0 | BJ30: 0 | BK30: 0 | BL30: 0 | BM30: 0 | BN30: 0
A31: 25 | B31: =VLOOKUP(A31,[1]salario!$A$3:$C$195,3,0) -> Colaborador 25 | C31: 1102.16 | D31: 0 | E31: 0 | F31: 0 | G31: 84.38 | H31: 5.9066 | I31: 78.4734 | J31: 500 | K31: 10 | L31: 490 | M31: 3.5214012 | N31: 1.7607006 | O31: 1.7607006 | T31: 0 | U31: #REF! | V31: 0 | W31: 0 | X31: 0 | Y31: 0 | Z31: 0 | AA31: 0 | AB31: 275 | AC31: 0 | AD31: 0 | AE31: 0 | AI31: 0 | AJ31: - | AK31: 0 | AL31: - | AM31: 90.566667 | AN31: 23.9 | AO31: 66.666667 | AP31: 875.77 | AQ31: 156.0151 | AR31: 739.66335 | AS31: 29.93 | AT31: 2.0951 | AU31: 27.8349 | AV31: 0 | AW31: 0 | AX31: 0 | AY31: 0 | AZ31: 0 | BA31: 0 | BB31: 0 | BC31: 138.88889 | BD31: 96.56 | BE31: 42.328889 | BF31: 166.66667 | BG31: - | BH31: 0 | BI31: 0 | BJ31: 0 | BK31: 0 | BL31: 0 | BM31: 0 | BN31: 0
A32: 26 | B32: =VLOOKUP(A32,[1]salario!$A$3:$C$195,3,0) -> Colaborador 26 | C32: 5617.18 | D32: 0 | E32: 0 | F32: 0 | G32: 84.38 | H32: 12.657 | I32: 71.723 | J32: 500 | K32: 30 | L32: 470 | M32: 17.94689 | N32: 8.9734451 | O32: 8.9734451 | T32: 0 | U32: #REF! | V32: 0 | W32: 0 | X32: 0 | Y32: 0 | Z32: 0 | AA32: 0 | AB32: 275 | AC32: 0 | AD32: 0 | AE32: 0 | AI32: 0 | AJ32: - | AK32: 0 | AL32: - | AM32: 90.566667 | AN32: 23.9 | AO32: 66.666667 | AP32: 900.29 | AQ32: 79.7696 | AR32: 840.42885 | AS32: 29.93 | AT32: 2.0951 | AU32: 27.8349 | AV32: 0 | AW32: 0 | AX32: 0 | AY32: 0 | AZ32: 0 | BA32: 0 | BB32: 0 | BC32: 138.88889 | BD32: 96.56 | BE32: 42.328889 | BF32: 166.66667 | BG32: - | BH32: 0 | BI32: 0 | BJ32: 0 | BK32: 0 | BL32: 0 | BM32: 0 | BN32: 0
A33: 27 | B33: =VLOOKUP(A33,[1]salario!$A$3:$C$195,3,0) -> Colaborador 27 | C33: 5591.86 | D33: 0 | E33: 0 | F33: 0 | G33: 210.95 | H33: 31.6425 | I33: 179.3075 | J33: 500 | K33: 30 | L33: 470 | M33: 17.865993 | N33: 8.9329963 | O33: 8.9329963 | T33: 0 | U33: #REF! | V33: 0 | W33: 0 | X33: 0 | Y33: 0 | Z33: 0 | AA33: 0 | AB33: 275 | AC33: 0 | AD33: 0 | AE33: 0 | AI33: 0 | AJ33: 165 | AK33: 65 | AL33: 100 | AM33: 90.566667 | AN33: 23.9 | AO33: 66.666667 | AP33: 789.72 | AQ33: 69.9651 | AR33: 739.66335 | AS33: 29.93 | AT33: 2.0951 | AU33: 27.8349 | AV33: 0 | AW33: 0 | AX33: 0 | AY33: 0 | AZ33: 0 | BA33: 0 | BB33: 0 | BC33: 138.88889 | BD33: 96.56 | BE33: 42.328889 | BF33: 166.66667 | BG33: - | BH33: 0 | BI33: 0 | BJ33: 0 | BK33: 0 | BL33: 0 | BM33: 0 | BN33: 0
A34: 28 | B34: =VLOOKUP(A34,[1]salario!$A$3:$C$195,3,0) -> Colaborador 28 | C34: 7685.13 | D34: 0 | E34: 0 | F34: 0 | G34: 210.95 | H34: 48.5185 | I34: 162.4315 | J34: 500 | K34: 50 | L34: 450 | M34: 24.55399 | N34: 12.276995 | O34: 12.276995 | T34: 0 | U34: #REF! | V34: 0 | W34: 0 | X34: 0 | Y34: 0 | Z34: 0 | AA34: 0 | AB34: 275 | AC34: 0 | AD34: 0 | AE34: 0 | AI34: 0 | AJ34: 165 | AK34: 65 | AL34: 100 | AM34: 90.566667 | AN34: 23.9 | AO34: 66.666667 | AP34: 980.31 | AQ34: 230.372 | AR34: 769.84645 | AS34: 29.93 | AT34: 4.4895 | AU34: 25.4405 | AV34: 0 | AW34: 0 | AX34: 0 | AY34: 0 | AZ34: 0 | BA34: 0 | BB34: 0 | BC34: 138.88889 | BD34: 96.56 | BE34: 42.328889 | BF34: 166.66667 | BG34: - | BH34: 0 | BI34: 0 | BJ34: 0 | BK34: 0 | BL34: 0 | BM34: 0 | BN34: 0
A35: 29 | B35: =VLOOKUP(A35,[1]salario!$A$3:$C$195,3,0) -> Colaborador 29 | C35: 3652.6 | D35: 0 | E35: 0 | F35: 0 | G35: 126.57 | H35: 8.8599 | I35: 117.7101 | J35: 550 | K35: 11 | L35: 539 | M35: 11.670057 | N35: 5.8350285 | O35: 5.8350285 | T35: 0 | U35: #REF! | V35: 0 | W35: 0 | X35: 0 | Y35: 0 | Z35: 0 | AA35: 0 | AB35: 275 | AC35: 0 | AD35: 0 | AE35: 0 | AI35: 0 | AJ35: 165 | AK35: 65 | AL35: 100 | AM35: 90.566667 | AN35: 23.9 | AO35: 66.666667 | AP35: 927.29 | AQ35: 154.861 | AR35: 792.33745 | AS35: 29.93 | AT35: 4.4895 | AU35: 25.4405 | AV35: 0 | AW35: 0 | AX35: 0 | AY35: 0 | AZ35: 0 | BA35: 0 | BB35: 0 | BC35: 138.88889 | BD35: 96.56 | BE35: 42.328889 | BF35: 166.66667 | BG35: - | BH35: 0 | BI35: 0 | BJ35: 0 | BK35: 0 | BL35: 0 | BM35: 0 | BN35: 0
A36: 30 | B36: =VLOOKUP(A36,[1]salario!$A$3:$C$195,3,0) -> Colaborador 30 | C36: 7943.86 | D36: 0 | E36: 0 | F36: 0 | G36: 210.95 | H36: 48.5185 | I36: 162.4315 | J36: 500 | K36: 50 | L36: 450 | M36: 25.380633 | N36: 12.690316 | O36: 12.690316 | T36: 0 | U36: #REF! | V36: 0 | W36: 0 | X36: 0 | Y36: 0 | Z36: 0 | AA36: 0 | AB36: 275 | AC36: 0 | AD36: 0 | AE36: 0 | AI36: 0 | AJ36: 165 | AK36: 65 | AL36: 100 | AM36: 90.566667 | AN36: 23.9 | AO36: 66.666667 | AP36: 789.72 | AQ36: 131.8795 | AR36: 677.74895 | AS36: 29.93 | AT36: 4.4895 | AU36: 25.4405 | AV36: 0 | AW36: 0 | AX36: 0 | AY36: 0 | AZ36: 0 | BA36: 0 | BB36: 0 | BC36: 138.88889 | BD36: 96.56 | BE36: 42.328889 | BF36: 166.66667 | BG36: - | BH36: 0 | BI36: 0 | BJ36: 0 | BK36: 0 | BL36: 0 | BM36: 0 | BN36: 0
B37: TOTAL | C37: 146612.78 | D37: 24839.42 | E37: 4941.7667 | F37: 19897.653 | G37: 4514.33 | H37: 640.0223 | I37: 3874.3077 | J37: 15150 | K37: 805 | L37: 14345 | M37: 468.42783 | N37: 234.21392 | O37: 234.21392 | P37: 0 | Q37: 0 | R37: 0 | S37: 0 | T37: 0 | U37: #REF! | V37: 0 | W37: 0 | X37: 0 | Y37: 0 | Z37: 0 | AA37: 0 | AB37: 8250 | AC37: 0 | AD37: 0 | AE37: 0 | AF37: 0 | AG37: 0 | AH37: 0 | AI37: 0 | AJ37: 3300 | AK37: 1300 | AL37: 2000 | AM37: 2717 | AN37: 717 | AO37: 2000 | AP37: 23828.04 | AQ37: 4314.849 | AR37: 20110.444 | AS37: 897.9 | AT37: 122.713 | AU37: 775.187 | AV37: 0 | AW37: 0 | AX37: 0 | AY37: 0 | AZ37: 0 | BA37: 0 | BB37: 0 | BC37: 10500 | BD37: 2896.8 | BE37: 7603.2 | BF37: 5000 | BG37: 0 | BH37: 0 | BI37: 0 | BJ37: 0 | BK37: 0 | BL37: 0 | BM37: 0 | BN37: 0

Sheet conciliacao_custos
D1: =SUBTOTAL(9,D4:D645) -> 0 | E1: =SUBTOTAL(9,E4:E645) -> 0 | F1: =SUBTOTAL(9,F4:F645) -> 0 | G1: =SUBTOTAL(9,G4:G645) -> 0 | H1: =SUBTOTAL(9,H4:H645) -> 0 | I1: =SUBTOTAL(9,I4:I645) -> 0 | J1: =SUBTOTAL(9,J4:J645) -> 0 | K1: =SUBTOTAL(9,K4:K645) -> 0 | ... S1: =SUBTOTAL(9,S4:S645) -> 0
B2: 1 | C2: 2 | D2: 3 | E2: 4 | F2: 5 | G2: 6 | H2: 7 | I2: 8 | J2: 9 | K2: 10 | L2: 11 | M2: 12 | N2: 13 | O2: 14 | P2: 15 | Q2: 16 | R2: 17
B3: Mat | C3: Nome | D3: Unimed | E3: Uniodonto | F3: Refeição | G3: Caju Extra | H3: SVG | I3: Sistel | J3: Transporte | K3: Assistencia Saúde | L3: Ingles | M3: Open English | N3: Zenklub | O3: Bradesco Saúde | P3: Bradesco Dental | Q3: Gympass | R3: Agiel | S3: Caju Intermitentes
B4: =[1]salario!A3 -> 1 | C4: =[1]salario!C3 -> Colaborador 1 | D4: =IFERROR(VLOOKUP(B4,cubo!$A$6:$BE$37,6,0)-VLOOKUP(B4,#REF!,$D$2,0),0) -> 0 | E4: =IFERROR(VLOOKUP(B4,cubo!$A$6:$BE$37,9,0)-VLOOKUP(B4,#REF!,$E$2,0),0) -> 0 | F4: =IFERROR(VLOOKUP(B4,cubo!$A$6:$BE$37,12,0)-VLOOKUP(B4,#REF!,$F$2,0),0) -> 0 | G4: =IFERROR(VLOOKUP(B4,cubo!$A$6:$BE$37,54,0)-VLOOKUP(B4,#REF!,$G$2,0),0) -> 0 | H4: =IFERROR(VLOOKUP(B4,cubo!$A$6:$BE$37,15,0)-VLOOKUP(B4,#REF!,$H$2,0),0) -> 0 | I4: =IFERROR(VLOOKUP(B4,cubo!$A$6:$BE$37,18,0)-VLOOKUP(B4,#REF!,$I$2,0),0) -> 0 | J4: =IFERROR(VLOOKUP(B4,cubo!$A$6:$BE$37,24,0)-VLOOKUP(B4,#REF!,$J$2,0),0) -> 0 | K4: =IFERROR(VLOOKUP(B4,cubo!$A$6:$BE$37,34,0)-VLOOKUP(B4,#REF!,$K$2,0),0) -> 0 | L4: =IFERROR(VLOOKUP(B4,cubo!$A$6:$BE$37,38,0)-VLOOKUP(B4,#REF!,$L$2,0),0) -> 0 | M4: =IFERROR(VLOOKUP(B4,cubo!$A$6:$BE$37,57,0)-VLOOKUP(B4,#REF!,$M$2,0),0) -> 0 | N4: =IFERROR(VLOOKUP(B4,cubo!$A$6:$BK$37,41,0)-VLOOKUP(conciliacao_custos!B4,#REF!,18,0),0) -> 0 | O4: =IFERROR(VLOOKUP(B4,cubo!$A$6:$BK$37,44,0)-VLOOKUP(conciliacao_custos!B4,#REF!,13,0),0) -> 0 | P4: =IFERROR(VLOOKUP(B4,cubo!$A$6:$BK$37,47,0)-VLOOKUP(conciliacao_custos!B4,#REF!,14,0),0) -> 0 | Q4: =IFERROR(VLOOKUP(B4,cubo!$A$6:$BK$37,58,0)-VLOOKUP(conciliacao_custos!B4,#REF!,16,0),0) -> 0 | R4: =IFERROR(VLOOKUP(B4,cubo!$A$6:$BK$37,64,0)-VLOOKUP(conciliacao_custos!B4,#REF!,17,0),0) -> 0 | S4: =IFERROR(VLOOKUP(B4,cubo!$A$6:$BK$37,61,0)-VLOOKUP(conciliacao_custos!B4,#REF!,15,0),0) -> 0
B5: =[1]salario!A4 -> 2 | C5: =[1]salario!C4 -> Colaborador 2 | D5: =IFERROR(VLOOKUP(B5,cubo!$A$6:$BE$37,6,0)-VLOOKUP(B5,#REF!,$D$2,0),0) -> 0 | E5: =IFERROR(VLOOKUP(B5,cubo!$A$6:$BE$37,9,0)-VLOOKUP(B5,#REF!,$E$2,0),0) -> 0 | F5: =IFERROR(VLOOKUP(B5,cubo!$A$6:$BE$37,12,0)-VLOOKUP(B5,#REF!,$F$2,0),0) -> 0 | G5: =IFERROR(VLOOKUP(B5,cubo!$A$6:$BE$37,54,0)-VLOOKUP(B5,#REF!,$G$2,0),0) -> 0 | H5: =IFERROR(VLOOKUP(B5,cubo!$A$6:$BE$37,15,0)-VLOOKUP(B5,#REF!,$H$2,0),0) -> 0 | I5: =IFERROR(VLOOKUP(B5,cubo!$A$6:$BE$37,18,0)-VLOOKUP(B5,#REF!,$I$2,0),0) -> 0 | J5: =IFERROR(VLOOKUP(B5,cubo!$A$6:$BE$37,24,0)-VLOOKUP(B5,#REF!,$J$2,0),0) -> 0 | K5: =IFERROR(VLOOKUP(B5,cubo!$A$6:$BE$37,34,0)-VLOOKUP(B5,#REF!,$K$2,0),0) -> 0 | L5: =IFERROR(VLOOKUP(B5,cubo!$A$6:$BE$37,38,0)-VLOOKUP(B5,#REF!,$L$2,0),0) -> 0 | M5: =IFERROR(VLOOKUP(B5,cubo!$A$6:$BE$37,57,0)-VLOOKUP(B5,#REF!,$M$2,0),0) -> 0 | N5: =IFERROR(VLOOKUP(B5,cubo!$A$6:$BK$37,41,0)-VLOOKUP(conciliacao_custos!B5,#REF!,18,0),0) -> 0 | O5: =IFERROR(VLOOKUP(B5,cubo!$A$6:$BK$37,44,0)-VLOOKUP(conciliacao_custos!B5,#REF!,13,0),0) -> 0 | P5: =IFERROR(VLOOKUP(B5,cubo!$A$6:$BK$37,47,0)-VLOOKUP(conciliacao_custos!B5,#REF!,14,0),0) -> 0 | Q5: =IFERROR(VLOOKUP(B5,cubo!$A$6:$BK$37,58,0)-VLOOKUP(conciliacao_custos!B5,#REF!,16,0),0) -> 0 | R5: =IFERROR(VLOOKUP(B5,cubo!$A$6:$BK$37,64,0)-VLOOKUP(conciliacao_custos!B5,#REF!,17,0),0) -> 0 | S5: =IFERROR(VLOOKUP(B5,cubo!$A$6:$BK$37,61,0)-VLOOKUP(conciliacao_custos!B5,#REF!,15,0),0) -> 0
B6: =[1]salario!A5 -> 3 | C6: =[1]salario!C5 -> Colaborador 3 | D6: =IFERROR(VLOOKUP(B6,cubo!$A$6:$BE$37,6,0)-VLOOKUP(B6,#REF!,$D$2,0),0) -> 0 | E6: =IFERROR(VLOOKUP(B6,cubo!$A$6:$BE$37,9,0)-VLOOKUP(B6,#REF!,$E$2,0),0) -> 0 | F6: =IFERROR(VLOOKUP(B6,cubo!$A$6:$BE$37,12,0)-VLOOKUP(B6,#REF!,$F$2,0),0) -> 0 | G6: =IFERROR(VLOOKUP(B6,cubo!$A$6:$BE$37,54,0)-VLOOKUP(B6,#REF!,$G$2,0),0) -> 0 | H6: =IFERROR(VLOOKUP(B6,cubo!$A$6:$BE$37,15,0)-VLOOKUP(B6,#REF!,$H$2,0),0) -> 0 | I6: =IFERROR(VLOOKUP(B6,cubo!$A$6:$BE$37,18,0)-VLOOKUP(B6,#REF!,$I$2,0),0) -> 0 | J6: =IFERROR(VLOOKUP(B6,cubo!$A$6:$BE$37,24,0)-VLOOKUP(B6,#REF!,$J$2,0),0) -> 0 | K6: =IFERROR(VLOOKUP(B6,cubo!$A$6:$BE$37,34,0)-VLOOKUP(B6,#REF!,$K$2,0),0) -> 0 | L6: =IFERROR(VLOOKUP(B6,cubo!$A$6:$BE$37,38,0)-VLOOKUP(B6,#REF!,$L$2,0),0) -> 0 | M6: =IFERROR(VLOOKUP(B6,cubo!$A$6:$BE$37,57,0)-VLOOKUP(B6,#REF!,$M$2,0),0) -> 0 | N6: =IFERROR(VLOOKUP(B6,cubo!$A$6:$BK$37,41,0)-VLOOKUP(conciliacao_custos!B6,#REF!,18,0),0) -> 0 | O6: =IFERROR(VLOOKUP(B6,cubo!$A$6:$BK$37,44,0)-VLOOKUP(conciliacao_custos!B6,#REF!,13,0),0) -> 0 | P6: =IFERROR(VLOOKUP(B6,cubo!$A$6:$BK$37,47,0)-VLOOKUP(conciliacao_custos!B6,#REF!,14,0),0) -> 0 | Q6: =IFERROR(VLOOKUP(B6,cubo!$A$6:$BK$37,58,0)-VLOOKUP(conciliacao_custos!B6,#REF!,16,0),0) -> 0 | R6: =IFERROR(VLOOKUP(B6,cubo!$A$6:$BK$37,64,0)-VLOOKUP(conciliacao_custos!B6,#REF!,17,0),0) -> 0 | S6: =IFERROR(VLOOKUP(B6,cubo!$A$6:$BK$37,61,0)-VLOOKUP(conciliacao_custos!B6,#REF!,15,0),0) -> 0
B7: =[1]salario!A6 -> 4 | C7: =[1]salario!C6 -> Colaborador 4 | D7: =IFERROR(VLOOKUP(B7,cubo!$A$6:$BE$37,6,0)-VLOOKUP(B7,#REF!,$D$2,0),0) -> 0 | E7: =IFERROR(VLOOKUP(B7,cubo!$A$6:$BE$37,9,0)-VLOOKUP(B7,#REF!,$E$2,0),0) -> 0 | F7: =IFERROR(VLOOKUP(B7,cubo!$A$6:$BE$37,12,0)-VLOOKUP(B7,#REF!,$F$2,0),0) -> 0 | G7: =IFERROR(VLOOKUP(B7,cubo!$A$6:$BE$37,54,0)-VLOOKUP(B7,#REF!,$G$2,0),0) -> 0 | H7: =IFERROR(VLOOKUP(B7,cubo!$A$6:$BE$37,15,0)-VLOOKUP(B7,#REF!,$H$2,0),0) -> 0 | I7: =IFERROR(VLOOKUP(B7,cubo!$A$6:$BE$37,18,0)-VLOOKUP(B7,#REF!,$I$2,0),0) -> 0 | J7: =IFERROR(VLOOKUP(B7,cubo!$A$6:$BE$37,24,0)-VLOOKUP(B7,#REF!,$J$2,0),0) -> 0 | K7: =IFERROR(VLOOKUP(B7,cubo!$A$6:$BE$37,34,0)-VLOOKUP(B7,#REF!,$K$2,0),0) -> 0 | L7: =IFERROR(VLOOKUP(B7,cubo!$A$6:$BE$37,38,0)-VLOOKUP(B7,#REF!,$L$2,0),0) -> 0 | M7: =IFERROR(VLOOKUP(B7,cubo!$A$6:$BE$37,57,0)-VLOOKUP(B7,#REF!,$M$2,0),0) -> 0 | N7: =IFERROR(VLOOKUP(B7,cubo!$A$6:$BK$37,41,0)-VLOOKUP(conciliacao_custos!B7,#REF!,18,0),0) -> 0 | O7: =IFERROR(VLOOKUP(B7,cubo!$A$6:$BK$37,44,0)-VLOOKUP(conciliacao_custos!B7,#REF!,13,0),0) -> 0 | P7: =IFERROR(VLOOKUP(B7,cubo!$A$6:$BK$37,47,0)-VLOOKUP(conciliacao_custos!B7,#REF!,14,0),0) -> 0 | Q7: =IFERROR(VLOOKUP(B7,cubo!$A$6:$BK$37,58,0)-VLOOKUP(conciliacao_custos!B7,#REF!,16,0),0) -> 0 | R7: =IFERROR(VLOOKUP(B7,cubo!$A$6:$BK$37,64,0)-VLOOKUP(conciliacao_custos!B7,#REF!,17,0),0) -> 0 | S7: =IFERROR(VLOOKUP(B7,cubo!$A$6:$BK$37,61,0)-VLOOKUP(conciliacao_custos!B7,#REF!,15,0),0) -> 0
B8: =[1]salario!A7 -> 5 | C8: =[1]salario!C7 -> Colaborador 5 | D8: =IFERROR(VLOOKUP(B8,cubo!$A$6:$BE$37,6,0)-VLOOKUP(B8,#REF!,$D$2,0),0) -> 0 | E8: =IFERROR(VLOOKUP(B8,cubo!$A$6:$BE$37,9,0)-VLOOKUP(B8,#REF!,$E$2,0),0) -> 0 | F8: =IFERROR(VLOOKUP(B8,cubo!$A$6:$BE$37,12,0)-VLOOKUP(B8,#REF!,$F$2,0),0) -> 0 | G8: =IFERROR(VLOOKUP(B8,cubo!$A$6:$BE$37,54,0)-VLOOKUP(B8,#REF!,$G$2,0),0) -> 0 | H8: =IFERROR(VLOOKUP(B8,cubo!$A$6:$BE$37,15,0)-VLOOKUP(B8,#REF!,$H$2,0),0) -> 0 | I8: =IFERROR(VLOOKUP(B8,cubo!$A$6:$BE$37,18,0)-VLOOKUP(B8,#REF!,$I$2,0),0) -> 0 | J8: =IFERROR(VLOOKUP(B8,cubo!$A$6:$BE$37,24,0)-VLOOKUP(B8,#REF!,$J$2,0),0) -> 0 | K8: =IFERROR(VLOOKUP(B8,cubo!$A$6:$BE$37,34,0)-VLOOKUP(B8,#REF!,$K$2,0),0) -> 0 | L8: =IFERROR(VLOOKUP(B8,cubo!$A$6:$BE$37,38,0)-VLOOKUP(B8,#REF!,$L$2,0),0) -> 0 | M8: =IFERROR(VLOOKUP(B8,cubo!$A$6:$BE$37,57,0)-VLOOKUP(B8,#REF!,$M$2,0),0) -> 0 | N8: =IFERROR(VLOOKUP(B8,cubo!$A$6:$BK$37,41,0)-VLOOKUP(conciliacao_custos!B8,#REF!,18,0),0) -> 0 | O8: =IFERROR(VLOOKUP(B8,cubo!$A$6:$BK$37,44,0)-VLOOKUP(conciliacao_custos!B8,#REF!,13,0),0) -> 0 | P8: =IFERROR(VLOOKUP(B8,cubo!$A$6:$BK$37,47,0)-VLOOKUP(conciliacao_custos!B8,#REF!,14,0),0) -> 0 | Q8: =IFERROR(VLOOKUP(B8,cubo!$A$6:$BK$37,58,0)-VLOOKUP(conciliacao_custos!B8,#REF!,16,0),0) -> 0 | R8: =IFERROR(VLOOKUP(B8,cubo!$A$6:$BK$37,64,0)-VLOOKUP(conciliacao_custos!B8,#REF!,17,0),0) -> 0 | S8: =IFERROR(VLOOKUP(B8,cubo!$A$6:$BK$37,61,0)-VLOOKUP(conciliacao_custos!B8,#REF!,15,0),0) -> 0
B9: =[1]salario!A8 -> 6 | C9: =[1]salario!C8 -> Colaborador 6 | D9: =IFERROR(VLOOKUP(B9,cubo!$A$6:$BE$37,6,0)-VLOOKUP(B9,#REF!,$D$2,0),0) -> 0 | E9: =IFERROR(VLOOKUP(B9,cubo!$A$6:$BE$37,9,0)-VLOOKUP(B9,#REF!,$E$2,0),0) -> 0 | F9: =IFERROR(VLOOKUP(B9,cubo!$A$6:$BE$37,12,0)-VLOOKUP(B9,#REF!,$F$2,0),0) -> 0 | G9: =IFERROR(VLOOKUP(B9,cubo!$A$6:$BE$37,54,0)-VLOOKUP(B9,#REF!,$G$2,0),0) -> 0 | H9: =IFERROR(VLOOKUP(B9,cubo!$A$6:$BE$37,15,0)-VLOOKUP(B9,#REF!,$H$2,0),0) -> 0 | I9: =IFERROR(VLOOKUP(B9,cubo!$A$6:$BE$37,18,0)-VLOOKUP(B9,#REF!,$I$2,0),0) -> 0 | J9: =IFERROR(VLOOKUP(B9,cubo!$A$6:$BE$37,24,0)-VLOOKUP(B9,#REF!,$J$2,0),0) -> 0 | K9: =IFERROR(VLOOKUP(B9,cubo!$A$6:$BE$37,34,0)-VLOOKUP(B9,#REF!,$K$2,0),0) -> 0 | L9: =IFERROR(VLOOKUP(B9,cubo!$A$6:$BE$37,38,0)-VLOOKUP(B9,#REF!,$L$2,0),0) -> 0 | M9: =IFERROR(VLOOKUP(B9,cubo!$A$6:$BE$37,57,0)-VLOOKUP(B9,#REF!,$M$2,0),0) -> 0 | N9: =IFERROR(VLOOKUP(B9,cubo!$A$6:$BK$37,41,0)-VLOOKUP(conciliacao_custos!B9,#REF!,18,0),0) -> 0 | O9: =IFERROR(VLOOKUP(B9,cubo!$A$6:$BK$37,44,0)-VLOOKUP(conciliacao_custos!B9,#REF!,13,0),0) -> 0 | P9: =IFERROR(VLOOKUP(B9,cubo!$A$6:$BK$37,47,0)-VLOOKUP(conciliacao_custos!B9,#REF!,14,0),0) -> 0 | Q9: =IFERROR(VLOOKUP(B9,cubo!$A$6:$BK$37,58,0)-VLOOKUP(conciliacao_custos!B9,#REF!,16,0),0) -> 0 | R9: =IFERROR(VLOOKUP(B9,cubo!$A$6:$BK$37,64,0)-VLOOKUP(conciliacao_custos!B9,#REF!,17,0),0) -> 0 | S9: =IFERROR(VLOOKUP(B9,cubo!$A$6:$BK$37,61,0)-VLOOKUP(conciliacao_custos!B9,#REF!,15,0),0) -> 0
B10: =[1]salario!A9 -> 7 | C10: =[1]salario!C9 -> Colaborador 7 | D10: =IFERROR(VLOOKUP(B10,cubo!$A$6:$BE$37,6,0)-VLOOKUP(B10,#REF!,$D$2,0),0) -> 0 | E10: =IFERROR(VLOOKUP(B10,cubo!$A$6:$BE$37,9,0)-VLOOKUP(B10,#REF!,$E$2,0),0) -> 0 | F10: =IFERROR(VLOOKUP(B10,cubo!$A$6:$BE$37,12,0)-VLOOKUP(B10,#REF!,$F$2,0),0) -> 0 | G10: =IFERROR(VLOOKUP(B10,cubo!$A$6:$BE$37,54,0)-VLOOKUP(B10,#REF!,$G$2,0),0) -> 0 | H10: =IFERROR(VLOOKUP(B10,cubo!$A$6:$BE$37,15,0)-VLOOKUP(B10,#REF!,$H$2,0),0) -> 0 | I10: =IFERROR(VLOOKUP(B10,cubo!$A$6:$BE$37,18,0)-VLOOKUP(B10,#REF!,$I$2,0),0) -> 0 | J10: =IFERROR(VLOOKUP(B10,cubo!$A$6:$BE$37,24,0)-VLOOKUP(B10,#REF!,$J$2,0),0) -> 0 | K10: =IFERROR(VLOOKUP(B10,cubo!$A$6:$BE$37,34,0)-VLOOKUP(B10,#REF!,$K$2,0),0) -> 0 | L10: =IFERROR(VLOOKUP(B10,cubo!$A$6:$BE$37,38,0)-VLOOKUP(B10,#REF!,$L$2,0),0) -> 0 | M10: =IFERROR(VLOOKUP(B10,cubo!$A$6:$BE$37,57,0)-VLOOKUP(B10,#REF!,$M$2,0),0) -> 0 | N10: =IFERROR(VLOOKUP(B10,cubo!$A$6:$BK$37,41,0)-VLOOKUP(conciliacao_custos!B10,#REF!,18,0),0) -> 0 | O10: =IFERROR(VLOOKUP(B10,cubo!$A$6:$BK$37,44,0)-VLOOKUP(conciliacao_custos!B10,#REF!,13,0),0) -> 0 | P10: =IFERROR(VLOOKUP(B10,cubo!$A$6:$BK$37,47,0)-VLOOKUP(conciliacao_custos!B10,#REF!,14,0),0) -> 0 | Q10: =IFERROR(VLOOKUP(B10,cubo!$A$6:$BK$37,58,0)-VLOOKUP(conciliacao_custos!B10,#REF!,16,0),0) -> 0 | R10: =IFERROR(VLOOKUP(B10,cubo!$A$6:$BK$37,64,0)-VLOOKUP(conciliacao_custos!B10,#REF!,17,0),0) -> 0 | S10: =IFERROR(VLOOKUP(B10,cubo!$A$6:$BK$37,61,0)-VLOOKUP(conciliacao_custos!B10,#REF!,15,0),0) -> 0
B11: =[1]salario!A10 -> 8 | C11: =[1]salario!C10 -> Colaborador 8 | D11: =IFERROR(VLOOKUP(B11,cubo!$A$6:$BE$37,6,0)-VLOOKUP(B11,#REF!,$D$2,0),0) -> 0 | E11: =IFERROR(VLOOKUP(B11,cubo!$A$6:$BE$37,9,0)-VLOOKUP(B11,#REF!,$E$2,0),0) -> 0 | F11: =IFERROR(VLOOKUP(B11,cubo!$A$6:$BE$37,12,0)-VLOOKUP(B11,#REF!,$F$2,0),0) -> 0 | G11: =IFERROR(VLOOKUP(B11,cubo!$A$6:$BE$37,54,0)-VLOOKUP(B11,#REF!,$G$2,0),0) -> 0 | H11: =IFERROR(VLOOKUP(B11,cubo!$A$6:$BE$37,15,0)-VLOOKUP(B11,#REF!,$H$2,0),0) -> 0 | I11: =IFERROR(VLOOKUP(B11,cubo!$A$6:$BE$37,18,0)-VLOOKUP(B11,#REF!,$I$2,0),0) -> 0 | J11: =IFERROR(VLOOKUP(B11,cubo!$A$6:$BE$37,24,0)-VLOOKUP(B11,#REF!,$J$2,0),0) -> 0 | K11: =IFERROR(VLOOKUP(B11,cubo!$A$6:$BE$37,34,0)-VLOOKUP(B11,#REF!,$K$2,0),0) -> 0 | L11: =IFERROR(VLOOKUP(B11,cubo!$A$6:$BE$37,38,0)-VLOOKUP(B11,#REF!,$L$2,0),0) -> 0 | M11: =IFERROR(VLOOKUP(B11,cubo!$A$6:$BE$37,57,0)-VLOOKUP(B11,#REF!,$M$2,0),0) -> 0 | N11: =IFERROR(VLOOKUP(B11,cubo!$A$6:$BK$37,41,0)-VLOOKUP(conciliacao_custos!B11,#REF!,18,0),0) -> 0 | O11: =IFERROR(VLOOKUP(B11,cubo!$A$6:$BK$37,44,0)-VLOOKUP(conciliacao_custos!B11,#REF!,13,0),0) -> 0 | P11: =IFERROR(VLOOKUP(B11,cubo!$A$6:$BK$37,47,0)-VLOOKUP(conciliacao_custos!B11,#REF!,14,0),0) -> 0 | Q11: =IFERROR(VLOOKUP(B11,cubo!$A$6:$BK$37,58,0)-VLOOKUP(conciliacao_custos!B11,#REF!,16,0),0) -> 0 | R11: =IFERROR(VLOOKUP(B11,cubo!$A$6:$BK$37,64,0)-VLOOKUP(conciliacao_custos!B11,#REF!,17,0),0) -> 0 | S11: =IFERROR(VLOOKUP(B11,cubo!$A$6:$BK$37,61,0)-VLOOKUP(conciliacao_custos!B11,#REF!,15,0),0) -> 0
B12: =[1]salario!A11 -> 9 | C12: =[1]salario!C11 -> Colaborador 9 | D12: =IFERROR(VLOOKUP(B12,cubo!$A$6:$BE$37,6,0)-VLOOKUP(B12,#REF!,$D$2,0),0) -> 0 | E12: =IFERROR(VLOOKUP(B12,cubo!$A$6:$BE$37,9,0)-VLOOKUP(B12,#REF!,$E$2,0),0) -> 0 | F12: =IFERROR(VLOOKUP(B12,cubo!$A$6:$BE$37,12,0)-VLOOKUP(B12,#REF!,$F$2,0),0) -> 0 | G12: =IFERROR(VLOOKUP(B12,cubo!$A$6:$BE$37,54,0)-VLOOKUP(B12,#REF!,$G$2,0),0) -> 0 | H12: =IFERROR(VLOOKUP(B12,cubo!$A$6:$BE$37,15,0)-VLOOKUP(B12,#REF!,$H$2,0),0) -> 0 | I12: =IFERROR(VLOOKUP(B12,cubo!$A$6:$BE$37,18,0)-VLOOKUP(B12,#REF!,$I$2,0),0) -> 0 | J12: =IFERROR(VLOOKUP(B12,cubo!$A$6:$BE$37,24,0)-VLOOKUP(B12,#REF!,$J$2,0),0) -> 0 | K12: =IFERROR(VLOOKUP(B12,cubo!$A$6:$BE$37,34,0)-VLOOKUP(B12,#REF!,$K$2,0),0) -> 0 | L12: =IFERROR(VLOOKUP(B12,cubo!$A$6:$BE$37,38,0)-VLOOKUP(B12,#REF!,$L$2,0),0) -> 0 | M12: =IFERROR(VLOOKUP(B12,cubo!$A$6:$BE$37,57,0)-VLOOKUP(B12,#REF!,$M$2,0),0) -> 0 | N12: =IFERROR(VLOOKUP(B12,cubo!$A$6:$BK$37,41,0)-VLOOKUP(conciliacao_custos!B12,#REF!,18,0),0) -> 0 | O12: =IFERROR(VLOOKUP(B12,cubo!$A$6:$BK$37,44,0)-VLOOKUP(conciliacao_custos!B12,#REF!,13,0),0) -> 0 | P12: =IFERROR(VLOOKUP(B12,cubo!$A$6:$BK$37,47,0)-VLOOKUP(conciliacao_custos!B12,#REF!,14,0),0) -> 0 | Q12: =IFERROR(VLOOKUP(B12,cubo!$A$6:$BK$37,58,0)-VLOOKUP(conciliacao_custos!B12,#REF!,16,0),0) -> 0 | R12: =IFERROR(VLOOKUP(B12,cubo!$A$6:$BK$37,64,0)-VLOOKUP(conciliacao_custos!B12,#REF!,17,0),0) -> 0 | S12: =IFERROR(VLOOKUP(B12,cubo!$A$6:$BK$37,61,0)-VLOOKUP(conciliacao_custos!B12,#REF!,15,0),0) -> 0
B13: =[1]salario!A12 -> 10 | C13: =[1]salario!C12 -> Colaborador 10 | D13: =IFERROR(VLOOKUP(B13,cubo!$A$6:$BE$37,6,0)-VLOOKUP(B13,#REF!,$D$2,0),0) -> 0 | E13: =IFERROR(VLOOKUP(B13,cubo!$A$6:$BE$37,9,0)-VLOOKUP(B13,#REF!,$E$2,0),0) -> 0 | F13: =IFERROR(VLOOKUP(B13,cubo!$A$6:$BE$37,12,0)-VLOOKUP(B13,#REF!,$F$2,0),0) -> 0 | G13: =IFERROR(VLOOKUP(B13,cubo!$A$6:$BE$37,54,0)-VLOOKUP(B13,#REF!,$G$2,0),0) -> 0 | H13: =IFERROR(VLOOKUP(B13,cubo!$A$6:$BE$37,15,0)-VLOOKUP(B13,#REF!,$H$2,0),0) -> 0 | I13: =IFERROR(VLOOKUP(B13,cubo!$A$6:$BE$37,18,0)-VLOOKUP(B13,#REF!,$I$2,0),0) -> 0 | J13: =IFERROR(VLOOKUP(B13,cubo!$A$6:$BE$37,24,0)-VLOOKUP(B13,#REF!,$J$2,0),0) -> 0 | K13: =IFERROR(VLOOKUP(B13,cubo!$A$6:$BE$37,34,0)-VLOOKUP(B13,#REF!,$K$2,0),0) -> 0 | L13: =IFERROR(VLOOKUP(B13,cubo!$A$6:$BE$37,38,0)-VLOOKUP(B13,#REF!,$L$2,0),0) -> 0 | M13: =IFERROR(VLOOKUP(B13,cubo!$A$6:$BE$37,57,0)-VLOOKUP(B13,#REF!,$M$2,0),0) -> 0 | N13: =IFERROR(VLOOKUP(B13,cubo!$A$6:$BK$37,41,0)-VLOOKUP(conciliacao_custos!B13,#REF!,18,0),0) -> 0 | O13: =IFERROR(VLOOKUP(B13,cubo!$A$6:$BK$37,44,0)-VLOOKUP(conciliacao_custos!B13,#REF!,13,0),0) -> 0 | P13: =IFERROR(VLOOKUP(B13,cubo!$A$6:$BK$37,47,0)-VLOOKUP(conciliacao_custos!B13,#REF!,14,0),0) -> 0 | Q13: =IFERROR(VLOOKUP(B13,cubo!$A$6:$BK$37,58,0)-VLOOKUP(conciliacao_custos!B13,#REF!,16,0),0) -> 0 | R13: =IFERROR(VLOOKUP(B13,cubo!$A$6:$BK$37,64,0)-VLOOKUP(conciliacao_custos!B13,#REF!,17,0),0) -> 0 | S13: =IFERROR(VLOOKUP(B13,cubo!$A$6:$BK$37,61,0)-VLOOKUP(conciliacao_custos!B13,#REF!,15,0),0) -> 0
B14: =[1]salario!A13 -> 11 | C14: =[1]salario!C13 -> Colaborador 11 | D14: =IFERROR(VLOOKUP(B14,cubo!$A$6:$BE$37,6,0)-VLOOKUP(B14,#REF!,$D$2,0),0) -> 0 | E14: =IFERROR(VLOOKUP(B14,cubo!$A$6:$BE$37,9,0)-VLOOKUP(B14,#REF!,$E$2,0),0) -> 0 | F14: =IFERROR(VLOOKUP(B14,cubo!$A$6:$BE$37,12,0)-VLOOKUP(B14,#REF!,$F$2,0),0) -> 0 | G14: =IFERROR(VLOOKUP(B14,cubo!$A$6:$BE$37,54,0)-VLOOKUP(B14,#REF!,$G$2,0),0) -> 0 | H14: =IFERROR(VLOOKUP(B14,cubo!$A$6:$BE$37,15,0)-VLOOKUP(B14,#REF!,$H$2,0),0) -> 0 | I14: =IFERROR(VLOOKUP(B14,cubo!$A$6:$BE$37,18,0)-VLOOKUP(B14,#REF!,$I$2,0),0) -> 0 | J14: =IFERROR(VLOOKUP(B14,cubo!$A$6:$BE$37,24,0)-VLOOKUP(B14,#REF!,$J$2,0),0) -> 0 | K14: =IFERROR(VLOOKUP(B14,cubo!$A$6:$BE$37,34,0)-VLOOKUP(B14,#REF!,$K$2,0),0) -> 0 | L14: =IFERROR(VLOOKUP(B14,cubo!$A$6:$BE$37,38,0)-VLOOKUP(B14,#REF!,$L$2,0),0) -> 0 | M14: =IFERROR(VLOOKUP(B14,cubo!$A$6:$BE$37,57,0)-VLOOKUP(B14,#REF!,$M$2,0),0) -> 0 | N14: =IFERROR(VLOOKUP(B14,cubo!$A$6:$BK$37,41,0)-VLOOKUP(conciliacao_custos!B14,#REF!,18,0),0) -> 0 | O14: =IFERROR(VLOOKUP(B14,cubo!$A$6:$BK$37,44,0)-VLOOKUP(conciliacao_custos!B14,#REF!,13,0),0) -> 0 | P14: =IFERROR(VLOOKUP(B14,cubo!$A$6:$BK$37,47,0)-VLOOKUP(conciliacao_custos!B14,#REF!,14,0),0) -> 0 | Q14: =IFERROR(VLOOKUP(B14,cubo!$A$6:$BK$37,58,0)-VLOOKUP(conciliacao_custos!B14,#REF!,16,0),0) -> 0 | R14: =IFERROR(VLOOKUP(B14,cubo!$A$6:$BK$37,64,0)-VLOOKUP(conciliacao_custos!B14,#REF!,17,0),0) -> 0 | S14: =IFERROR(VLOOKUP(B14,cubo!$A$6:$BK$37,61,0)-VLOOKUP(conciliacao_custos!B14,#REF!,15,0),0) -> 0
B15: =[1]salario!A14 -> 12 | C15: =[1]salario!C14 -> Colaborador 12 | D15: =IFERROR(VLOOKUP(B15,cubo!$A$6:$BE$37,6,0)-VLOOKUP(B15,#REF!,$D$2,0),0) -> 0 | E15: =IFERROR(VLOOKUP(B15,cubo!$A$6:$BE$37,9,0)-VLOOKUP(B15,#REF!,$E$2,0),0) -> 0 | F15: =IFERROR(VLOOKUP(B15,cubo!$A$6:$BE$37,12,0)-VLOOKUP(B15,#REF!,$F$2,0),0) -> 0 | G15: =IFERROR(VLOOKUP(B15,cubo!$A$6:$BE$37,54,0)-VLOOKUP(B15,#REF!,$G$2,0),0) -> 0 | H15: =IFERROR(VLOOKUP(B15,cubo!$A$6:$BE$37,15,0)-VLOOKUP(B15,#REF!,$H$2,0),0) -> 0 | I15: =IFERROR(VLOOKUP(B15,cubo!$A$6:$BE$37,18,0)-VLOOKUP(B15,#REF!,$I$2,0),0) -> 0 | J15: =IFERROR(VLOOKUP(B15,cubo!$A$6:$BE$37,24,0)-VLOOKUP(B15,#REF!,$J$2,0),0) -> 0 | K15: =IFERROR(VLOOKUP(B15,cubo!$A$6:$BE$37,34,0)-VLOOKUP(B15,#REF!,$K$2,0),0) -> 0 | L15: =IFERROR(VLOOKUP(B15,cubo!$A$6:$BE$37,38,0)-VLOOKUP(B15,#REF!,$L$2,0),0) -> 0 | M15: =IFERROR(VLOOKUP(B15,cubo!$A$6:$BE$37,57,0)-VLOOKUP(B15,#REF!,$M$2,0),0) -> 0 | N15: =IFERROR(VLOOKUP(B15,cubo!$A$6:$BK$37,41,0)-VLOOKUP(conciliacao_custos!B15,#REF!,18,0),0) -> 0 | O15: =IFERROR(VLOOKUP(B15,cubo!$A$6:$BK$37,44,0)-VLOOKUP(conciliacao_custos!B15,#REF!,13,0),0) -> 0 | P15: =IFERROR(VLOOKUP(B15,cubo!$A$6:$BK$37,47,0)-VLOOKUP(conciliacao_custos!B15,#REF!,14,0),0) -> 0 | Q15: =IFERROR(VLOOKUP(B15,cubo!$A$6:$BK$37,58,0)-VLOOKUP(conciliacao_custos!B15,#REF!,16,0),0) -> 0 | R15: =IFERROR(VLOOKUP(B15,cubo!$A$6:$BK$37,64,0)-VLOOKUP(conciliacao_custos!B15,#REF!,17,0),0) -> 0 | S15: =IFERROR(VLOOKUP(B15,cubo!$A$6:$BK$37,61,0)-VLOOKUP(conciliacao_custos!B15,#REF!,15,0),0) -> 0
... B666: =[1]salario!A665 -> 0 | C666: =[1]salario!C665 -> 0 | D666: =IFERROR(VLOOKUP(B666,cubo!$A$6:$BE$37,6,0)-VLOOKUP(B666,#REF!,$D$2,0),0) -> 0 | E666: =IFERROR(VLOOKUP(B666,cubo!$A$6:$BE$37,9,0)-VLOOKUP(B666,#REF!,$E$2,0),0) -> 0 | F666: =IFERROR(VLOOKUP(B666,cubo!$A$6:$BE$37,12,0)-VLOOKUP(B666,#REF!,$F$2,0),0) -> 0 | G666: =IFERROR(VLOOKUP(B666,cubo!$A$6:$BE$37,54,0)-VLOOKUP(B666,#REF!,$G$2,0),0) -> 0 | H666: =IFERROR(VLOOKUP(B666,cubo!$A$6:$BE$37,15,0)-VLOOKUP(B666,#REF!,$H$2,0),0) -> 0 | I666: =IFERROR(VLOOKUP(B666,cubo!$A$6:$BE$37,18,0)-VLOOKUP(B666,#REF!,$I$2,0),0) -> 0 | J666: =IFERROR(VLOOKUP(B666,cubo!$A$6:$BE$37,24,0)-VLOOKUP(B666,#REF!,$J$2,0),0) -> 0 | K666: =IFERROR(VLOOKUP(B666,cubo!$A$6:$BE$37,34,0)-VLOOKUP(B666,#REF!,$K$2,0),0) -> 0 | L666: =IFERROR(VLOOKUP(B666,cubo!$A$6:$BE$37,38,0)-VLOOKUP(B666,#REF!,$L$2,0),0) -> 0 | M666: =IFERROR(VLOOKUP(B666,cubo!$A$6:$BE$37,57,0)-VLOOKUP(B666,#REF!,$M$2,0),0) -> 0 | N666: =IFERROR(VLOOKUP(B666,cubo!$A$6:$BK$37,41,0)-VLOOKUP(conciliacao_custos!B666,#REF!,18,0),0) -> 0 | O666: =IFERROR(VLOOKUP(B666,cubo!$A$6:$BK$37,44,0)-VLOOKUP(conciliacao_custos!B666,#REF!,13,0),0) -> 0 | P666: =IFERROR(VLOOKUP(B666,cubo!$A$6:$BK$37,47,0)-VLOOKUP(conciliacao_custos!B666,#REF!,14,0),0) -> 0 | Q666: =IFERROR(VLOOKUP(B666,cubo!$A$6:$BK$37,58,0)-VLOOKUP(conciliacao_custos!B666,#REF!,16,0),0) -> 0 | R666: =IFERROR(VLOOKUP(B666,cubo!$A$6:$BK$37,64,0)-VLOOKUP(conciliacao_custos!B666,#REF!,17,0),0) -> 0 | S666: =IFERROR(VLOOKUP(B666,cubo!$A$6:$BK$37,61,0)-VLOOKUP(conciliacao_custos!B666,#REF!,15,0),0) -> 0

Sheet conciliação_descontos
D1: =SUBTOTAL(9,D4:D645) -> 0 | E1: =SUBTOTAL(9,E4:E645) -> 0 | F1: =SUBTOTAL(9,F4:F645) -> 0 | G1: =SUBTOTAL(9,G4:G645) -> 0 | H1: =SUBTOTAL(9,H4:H645) -> 0 | I1: =SUBTOTAL(9,I4:I645) -> 0 | J1: =SUBTOTAL(9,J4:J645) -> 0 | K1: =SUBTOTAL(9,K4:K645) -> 0 | ... AN1: =SUBTOTAL(9,AN4:AN645) -> 0
D2: 3 | E2: 4 | F2: 5 | G2: 6 | H2: 7 | I2: 8 | J2: 9 | K2: 10 | L2: 11 | M2: 12 | N2: 13 | O2: 14 | P2: 15 | Q2: 16 | R2: 17 | S2: 18 | T2: 19 | U2: 20 | V2: 21 | W2: 22 | X2: 23 | Y2: 24 | Z2: 25 | AA2: 26 | AB2: 27 | AC2: 28 | AD2: 29 | AE2: 30 | AF2: 31 | AG2: 32 | AH2: 33 | AI2: 34 | AJ2: 35 | AK2: 36 | AL2: 37 | AM2: 38 | AN2: 39
B3: Mat | C3: Nome | D3: Salario | E3: Unimed | F3: Uniodonto | G3: Refeição | H3: Caju Extra | I3: SVG | J3: Sistel | K3: Empr Sistel | L3: Claro | M3: Transporte | N3: Pensão Alimentícia | O3: Assistencia Saúde | P3: Ingles | Q3: Open English | R3: Zenklub | S3: Bradesco Saúde | T3: Bradesco Dental | U3: Diaria de Viagem | V3: Caju Intermitentes | W3: Gratificação | X3: Auxilio Creche | Y3: Reembolso func | Z3: Pós Graduação | AA3: Auxílio HO | AB3: ASO | AC3: Auxilio funeral | AD3: Indicação premiada | AE3: Auxilio Transporte | AF3: Ascan | AG3: Comissao | AH3: Academy | AI3: Diaria de Viagem | AJ3: Creche Intermitentes | AK3: Auxílio HO - Intermitente | AL3: Gympass | AM3: Agiel | AN3: Zenklub
B4: =[1]salario!A3 -> 1 | C4: =[1]salario!C3 -> Colaborador 1 | D4: =IFERROR(VLOOKUP(B4,cubo!$A$6:$BE$37,3,0)-VLOOKUP(B4,#REF!,$D$2,0),0) -> 0 | E4: =IFERROR(VLOOKUP(B4,cubo!$A$6:$BE$37,5,0)-VLOOKUP(B4,#REF!,$E$2,0),0) -> 0 | F4: =IFERROR(VLOOKUP(B4,cubo!$A$6:$BE$37,8,0)-VLOOKUP(B4,#REF!,$F$2,0),0) -> 0 | G4: =IFERROR(VLOOKUP(B4,cubo!$A$6:$BE$37,11,0)-VLOOKUP(B4,#REF!,$G$2,0),0) -> 0 | H4: =IFERROR(VLOOKUP(B4,cubo!$A$6:$BE$37,53,0)-VLOOKUP(B4,#REF!,$H$2,0),0) -> 0 | I4: =IFERROR(VLOOKUP(B4,cubo!$A$6:$BE$37,14,0)-VLOOKUP(B4,#REF!,$I$2,0),0) -> 0 | J4: =IFERROR(VLOOKUP(B4,cubo!$A$6:$BE$37,16,0)-VLOOKUP(B4,#REF!,$J$2,0),0) -> 0 | K4: =IFERROR(VLOOKUP(B4,cubo!$A$6:$BE$37,17,0)-VLOOKUP(B4,#REF!,$K$2,0),0) -> 0 | L4: =IFERROR(VLOOKUP(B4,cubo!$A$6:$BE$37,19,0)-VLOOKUP(B4,#REF!,$L$2,0),0) -> 0 | M4: =IFERROR(VLOOKUP(B4,cubo!$A$6:$BE$37,23,0)-VLOOKUP(B4,#REF!,$M$2,0),0) -> 0 | N4: =IFERROR(VLOOKUP(B4,cubo!$A$6:$BE$37,25,0)-VLOOKUP(B4,#REF!,$N$2,0),0) -> 0 | O4: =IFERROR(VLOOKUP(B4,cubo!$A$6:$BE$37,33,0)-VLOOKUP(B4,#REF!,$O$2,0),0) -> 0 | P4: =IFERROR(VLOOKUP(B4,cubo!$A$6:$BE$37,37,0)-VLOOKUP(B4,#REF!,$P$2,0),0) -> 0 | Q4: =IFERROR(VLOOKUP(B4,cubo!$A$6:$BE$37,56,0)-VLOOKUP(B4,#REF!,$Q$2,0),0) -> 0 | R4: =IFERROR(VLOOKUP(B4,cubo!$A$6:$BE$37,40,0)-VLOOKUP(B4,#REF!,$R$2,0),0) -> 0 | S4: =IFERROR(VLOOKUP(B4,cubo!$A$6:$BE$37,43,0)-VLOOKUP(B4,#REF!,$S$2,0),0) -> 0 | T4: =IFERROR(VLOOKUP(B4,cubo!$A$6:$BE$37,46,0)-VLOOKUP(B4,#REF!,$T$2,0),0) -> 0 | U4: =IFERROR(VLOOKUP(B4,cubo!$A$6:$BE$37,51,0)-VLOOKUP(B4,#REF!,$U$2,0),0) -> 0 | V4: =IFERROR(VLOOKUP(B4,cubo!$A$6:$BJ$37,60,0)-VLOOKUP(B4,#REF!,$V$2,0),0) -> 0 | W4: =IFERROR(VLOOKUP(B4,cubo!$A$6:$BE$37,26,0)-VLOOKUP(B4,#REF!,$W$2,0),0) -> 0 | X4: =IFERROR(VLOOKUP(B4,cubo!$A$6:$BE$37,20,0)-VLOOKUP(B4,#REF!,$X$2,0),0) -> 0 | Y4: =IFERROR(VLOOKUP(B4,cubo!$A$6:$BE$37,21,0)-VLOOKUP(B4,#REF!,$Y$2,0),0) -> 0 | Z4: =IFERROR(VLOOKUP(B4,cubo!$A$6:$BE$37,27,0)-VLOOKUP(B4,#REF!,$Z$2,0),0) -> 0 | AA4: =IFERROR(VLOOKUP(B4,cubo!$A$6:$BE$37,28,0)-VLOOKUP(B4,#REF!,$AA$2,0),0) -> 0 | AB4: =IFERROR(VLOOKUP(B4,cubo!$A$6:$BE$37,29,0)-VLOOKUP(B4,#REF!,$AB$2,0),0) -> 0 | AC4: =IFERROR(VLOOKUP(B4,cubo!$A$6:$BE$37,30,0)-VLOOKUP(B4,#REF!,$AC$2,0),0) -> 0 | AD4: =IFERROR(VLOOKUP(B4,cubo!$A$6:$BE$37,31,0)-VLOOKUP(B4,#REF!,$AD$2,0),0) -> 0 | AE4: =IFERROR(VLOOKUP(B4,cubo!$A$6:$BE$37,35,0)-VLOOKUP(B4,#REF!,$AE$2,0),0) -> 0 | AF4: {=IFERROR(rrPROCV(B4,cubo!$A$6:$BE$37,48,0)-VLOOKUP(B4,#REF!,$AF$2,0),0)} -> 0 | AG4: =IFERROR(VLOOKUP(B4,cubo!$A$6:$BE$37,49,0)-VLOOKUP(B4,#REF!,$AG$2,0),0) -> 0 | AH4: =IFERROR(VLOOKUP(B4,cubo!$A$6:$BE$37,50,0)-VLOOKUP(B4,#REF!,$AH$2,0),0) -> 0 | AI4: =IFERROR(VLOOKUP(B4,cubo!$A$6:$BE$37,51,0)-VLOOKUP(B4,#REF!,$AI$2,0),0) -> 0 | AJ4: =IFERROR(VLOOKUP(B4,cubo!$A$6:$BI$116,62,0)-VLOOKUP(B4,#REF!,$AJ$2,0),0) -> 0 | AK4: =IFERROR(VLOOKUP(B4,cubo!$A$6:$BJ$37,63,0)-VLOOKUP(B4,#REF!,$AK$2,0),0) -> 0 | AL4: =IFERROR(VLOOKUP(B4,cubo!$A$6:$BE$37,58,0)-VLOOKUP(B4,#REF!,$AL$2,0),0) -> 0 | AM4: =IFERROR(VLOOKUP(B4,cubo!$A$6:$BK$37,64,0)-VLOOKUP(B4,#REF!,$AM$2,0),0) -> 0 | AN4: =IFERROR(VLOOKUP(B4,cubo!$A$6:$AN$37,41,0)-VLOOKUP(B4,#REF!,$AN$2,0),0) -> 0
B5: =[1]salario!A4 -> 2 | C5: =[1]salario!C4 -> Colaborador 2 | D5: =IFERROR(VLOOKUP(B5,cubo!$A$6:$BE$37,3,0)-VLOOKUP(B5,#REF!,$D$2,0),0) -> 0 | E5: =IFERROR(VLOOKUP(B5,cubo!$A$6:$BE$37,5,0)-VLOOKUP(B5,#REF!,$E$2,0),0) -> 0 | F5: =IFERROR(VLOOKUP(B5,cubo!$A$6:$BE$37,8,0)-VLOOKUP(B5,#REF!,$F$2,0),0) -> 0 | G5: =IFERROR(VLOOKUP(B5,cubo!$A$6:$BE$37,11,0)-VLOOKUP(B5,#REF!,$G$2,0),0) -> 0 | H5: =IFERROR(VLOOKUP(B5,cubo!$A$6:$BE$37,53,0)-VLOOKUP(B5,#REF!,$H$2,0),0) -> 0 | I5: =IFERROR(VLOOKUP(B5,cubo!$A$6:$BE$37,14,0)-VLOOKUP(B5,#REF!,$I$2,0),0) -> 0 | J5: =IFERROR(VLOOKUP(B5,cubo!$A$6:$BE$37,16,0)-VLOOKUP(B5,#REF!,$J$2,0),0) -> 0 | K5: =IFERROR(VLOOKUP(B5,cubo!$A$6:$BE$37,17,0)-VLOOKUP(B5,#REF!,$K$2,0),0) -> 0 | L5: =IFERROR(VLOOKUP(B5,cubo!$A$6:$BE$37,19,0)-VLOOKUP(B5,#REF!,$L$2,0),0) -> 0 | M5: =IFERROR(VLOOKUP(B5,cubo!$A$6:$BE$37,23,0)-VLOOKUP(B5,#REF!,$M$2,0),0) -> 0 | N5: =IFERROR(VLOOKUP(B5,cubo!$A$6:$BE$37,25,0)-VLOOKUP(B5,#REF!,$N$2,0),0) -> 0 | O5: =IFERROR(VLOOKUP(B5,cubo!$A$6:$BE$37,33,0)-VLOOKUP(B5,#REF!,$O$2,0),0) -> 0 | P5: =IFERROR(VLOOKUP(B5,cubo!$A$6:$BE$37,37,0)-VLOOKUP(B5,#REF!,$P$2,0),0) -> 0 | Q5: =IFERROR(VLOOKUP(B5,cubo!$A$6:$BE$37,56,0)-VLOOKUP(B5,#REF!,$Q$2,0),0) -> 0 | R5: =IFERROR(VLOOKUP(B5,cubo!$A$6:$BE$37,40,0)-VLOOKUP(B5,#REF!,$R$2,0),0) -> 0 | S5: =IFERROR(VLOOKUP(B5,cubo!$A$6:$BE$37,43,0)-VLOOKUP(B5,#REF!,$S$2,0),0) -> 0 | T5: =IFERROR(VLOOKUP(B5,cubo!$A$6:$BE$37,46,0)-VLOOKUP(B5,#REF!,$T$2,0),0) -> 0 | U5: =IFERROR(VLOOKUP(B5,cubo!$A$6:$BE$37,51,0)-VLOOKUP(B5,#REF!,$U$2,0),0) -> 0 | V5: =IFERROR(VLOOKUP(B5,cubo!$A$6:$BJ$37,60,0)-VLOOKUP(B5,#REF!,$V$2,0),0) -> 0 | W5: =IFERROR(VLOOKUP(B5,cubo!$A$6:$BE$37,26,0)-VLOOKUP(B5,#REF!,$W$2,0),0) -> 0 | X5: =IFERROR(VLOOKUP(B5,cubo!$A$6:$BE$37,20,0)-VLOOKUP(B5,#REF!,$X$2,0),0) -> 0 | Y5: =IFERROR(VLOOKUP(B5,cubo!$A$6:$BE$37,21,0)-VLOOKUP(B5,#REF!,$Y$2,0),0) -> 0 | Z5: =IFERROR(VLOOKUP(B5,cubo!$A$6:$BE$37,27,0)-VLOOKUP(B5,#REF!,$Z$2,0),0) -> 0 | AA5: =IFERROR(VLOOKUP(B5,cubo!$A$6:$BE$37,28,0)-VLOOKUP(B5,#REF!,$AA$2,0),0) -> 0 | AB5: =IFERROR(VLOOKUP(B5,cubo!$A$6:$BE$37,29,0)-VLOOKUP(B5,#REF!,$AB$2,0),0) -> 0 | AC5: =IFERROR(VLOOKUP(B5,cubo!$A$6:$BE$37,30,0)-VLOOKUP(B5,#REF!,$AC$2,0),0) -> 0 | AD5: =IFERROR(VLOOKUP(B5,cubo!$A$6:$BE$37,31,0)-VLOOKUP(B5,#REF!,$AD$2,0),0) -> 0 | AE5: =IFERROR(VLOOKUP(B5,cubo!$A$6:$BE$37,35,0)-VLOOKUP(B5,#REF!,$AE$2,0),0) -> 0 | AF5: {=IFERROR(rrPROCV(B5,cubo!$A$6:$BE$37,48,0)-VLOOKUP(B5,#REF!,$AF$2,0),0)} -> 0 | AG5: =IFERROR(VLOOKUP(B5,cubo!$A$6:$BE$37,49,0)-VLOOKUP(B5,#REF!,$AG$2,0),0) -> 0 | AH5: =IFERROR(VLOOKUP(B5,cubo!$A$6:$BE$37,50,0)-VLOOKUP(B5,#REF!,$AH$2,0),0) -> 0 | AI5: =IFERROR(VLOOKUP(B5,cubo!$A$6:$BE$37,51,0)-VLOOKUP(B5,#REF!,$AI$2,0),0) -> 0 | AJ5: =IFERROR(VLOOKUP(B5,cubo!$A$6:$BI$116,62,0)-VLOOKUP(B5,#REF!,$AJ$2,0),0) -> 0 | AK5: =IFERROR(VLOOKUP(B5,cubo!$A$6:$BJ$37,63,0)-VLOOKUP(B5,#REF!,$AK$2,0),0) -> 0 | AL5: =IFERROR(VLOOKUP(B5,cubo!$A$6:$BE$37,58,0)-VLOOKUP(B5,#REF!,$AL$2,0),0) -> 0 | AM5: =IFERROR(VLOOKUP(B5,cubo!$A$6:$BK$37,64,0)-VLOOKUP(B5,#REF!,$AM$2,0),0) -> 0 | AN5: =IFERROR(VLOOKUP(B5,cubo!$A$6:$AN$37,41,0)-VLOOKUP(B5,#REF!,$AN$2,0),0) -> 0
