Workbook
Name CARGOS: [1]cargos_atlantico!$B$8:$B$33
Name EIXOS: [1]cargos_atlantico!$H$8:$H$14

Sheet total
E1: =SUBTOTAL(9,E4:E33) -> 146612.78 | F1: =SUBTOTAL(9,F4:F33) -> #VALUE! | G1: =SUBTOTAL(9,G4:G33) -> #VALUE! | H1: =SUBTOTAL(9,H4:H33) -> #VALUE! | I1: =SUBTOTAL(9,I4:I33) -> 4514.33 | J1: =SUBTOTAL(9,J4:J33) -> 640.0223 | K1: =SUBTOTAL(9,K4:K33) -> 3874.3077 | L1: =SUBTOTAL(9,L4:L33) -> 15150 | ... BP1: =SUBTOTAL(9,BP4:BP33) -> 0
B2: Mat | C2: Matrícula | D2: Nome | E2: Salário | F2: Unimed | I2: Uniodonto | L2: Caju | O2: Seguro de Vida | R2: Sistel | U2: Claro | V2: Auxílio Creche | W2: Reembolso Func | X2: Transporte | AA2: Pensão Alimentícia | AB2: Gratificação | AC2: Auxílio Pós Graduação | AD2: Auxílio HO | AE2: ASO | AF2: Auxílio Funeral | AG2: Indicação Premiada | AH2: Assistência Saúde | AK2: Auxílio Transporte | AL2: Inglês Tim | AO2: Zenklub | AQ2: Zenklub | AR2: Bradesco Saúde | AU2: Bradesco Dental | AX2: Ascan | AY2: Comissão | AZ2: Academy | BA2: Diária de Viagem | BB2: Caju Extra | BE2: Open English | BH2: Gympass | BI2: Agiel | BJ2: Caju Intermitentes | BM2: Diferença Sistel | BO2: Auxílio HO - Intermitente | BP2: Creche - Intermitente
F3: Fatura | G3: Desconto | H3: Custo | I3: Fatura | J3: Desconto | K3: Custo | L3: Fatura | M3: Desconto | N3: Custo | O3: Fatura | P3: Desconto | Q3: Custo | R3: Folha | S3: Empresti | T3: Custo | V3: Custo | X3: Fatura | Y3: Desconto | Z3: Custo | AA3: Desconto | AB3: Custo | AH3: Fatura | AI3: Desconto | AJ3: Custo | AL3: Fatura | AM3: Desconto | AN3: Custo | AO3: Fatura | AP3: Desconto | AQ3: Custo | AR3: Fatura | AS3: Desconto | AT3: Custo | AU3: Fatura | AV3: Desconto | AW3: Custo | BB3: Fatura | BC3: Desconto | BD3: Custo | BE3: Fatura | BF3: Desconto | BG3: Custo | BH3: Custo | BI3: Custo | BJ3: Fatura | BK3: Desconto | BL3: Custo | BM3: Folha | BN3: Custo
B4: 1 | C4: =VLOOKUP(B4,salario!$A$3:$C$195,2,0) -> ATIVO | D4: =VLOOKUP(B4,salario!$A$3:$C$195,3,0) -> Colaborador 1 | E4: =IFERROR(VLOOKUP(B4,salario!$A$3:$K$854,11,0), "0") -> 5826.03 | F4: =SUMIF([2]unimed!$AL:$AL,B4,[2]unimed!$AJ:$AJ) -> #VALUE! | G4: =SUMIF([2]unimed!$AL:$AL,B4,[2]unimed!$AQ:$AQ) -> #VALUE! | H4: =SUMIF([2]unimed!$AL:$AL,B4,[2]unimed!$AP:$AP) -> #VALUE! | I4: =IFERROR(VLOOKUP(B4,uniodonto!$B$3:$F$339,5,0),0) -> 84.38 | J4: =IF(E4>=0,IF(AND(E4>tabelas!$C$4,E4<=tabelas!$C$5),I4*tabelas!$E$4,IF(AND(E4>=tabelas!$C$5,E4<=tabelas!$C$6),I4*tabelas!$E$5,IF(AND(E4>=tabelas!$C$6,E4<=tabelas!$C$7),I4*tabelas!$E$6,IF(AND(E4>0,E4>tabelas!$C$7),I4*tabelas!$E$7,0))))) -> 12.657 | K4: =I4-J4 -> 71.723 | L4: =SUMIF(caju!$A$4:$A$562,total!B4,caju!$C$4:$C$2900) -> 500 | M4: =IF(E4>=0,IF(AND(E4>tabelas!$C$11,E4<=tabelas!$C$12),L4*tabelas!$E$11,IF(AND(E4>=tabelas!$C$12,E4<=tabelas!$C$13),L4*tabelas!$E$12,IF(AND(E4>=tabelas!$C$13,E4<=tabelas!$C$14),L4*tabelas!$E$13,IF(AND(E4>0,E4>tabelas!$C$14),L4*tabelas!$E$14,0))))) -> 30 | N4: =L4-M4 -> 470 | O4: =IFERROR(VLOOKUP(B4,segurodevida!$B$4:$E$588,4,0),0) -> 18.614166 | P4: =O4/2 -> 9.3070829 | Q4: =O4-P4 -> 9.3070829 | V4: =IFERROR(VLOOKUP(B4,#REF!,3,0),0) -> 0 | W4: =SUMIF(#REF!,total!B4,#REF!) -> #REF! | X4: =IFERROR(VLOOKUP(B4,#REF!,4,0),0) -> 0 | Y4: =IFERROR(VLOOKUP(B4,#REF!,5,0),0) -> 0 | Z4: =IFERROR(X4-Y4,0) -> 0 | AA4: =IFERROR(VLOOKUP(B4,#REF!,3,0),0) -> 0 | AB4: =IFERROR(VLOOKUP(B4,#REF!,3,0),0) -> 0 | AC4: =IFERROR(VLOOKUP(B4,#REF!,5,0),0) -> 0 | AD4: 275 | AE4: =IFERROR(VLOOKUP(B4,#REF!,3,0),0) -> 0 | AF4: =IFERROR(VLOOKUP(B4,#REF!,3,0),0) -> 0 | AG4: =IFERROR(VLOOKUP(B4,#REF!,3,0),0) -> 0 | AK4: =IFERROR(VLOOKUP(B4,#REF!,3,0),0) -> 0 | AL4: =IFERROR(VLOOKUP(B4,ingles!$A$2:$C$673,3,0),"-") -> 165 | AM4: =ROUNDUP(IFERROR(AL4*39.39%,"0"),1) -> 65 | AN4: =IFERROR(AL4-AM4,"-") -> 100 | AO4: =SUMIFS(zenklub!I:I,zenklub!A:A,total!B4) -> 90.566667 | AP4: =SUMIF(zenklub!$A$49:$A$106,total!B4,zenklub!$I$49:$I$106) -> 23.9 | AQ4: =AO4-AP4 -> 66.666667 | AR4: =SUMIF([3]bradesco!$C:$C,B4,[3]bradesco!$M:$M) -> #VALUE! | AS4: =SUMIF([3]bradesco!$C:$C,B4,[3]bradesco!$V:$V) -> #VALUE! | AT4: =IFERROR(SUMIF([3]bradesco!$C:$C,B4,[3]bradesco!$Y:$Y),0) -> 0 | AU4: =SUMIF([4]bradesco!$C:$C,B4,[4]bradesco!$M:$M) -> #VALUE! | AV4: =SUMIF([4]bradesco!$C:$C,B4,[4]bradesco!$V:$V) -> #VALUE! | AW4: =AU4-AV4 -> #VALUE! | AX4: =IFERROR(VLOOKUP(B4,#REF!,3,0),0) -> 0 | AY4: =IFERROR(VLOOKUP(B4,#REF!,3,0),0) -> 0 | AZ4: =IFERROR(VLOOKUP(B4,#REF!,3,0),0) -> 0 | BA4: 0 | BB4: =IFERROR(VLOOKUP(B4,#REF!,3,0),0) -> 0 | BC4: =IF(E4>=0,IF(AND(E4>tabelas!$C$11,E4<=tabelas!$C$12),BB4*tabelas!$E$11,IF(AND(E4>=tabelas!$C$12,E4<=tabelas!$C$13),BB4*tabelas!$E$12,IF(AND(E4>=tabelas!$C$13,E4<=tabelas!$C$14),BB4*tabelas!$E$13,IF(AND(E4>0,E4>tabelas!$C$14),BB4*tabelas!$E$14,0))))) -> 0 | BD4: =BB4-BC4 -> 0 | BE4: =SUMIF(open_english!A:A,total!B4,open_english!C:C) -> 138.88889 | BF4: =SUMIF(open_english!A:A,total!B4,open_english!D:D) -> 96.56 | BG4: =SUMIF(open_english!A:A,total!B4,open_english!E:E) -> 42.328889 | BH4: =IFERROR(VLOOKUP(B4,gympass!$A$2:$F$527,6,0),"-") -> 166.66667 | BI4: =IFERROR(VLOOKUP(B4,#REF!,4,0),"-") -> - | BJ4: =IFERROR(VLOOKUP(B4,#REF!,3,0),0) -> 0 | BK4: =IF(E4>=0,IF(AND(E4>tabelas!$C$11,E4<=tabelas!$C$12),BJ4*tabelas!$E$11,IF(AND(E4>=tabelas!$C$12,E4<=tabelas!$C$13),BJ4*tabelas!$E$12,IF(AND(E4>=tabelas!$C$13,E4<=tabelas!$C$14),BJ4*tabelas!$E$13,IF(AND(E4>0,E4>tabelas!$C$14),BJ4*tabelas!$E$14,0))))) -> 0 | BL4: =BJ4-BK4 -> 0 | BM4: =IFERROR(INDEX(dif_sistel!L:L,MATCH(total!B4,dif_sistel!D:D,0)),0)+IFERROR(INDEX(dif_sistel!N:N,MATCH(total!B4,dif_sistel!D:D,0)),0) -> 0 | BN4: =IFERROR(VLOOKUP(B4,dif_sistel!$D$3:$X$257,21,0),0) -> 0 | BO4: =IFERROR(SUMIF(#REF!,total!B4,#REF!),"0") -> 0 | BP4: =IFERROR(SUMIF(#REF!,total!B4,#REF!),"0") -> 0
B5: 2 | C5: =VLOOKUP(B5,salario!$A$3:$C$195,2,0) -> ATIVO | D5: =VLOOKUP(B5,salario!$A$3:$C$195,3,0) -> Colaborador 2 | E5: =IFERROR(VLOOKUP(B5,salario!$A$3:$K$854,11,0), "0") -> 4332.22 | F5: =SUMIF([2]unimed!$AL:$AL,B5,[2]unimed!$AJ:$AJ) -> #VALUE! | G5: =SUMIF([2]unimed!$AL:$AL,B5,[2]unimed!$AQ:$AQ) -> #VALUE! | H5: =SUMIF([2]unimed!$AL:$AL,B5,[2]unimed!$AP:$AP) -> #VALUE! | I5: =IFERROR(VLOOKUP(B5,uniodonto!$B$3:$F$339,5,0),0) -> 210.95 | J5: =IF(E5>=0,IF(AND(E5>tabelas!$C$4,E5<=tabelas!$C$5),I5*tabelas!$E$4,IF(AND(E5>=tabelas!$C$5,E5<=tabelas!$C$6),I5*tabelas!$E$5,IF(AND(E5>=tabelas!$C$6,E5<=tabelas!$C$7),I5*tabelas!$E$6,IF(AND(E5>0,E5>tabelas!$C$7),I5*tabelas!$E$7,0))))) -> 31.6425 | K5: =I5-J5 -> 179.3075 | L5: =SUMIF(caju!$A$4:$A$562,total!B5,caju!$C$4:$C$2900) -> 500 | M5: =IF(E5>=0,IF(AND(E5>tabelas!$C$11,E5<=tabelas!$C$12),L5*tabelas!$E$11,IF(AND(E5>=tabelas!$C$12,E5<=tabelas!$C$13),L5*tabelas!$E$12,IF(AND(E5>=tabelas!$C$13,E5<=tabelas!$C$14),L5*tabelas!$E$13,IF(AND(E5>0,E5>tabelas!$C$14),L5*tabelas!$E$14,0))))) -> 30 | N5: =L5-M5 -> 470 | O5: =IFERROR(VLOOKUP(B5,segurodevida!$B$4:$E$588,4,0),0) -> 13.841443 | P5: =O5/2 -> 6.9207215 | Q5: =O5-P5 -> 6.9207215 | V5: =IFERROR(VLOOKUP(B5,#REF!,3,0),0) -> 0 | W5: =SUMIF(#REF!,total!B5,#REF!) -> #REF! | X5: =IFERROR(VLOOKUP(B5,#REF!,4,0),0) -> 0 | Y5: =IFERROR(VLOOKUP(B5,#REF!,5,0),0) -> 0 | Z5: =IFERROR(X5-Y5,0) -> 0 | AA5: =IFERROR(VLOOKUP(B5,#REF!,3,0),0) -> 0 | AB5: =IFERROR(VLOOKUP(B5,#REF!,3,0),0) -> 0 | AC5: =IFERROR(VLOOKUP(B5,#REF!,5,0),0) -> 0 | AD5: 275 | AE5: =IFERROR(VLOOKUP(B5,#REF!,3,0),0) -> 0 | AF5: =IFERROR(VLOOKUP(B5,#REF!,3,0),0) -> 0 | AG5: =IFERROR(VLOOKUP(B5,#REF!,3,0),0) -> 0 | AK5: =IFERROR(VLOOKUP(B5,#REF!,3,0),0) -> 0 | AL5: =IFERROR(VLOOKUP(B5,ingles!$A$2:$C$673,3,0),"-") -> 165 | AM5: =ROUNDUP(IFERROR(AL5*39.39%,"0"),1) -> 65 | AN5: =IFERROR(AL5-AM5,"-") -> 100 | AO5: =SUMIFS(zenklub!I:I,zenklub!A:A,total!B5) -> 90.566667 | AP5: =SUMIF(zenklub!$A$49:$A$106,total!B5,zenklub!$I$49:$I$106) -> 23.9 | AQ5: =AO5-AP5 -> 66.666667 | AR5: =SUMIF([3]bradesco!$C:$C,B5,[3]bradesco!$M:$M) -> #VALUE! | AS5: =SUMIF([3]bradesco!$C:$C,B5,[3]bradesco!$V:$V) -> #VALUE! | AT5: =IFERROR(SUMIF([3]bradesco!$C:$C,B5,[3]bradesco!$Y:$Y),0) -> 0 | AU5: =SUMIF([4]bradesco!$C:$C,B5,[4]bradesco!$M:$M) -> #VALUE! | AV5: =SUMIF([4]bradesco!$C:$C,B5,[4]bradesco!$V:$V) -> #VALUE! | AW5: =AU5-AV5 -> #VALUE! | AX5: =IFERROR(VLOOKUP(B5,#REF!,3,0),0) -> 0 | AY5: =IFERROR(VLOOKUP(B5,#REF!,3,0),0) -> 0 | AZ5: =IFERROR(VLOOKUP(B5,#REF!,3,0),0) -> 0 | BA5: 0 | BB5: =IFERROR(VLOOKUP(B5,#REF!,3,0),0) -> 0 | BC5: =IF(E5>=0,IF(AND(E5>tabelas!$C$11,E5<=tabelas!$C$12),BB5*tabelas!$E$11,IF(AND(E5>=tabelas!$C$12,E5<=tabelas!$C$13),BB5*tabelas!$E$12,IF(AND(E5>=tabelas!$C$13,E5<=tabelas!$C$14),BB5*tabelas!$E$13,IF(AND(E5>0,E5>tabelas!$C$14),BB5*tabelas!$E$14,0))))) -> 0 | BD5: =BB5-BC5 -> 0 | BE5: =SUMIF(open_english!A:A,total!B5,open_english!C:C) -> 138.88889 | BF5: =SUMIF(open_english!A:A,total!B5,open_english!D:D) -> 96.56 | BG5: =SUMIF(open_english!A:A,total!B5,open_english!E:E) -> 42.328889 | BH5: =IFERROR(VLOOKUP(B5,gympass!$A$2:$F$527,6,0),"-") -> 166.66667 | BI5: =IFERROR(VLOOKUP(B5,#REF!,4,0),"-") -> - | BJ5: =IFERROR(VLOOKUP(B5,#REF!,3,0),0) -> 0 | BK5: =IF(E5>=0,IF(AND(E5>tabelas!$C$11,E5<=tabelas!$C$12),BJ5*tabelas!$E$11,IF(AND(E5>=tabelas!$C$12,E5<=tabelas!$C$13),BJ5*tabelas!$E$12,IF(AND(E5>=tabelas!$C$13,E5<=tabelas!$C$14),BJ5*tabelas!$E$13,IF(AND(E5>0,E5>tabelas!$C$14),BJ5*tabelas!$E$14,0))))) -> 0 | BL5: =BJ5-BK5 -> 0 | BM5: =IFERROR(INDEX(dif_sistel!L:L,MATCH(total!B5,dif_sistel!D:D,0)),0)+IFERROR(INDEX(dif_sistel!N:N,MATCH(total!B5,dif_sistel!D:D,0)),0) -> 0 | BN5: =IFERROR(VLOOKUP(B5,dif_sistel!$D$3:$X$257,21,0),0) -> 0 | BO5: =IFERROR(SUMIF(#REF!,total!B5,#REF!),"0") -> 0 | BP5: =IFERROR(SUMIF(#REF!,total!B5,#REF!),"0") -> 0
B6: 3 | C6: =VLOOKUP(B6,salario!$A$3:$C$195,2,0) -> ATIVO | D6: =VLOOKUP(B6,salario!$A$3:$C$195,3,0) -> Colaborador 3 | E6: =IFERROR(VLOOKUP(B6,salario!$A$3:$K$854,11,0), "0") -> 4714.12 | F6: =SUMIF([2]unimed!$AL:$AL,B6,[2]unimed!$AJ:$AJ) -> #VALUE! | G6: =SUMIF([2]unimed!$AL:$AL,B6,[2]unimed!$AQ:$AQ) -> #VALUE! | H6: =SUMIF([2]unimed!$AL:$AL,B6,[2]unimed!$AP:$AP) -> #VALUE! | I6: =IFERROR(VLOOKUP(B6,uniodonto!$B$3:$F$339,5,0),0) -> 253.14 | J6: =IF(E6>=0,IF(AND(E6>tabelas!$C$4,E6<=tabelas!$C$5),I6*tabelas!$E$4,IF(AND(E6>=tabelas!$C$5,E6<=tabelas!$C$6),I6*tabelas!$E$5,IF(AND(E6>=tabelas!$C$6,E6<=tabelas!$C$7),I6*tabelas!$E$6,IF(AND(E6>0,E6>tabelas!$C$7),I6*tabelas!$E$7,0))))) -> 37.971 | K6: =I6-J6 -> 215.169 | L6: =SUMIF(caju!$A$4:$A$562,total!B6,caju!$C$4:$C$2900) -> 500 | M6: =IF(E6>=0,IF(AND(E6>tabelas!$C$11,E6<=tabelas!$C$12),L6*tabelas!$E$11,IF(AND(E6>=tabelas!$C$12,E6<=tabelas!$C$13),L6*tabelas!$E$12,IF(AND(E6>=tabelas!$C$13,E6<=tabelas!$C$14),L6*tabelas!$E$13,IF(AND(E6>0,E6>tabelas!$C$14),L6*tabelas!$E$14,0))))) -> 30 | N6: =L6-M6 -> 470 | O6: =IFERROR(VLOOKUP(B6,segurodevida!$B$4:$E$588,4,0),0) -> 15.061613 | P6: =O6/2 -> 7.5308067 | Q6: =O6-P6 -> 7.5308067 | V6: =IFERROR(VLOOKUP(B6,#REF!,3,0),0) -> 0 | W6: =SUMIF(#REF!,total!B6,#REF!) -> #REF! | X6: =IFERROR(VLOOKUP(B6,#REF!,4,0),0) -> 0 | Y6: =IFERROR(VLOOKUP(B6,#REF!,5,0),0) -> 0 | Z6: =IFERROR(X6-Y6,0) -> 0 | AA6: =IFERROR(VLOOKUP(B6,#REF!,3,0),0) -> 0 | AB6: =IFERROR(VLOOKUP(B6,#REF!,3,0),0) -> 0 | AC6: =IFERROR(VLOOKUP(B6,#REF!,5,0),0) -> 0 | AD6: 275 | AE6: =IFERROR(VLOOKUP(B6,#REF!,3,0),0) -> 0 | AF6: =IFERROR(VLOOKUP(B6,#REF!,3,0),0) -> 0 | AG6: =IFERROR(VLOOKUP(B6,#REF!,3,0),0) -> 0 | AK6: =IFERROR(VLOOKUP(B6,#REF!,3,0),0) -> 0 | AL6: =IFERROR(VLOOKUP(B6,ingles!$A$2:$C$673,3,0),"-") -> 165 | AM6: =ROUNDUP(IFERROR(AL6*39.39%,"0"),1) -> 65 | AN6: =IFERROR(AL6-AM6,"-") -> 100 | AO6: =SUMIFS(zenklub!I:I,zenklub!A:A,total!B6) -> 90.566667 | AP6: =SUMIF(zenklub!$A$49:$A$106,total!B6,zenklub!$I$49:$I$106) -> 23.9 | AQ6: =AO6-AP6 -> 66.666667 | AR6: =SUMIF([3]bradesco!$C:$C,B6,[3]bradesco!$M:$M) -> #VALUE! | AS6: =SUMIF([3]bradesco!$C:$C,B6,[3]bradesco!$V:$V) -> #VALUE! | AT6: =IFERROR(SUMIF([3]bradesco!$C:$C,B6,[3]bradesco!$Y:$Y),0) -> 0 | AU6: =SUMIF([4]bradesco!$C:$C,B6,[4]bradesco!$M:$M) -> #VALUE! | AV6: =SUMIF([4]bradesco!$C:$C,B6,[4]bradesco!$V:$V) -> #VALUE! | AW6: =AU6-AV6 -> #VALUE! | AX6: =IFERROR(VLOOKUP(B6,#REF!,3,0),0) -> 0 | AY6: =IFERROR(VLOOKUP(B6,#REF!,3,0),0) -> 0 | AZ6: =IFERROR(VLOOKUP(B6,#REF!,3,0),0) -> 0 | BA6: 0 | BB6: =IFERROR(VLOOKUP(B6,#REF!,3,0),0) -> 0 | BC6: =IF(E6>=0,IF(AND(E6>tabelas!$C$11,E6<=tabelas!$C$12),BB6*tabelas!$E$11,IF(AND(E6>=tabelas!$C$12,E6<=tabelas!$C$13),BB6*tabelas!$E$12,IF(AND(E6>=tabelas!$C$13,E6<=tabelas!$C$14),BB6*tabelas!$E$13,IF(AND(E6>0,E6>tabelas!$C$14),BB6*tabelas!$E$14,0))))) -> 0 | BD6: =BB6-BC6 -> 0 | BE6: =SUMIF(open_english!A:A,total!B6,open_english!C:C) -> 138.88889 | BF6: =SUMIF(open_english!A:A,total!B6,open_english!D:D) -> 96.56 | BG6: =SUMIF(open_english!A:A,total!B6,open_english!E:E) -> 42.328889 | BH6: =IFERROR(VLOOKUP(B6,gympass!$A$2:$F$527,6,0),"-") -> 166.66667 | BI6: =IFERROR(VLOOKUP(B6,#REF!,4,0),"-") -> - | BJ6: =IFERROR(VLOOKUP(B6,#REF!,3,0),0) -> 0 | BK6: =IF(E6>=0,IF(AND(E6>tabelas!$C$11,E6<=tabelas!$C$12),BJ6*tabelas!$E$11,IF(AND(E6>=tabelas!$C$12,E6<=tabelas!$C$13),BJ6*tabelas!$E$12,IF(AND(E6>=tabelas!$C$13,E6<=tabelas!$C$14),BJ6*tabelas!$E$13,IF(AND(E6>0,E6>tabelas!$C$14),BJ6*tabelas!$E$14,0))))) -> 0 | BL6: =BJ6-BK6 -> 0 | BM6: =IFERROR(INDEX(dif_sistel!L:L,MATCH(total!B6,dif_sistel!D:D,0)),0)+IFERROR(INDEX(dif_sistel!N:N,MATCH(total!B6,dif_sistel!D:D,0)),0) -> 0 | BN6: =IFERROR(VLOOKUP(B6,dif_sistel!$D$3:$X$257,21,0),0) -> 0 | BO6: =IFERROR(SUMIF(#REF!,total!B6,#REF!),"0") -> 0 | BP6: =IFERROR(SUMIF(#REF!,total!B6,#REF!),"0") -> 0
B7: 4 | C7: =VLOOKUP(B7,salario!$A$3:$C$195,2,0) -> ATIVO | D7: =VLOOKUP(B7,salario!$A$3:$C$195,3,0) -> Colaborador 4 | E7: =IFERROR(VLOOKUP(B7,salario!$A$3:$K$854,11,0), "0") -> 7685.13 | F7: =SUMIF([2]unimed!$AL:$AL,B7,[2]unimed!$AJ:$AJ) -> #VALUE! | G7: =SUMIF([2]unimed!$AL:$AL,B7,[2]unimed!$AQ:$AQ) -> #VALUE! | H7: =SUMIF([2]unimed!$AL:$AL,B7,[2]unimed!$AP:$AP) -> #VALUE! | I7: =IFERROR(VLOOKUP(B7,uniodonto!$B$3:$F$339,5,0),0) -> 42.19 | J7: =IF(E7>=0,IF(AND(E7>tabelas!$C$4,E7<=tabelas!$C$5),I7*tabelas!$E$4,IF(AND(E7>=tabelas!$C$5,E7<=tabelas!$C$6),I7*tabelas!$E$5,IF(AND(E7>=tabelas!$C$6,E7<=tabelas!$C$7),I7*tabelas!$E$6,IF(AND(E7>0,E7>tabelas!$C$7),I7*tabelas!$E$7,0))))) -> 9.7037 | K7: =I7-J7 -> 32.4863 | L7: =SUMIF(caju!$A$4:$A$562,total!B7,caju!$C$4:$C$2900) -> 500 | M7: =IF(E7>=0,IF(AND(E7>tabelas!$C$11,E7<=tabelas!$C$12),L7*tabelas!$E$11,IF(AND(E7>=tabelas!$C$12,E7<=tabelas!$C$13),L7*tabelas!$E$12,IF(AND(E7>=tabelas!$C$13,E7<=tabelas!$C$14),L7*tabelas!$E$13,IF(AND(E7>0,E7>tabelas!$C$14),L7*tabelas!$E$14,0))))) -> 50 | N7: =L7-M7 -> 450 | O7: =IFERROR(VLOOKUP(B7,segurodevida!$B$4:$E$588,4,0),0) -> 24.55399 | P7: =O7/2 -> 12.276995 | Q7: =O7-P7 -> 12.276995 | V7: =IFERROR(VLOOKUP(B7,#REF!,3,0),0) -> 0 | W7: =SUMIF(#REF!,total!B7,#REF!) -> #REF! | X7: =IFERROR(VLOOKUP(B7,#REF!,4,0),0) -> 0 | Y7: =IFERROR(VLOOKUP(B7,#REF!,5,0),0) -> 0 | Z7: =IFERROR(X7-Y7,0) -> 0 | AA7: =IFERROR(VLOOKUP(B7,#REF!,3,0),0) -> 0 | AB7: =IFERROR(VLOOKUP(B7,#REF!,3,0),0) -> 0 | AC7: =IFERROR(VLOOKUP(B7,#REF!,5,0),0) -> 0 | AD7: 275 | AE7: =IFERROR(VLOOKUP(B7,#REF!,3,0),0) -> 0 | AF7: =IFERROR(VLOOKUP(B7,#REF!,3,0),0) -> 0 | AG7: =IFERROR(VLOOKUP(B7,#REF!,3,0),0) -> 0 | AK7: =IFERROR(VLOOKUP(B7,#REF!,3,0),0) -> 0 | AL7: =IFERROR(VLOOKUP(B7,ingles!$A$2:$C$673,3,0),"-") -> 165 | AM7: =ROUNDUP(IFERROR(AL7*39.39%,"0"),1) -> 65 | AN7: =IFERROR(AL7-AM7,"-") -> 100 | AO7: =SUMIFS(zenklub!I:I,zenklub!A:A,total!B7) -> 90.566667 | AP7: =SUMIF(zenklub!$A$49:$A$106,total!B7,zenklub!$I$49:$I$106) -> 23.9 | AQ7: =AO7-AP7 -> 66.666667 | AR7: =SUMIF([3]bradesco!$C:$C,B7,[3]bradesco!$M:$M) -> #VALUE! | AS7: =SUMIF([3]bradesco!$C:$C,B7,[3]bradesco!$V:$V) -> #VALUE! | AT7: =IFERROR(SUMIF([3]bradesco!$C:$C,B7,[3]bradesco!$Y:$Y),0) -> 0 | AU7: =SUMIF([4]bradesco!$C:$C,B7,[4]bradesco!$M:$M) -> #VALUE! | AV7: =SUMIF([4]bradesco!$C:$C,B7,[4]bradesco!$V:$V) -> #VALUE! | AW7: =AU7-AV7 -> #VALUE! | AX7: =IFERROR(VLOOKUP(B7,#REF!,3,0),0) -> 0 | AY7: =IFERROR(VLOOKUP(B7,#REF!,3,0),0) -> 0 | AZ7: =IFERROR(VLOOKUP(B7,#REF!,3,0),0) -> 0 | BA7: 0 | BB7: =IFERROR(VLOOKUP(B7,#REF!,3,0),0) -> 0 | BC7: =IF(E7>=0,IF(AND(E7>tabelas!$C$11,E7<=tabelas!$C$12),BB7*tabelas!$E$11,IF(AND(E7>=tabelas!$C$12,E7<=tabelas!$C$13),BB7*tabelas!$E$12,IF(AND(E7>=tabelas!$C$13,E7<=tabelas!$C$14),BB7*tabelas!$E$13,IF(AND(E7>0,E7>tabelas!$C$14),BB7*tabelas!$E$14,0))))) -> 0 | BD7: =BB7-BC7 -> 0 | BE7: =SUMIF(open_english!A:A,total!B7,open_english!C:C) -> 138.88889 | BF7: =SUMIF(open_english!A:A,total!B7,open_english!D:D) -> 96.56 | BG7: =SUMIF(open_english!A:A,total!B7,open_english!E:E) -> 42.328889 | BH7: =IFERROR(VLOOKUP(B7,gympass!$A$2:$F$527,6,0),"-") -> 166.66667 | BI7: =IFERROR(VLOOKUP(B7,#REF!,4,0),"-") -> - | BJ7: =IFERROR(VLOOKUP(B7,#REF!,3,0),0) -> 0 | BK7: =IF(E7>=0,IF(AND(E7>tabelas!$C$11,E7<=tabelas!$C$12),BJ7*tabelas!$E$11,IF(AND(E7>=tabelas!$C$12,E7<=tabelas!$C$13),BJ7*tabelas!$E$12,IF(AND(E7>=tabelas!$C$13,E7<=tabelas!$C$14),BJ7*tabelas!$E$13,IF(AND(E7>0,E7>tabelas!$C$14),BJ7*tabelas!$E$14,0))))) -> 0 | BL7: =BJ7-BK7 -> 0 | BM7: =IFERROR(INDEX(dif_sistel!L:L,MATCH(total!B7,dif_sistel!D:D,0)),0)+IFERROR(INDEX(dif_sistel!N:N,MATCH(total!B7,dif_sistel!D:D,0)),0) -> 0 | BN7: =IFERROR(VLOOKUP(B7,dif_sistel!$D$3:$X$257,21,0),0) -> 0 | BO7: =IFERROR(SUMIF(#REF!,total!B7,#REF!),"0") -> 0 | BP7: =IFERROR(SUMIF(#REF!,total!B7,#REF!),"0") -> 0
B8: 5 | C8: =VLOOKUP(B8,salario!$A$3:$C$195,2,0) -> ATIVO | D8: =VLOOKUP(B8,salario!$A$3:$C$195,3,0) -> Colaborador 5 | E8: =IFERROR(VLOOKUP(B8,salario!$A$3:$K$854,11,0), "0") -> 3652.6 | F8: =SUMIF([2]unimed!$AL:$AL,B8,[2]unimed!$AJ:$AJ) -> #VALUE! | G8: =SUMIF([2]unimed!$AL:$AL,B8,[2]unimed!$AQ:$AQ) -> #VALUE! | H8: =SUMIF([2]unimed!$AL:$AL,B8,[2]unimed!$AP:$AP) -> #VALUE! | I8: =IFERROR(VLOOKUP(B8,uniodonto!$B$3:$F$339,5,0),0) -> 253.14 | J8: =IF(E8>=0,IF(AND(E8>tabelas!$C$4,E8<=tabelas!$C$5),I8*tabelas!$E$4,IF(AND(E8>=tabelas!$C$5,E8<=tabelas!$C$6),I8*tabelas!$E$5,IF(AND(E8>=tabelas!$C$6,E8<=tabelas!$C$7),I8*tabelas!$E$6,IF(AND(E8>0,E8>tabelas!$C$7),I8*tabelas!$E$7,0))))) -> 17.7198 | K8: =I8-J8 -> 235.4202 | L8: =SUMIF(caju!$A$4:$A$562,total!B8,caju!$C$4:$C$2900) -> 500 | M8: =IF(E8>=0,IF(AND(E8>tabelas!$C$11,E8<=tabelas!$C$12),L8*tabelas!$E$11,IF(AND(E8>=tabelas!$C$12,E8<=tabelas!$C$13),L8*tabelas!$E$12,IF(AND(E8>=tabelas!$C$13,E8<=tabelas!$C$14),L8*tabelas!$E$13,IF(AND(E8>0,E8>tabelas!$C$14),L8*tabelas!$E$14,0))))) -> 10 | N8: =L8-M8 -> 490 | O8: =IFERROR(VLOOKUP(B8,segurodevida!$B$4:$E$588,4,0),0) -> 11.670057 | P8: =O8/2 -> 5.8350285 | Q8: =O8-P8 -> 5.8350285 | V8: =IFERROR(VLOOKUP(B8,#REF!,3,0),0) -> 0 | W8: =SUMIF(#REF!,total!B8,#REF!) -> #REF! | X8: =IFERROR(VLOOKUP(B8,#REF!,4,0),0) -> 0 | Y8: =IFERROR(VLOOKUP(B8,#REF!,5,0),0) -> 0 | Z8: =IFERROR(X8-Y8,0) -> 0 | AA8: =IFERROR(VLOOKUP(B8,#REF!,3,0),0) -> 0 | AB8: =IFERROR(VLOOKUP(B8,#REF!,3,0),0) -> 0 | AC8: =IFERROR(VLOOKUP(B8,#REF!,5,0),0) -> 0 | AD8: 275 | AE8: =IFERROR(VLOOKUP(B8,#REF!,3,0),0) -> 0 | AF8: =IFERROR(VLOOKUP(B8,#REF!,3,0),0) -> 0 | AG8: =IFERROR(VLOOKUP(B8,#REF!,3,0),0) -> 0 | AK8: =IFERROR(VLOOKUP(B8,#REF!,3,0),0) -> 0 | AL8: =IFERROR(VLOOKUP(B8,ingles!$A$2:$C$673,3,0),"-") -> 165 | AM8: =ROUNDUP(IFERROR(AL8*39.39%,"0"),1) -> 65 | AN8: =IFERROR(AL8-AM8,"-") -> 100 | AO8: =SUMIFS(zenklub!I:I,zenklub!A:A,total!B8) -> 90.566667 | AP8: =SUMIF(zenklub!$A$49:$A$106,total!B8,zenklub!$I$49:$I$106) -> 23.9 | AQ8: =AO8-AP8 -> 66.666667 | AR8: =SUMIF([3]bradesco!$C:$C,B8,[3]bradesco!$M:$M) -> #VALUE! | AS8: =SUMIF([3]bradesco!$C:$C,B8,[3]bradesco!$V:$V) -> #VALUE! | AT8: =IFERROR(SUMIF([3]bradesco!$C:$C,B8,[3]bradesco!$Y:$Y),0) -> 0 | AU8: =SUMIF([4]bradesco!$C:$C,B8,[4]bradesco!$M:$M) -> #VALUE! | AV8: =SUMIF([4]bradesco!$C:$C,B8,[4]bradesco!$V:$V) -> #VALUE! | AW8: =AU8-AV8 -> #VALUE! | AX8: =IFERROR(VLOOKUP(B8,#REF!,3,0),0) -> 0 | AY8: =IFERROR(VLOOKUP(B8,#REF!,3,0),0) -> 0 | AZ8: =IFERROR(VLOOKUP(B8,#REF!,3,0),0) -> 0 | BA8: 0 | BB8: =IFERROR(VLOOKUP(B8,#REF!,3,0),0) -> 0 | BC8: =IF(E8>=0,IF(AND(E8>tabelas!$C$11,E8<=tabelas!$C$12),BB8*tabelas!$E$11,IF(AND(E8>=tabelas!$C$12,E8<=tabelas!$C$13),BB8*tabelas!$E$12,IF(AND(E8>=tabelas!$C$13,E8<=tabelas!$C$14),BB8*tabelas!$E$13,IF(AND(E8>0,E8>tabelas!$C$14),BB8*tabelas!$E$14,0))))) -> 0 | BD8: =BB8-BC8 -> 0 | BE8: =SUMIF(open_english!A:A,total!B8,open_english!C:C) -> 138.88889 | BF8: =SUMIF(open_english!A:A,total!B8,open_english!D:D) -> 96.56 | BG8: =SUMIF(open_english!A:A,total!B8,open_english!E:E) -> 42.328889 | BH8: =IFERROR(VLOOKUP(B8,gympass!$A$2:$F$527,6,0),"-") -> 166.66667 | BI8: =IFERROR(VLOOKUP(B8,#REF!,4,0),"-") -> - | BJ8: =IFERROR(VLOOKUP(B8,#REF!,3,0),0) -> 0 | BK8: =IF(E8>=0,IF(AND(E8>tabelas!$C$11,E8<=tabelas!$C$12),BJ8*tabelas!$E$11,IF(AND(E8>=tabelas!$C$12,E8<=tabelas!$C$13),BJ8*tabelas!$E$12,IF(AND(E8>=tabelas!$C$13,E8<=tabelas!$C$14),BJ8*tabelas!$E$13,IF(AND(E8>0,E8>tabelas!$C$14),BJ8*tabelas!$E$14,0))))) -> 0 | BL8: =BJ8-BK8 -> 0 | BM8: =IFERROR(INDEX(dif_sistel!L:L,MATCH(total!B8,dif_sistel!D:D,0)),0)+IFERROR(INDEX(dif_sistel!N:N,MATCH(total!B8,dif_sistel!D:D,0)),0) -> 0 | BN8: =IFERROR(VLOOKUP(B8,dif_sistel!$D$3:$X$257,21,0),0) -> 0 | BO8: =IFERROR(SUMIF(#REF!,total!B8,#REF!),"0") -> 0 | BP8: =IFERROR(SUMIF(#REF!,total!B8,#REF!),"0") -> 0
B9: 6 | C9: =VLOOKUP(B9,salario!$A$3:$C$195,2,0) -> ATIVO | D9: =VLOOKUP(B9,salario!$A$3:$C$195,3,0) -> Colaborador 6 | E9: =IFERROR(VLOOKUP(B9,salario!$A$3:$K$854,11,0), "0") -> 7943.86 | F9: =SUMIF([2]unimed!$AL:$AL,B9,[2]unimed!$AJ:$AJ) -> #VALUE! | G9: =SUMIF([2]unimed!$AL:$AL,B9,[2]unimed!$AQ:$AQ) -> #VALUE! | H9: =SUMIF([2]unimed!$AL:$AL,B9,[2]unimed!$AP:$AP) -> #VALUE! | I9: =IFERROR(VLOOKUP(B9,uniodonto!$B$3:$F$339,5,0),0) -> 168.76 | J9: =IF(E9>=0,IF(AND(E9>tabelas!$C$4,E9<=tabelas!$C$5),I9*tabelas!$E$4,IF(AND(E9>=tabelas!$C$5,E9<=tabelas!$C$6),I9*tabelas!$E$5,IF(AND(E9>=tabelas!$C$6,E9<=tabelas!$C$7),I9*tabelas!$E$6,IF(AND(E9>0,E9>tabelas!$C$7),I9*tabelas!$E$7,0))))) -> 38.8148 | K9: =I9-J9 -> 129.9452 | L9: =SUMIF(caju!$A$4:$A$562,total!B9,caju!$C$4:$C$2900) -> 500 | M9: =IF(E9>=0,IF(AND(E9>tabelas!$C$11,E9<=tabelas!$C$12),L9*tabelas!$E$11,IF(AND(E9>=tabelas!$C$12,E9<=tabelas!$C$13),L9*tabelas!$E$12,IF(AND(E9>=tabelas!$C$13,E9<=tabelas!$C$14),L9*tabelas!$E$13,IF(AND(E9>0,E9>tabelas!$C$14),L9*tabelas!$E$14,0))))) -> 50 | N9: =L9-M9 -> 450 | O9: =IFERROR(VLOOKUP(B9,segurodevida!$B$4:$E$588,4,0),0) -> 25.380633 | P9: =O9/2 -> 12.690316 | Q9: =O9-P9 -> 12.690316 | V9: =IFERROR(VLOOKUP(B9,#REF!,3,0),0) -> 0 | W9: =SUMIF(#REF!,total!B9,#REF!) -> #REF! | X9: =IFERROR(VLOOKUP(B9,#REF!,4,0),0) -> 0 | Y9: =IFERROR(VLOOKUP(B9,#REF!,5,0),0) -> 0 | Z9: =IFERROR(X9-Y9,0) -> 0 | AA9: =IFERROR(VLOOKUP(B9,#REF!,3,0),0) -> 0 | AB9: =IFERROR(VLOOKUP(B9,#REF!,3,0),0) -> 0 | AC9: =IFERROR(VLOOKUP(B9,#REF!,5,0),0) -> 0 | AD9: 275 | AE9: =IFERROR(VLOOKUP(B9,#REF!,3,0),0) -> 0 | AF9: =IFERROR(VLOOKUP(B9,#REF!,3,0),0) -> 0 | AG9: =IFERROR(VLOOKUP(B9,#REF!,3,0),0) -> 0 | AK9: =IFERROR(VLOOKUP(B9,#REF!,3,0),0) -> 0 | AL9: =IFERROR(VLOOKUP(B9,ingles!$A$2:$C$673,3,0),"-") -> 165 | AM9: =ROUNDUP(IFERROR(AL9*39.39%,"0"),1) -> 65 | AN9: =IFERROR(AL9-AM9,"-") -> 100 | AO9: =SUMIFS(zenklub!I:I,zenklub!A:A,total!B9) -> 90.566667 | AP9: =SUMIF(zenklub!$A$49:$A$106,total!B9,zenklub!$I$49:$I$106) -> 23.9 | AQ9: =AO9-AP9 -> 66.666667 | AR9: =SUMIF([3]bradesco!$C:$C,B9,[3]bradesco!$M:$M) -> #VALUE! | AS9: =SUMIF([3]bradesco!$C:$C,B9,[3]bradesco!$V:$V) -> #VALUE! | AT9: =IFERROR(SUMIF([3]bradesco!$C:$C,B9,[3]bradesco!$Y:$Y),0) -> 0 | AU9: =SUMIF([4]bradesco!$C:$C,B9,[4]bradesco!$M:$M) -> #VALUE! | AV9: =SUMIF([4]bradesco!$C:$C,B9,[4]bradesco!$V:$V) -> #VALUE! | AW9: =AU9-AV9 -> #VALUE! | AX9: =IFERROR(VLOOKUP(B9,#REF!,3,0),0) -> 0 | AY9: =IFERROR(VLOOKUP(B9,#REF!,3,0),0) -> 0 | AZ9: =IFERROR(VLOOKUP(B9,#REF!,3,0),0) -> 0 | BA9: 0 | BB9: =IFERROR(VLOOKUP(B9,#REF!,3,0),0) -> 0 | BC9: =IF(E9>=0,IF(AND(E9>tabelas!$C$11,E9<=tabelas!$C$12),BB9*tabelas!$E$11,IF(AND(E9>=tabelas!$C$12,E9<=tabelas!$C$13),BB9*tabelas!$E$12,IF(AND(E9>=tabelas!$C$13,E9<=tabelas!$C$14),BB9*tabelas!$E$13,IF(AND(E9>0,E9>tabelas!$C$14),BB9*tabelas!$E$14,0))))) -> 0 | BD9: =BB9-BC9 -> 0 | BE9: =SUMIF(open_english!A:A,total!B9,open_english!C:C) -> 138.88889 | BF9: =SUMIF(open_english!A:A,total!B9,open_english!D:D) -> 96.56 | BG9: =SUMIF(open_english!A:A,total!B9,open_english!E:E) -> 42.328889 | BH9: =IFERROR(VLOOKUP(B9,gympass!$A$2:$F$527,6,0),"-") -> 166.66667 | BI9: =IFERROR(VLOOKUP(B9,#REF!,4,0),"-") -> - | BJ9: =IFERROR(VLOOKUP(B9,#REF!,3,0),0) -> 0 | BK9: =IF(E9>=0,IF(AND(E9>tabelas!$C$11,E9<=tabelas!$C$12),BJ9*tabelas!$E$11,IF(AND(E9>=tabelas!$C$12,E9<=tabelas!$C$13),BJ9*tabelas!$E$12,IF(AND(E9>=tabelas!$C$13,E9<=tabelas!$C$14),BJ9*tabelas!$E$13,IF(AND(E9>0,E9>tabelas!$C$14),BJ9*tabelas!$E$14,0))))) -> 0 | BL9: =BJ9-BK9 -> 0 | BM9: =IFERROR(INDEX(dif_sistel!L:L,MATCH(total!B9,dif_sistel!D:D,0)),0)+IFERROR(INDEX(dif_sistel!N:N,MATCH(total!B9,dif_sistel!D:D,0)),0) -> 0 | BN9: =IFERROR(VLOOKUP(B9,dif_sistel!$D$3:$X$257,21,0),0) -> 0 | BO9: =IFERROR(SUMIF(#REF!,total!B9,#REF!),"0") -> 0 | BP9: =IFERROR(SUMIF(#REF!,total!B9,#REF!),"0") -> 0
B10: 7 | C10: =VLOOKUP(B10,salario!$A$3:$C$195,2,0) -> ATIVO | D10: =VLOOKUP(B10,salario!$A$3:$C$195,3,0) -> Colaborador 7 | E10: =IFERROR(VLOOKUP(B10,salario!$A$3:$K$854,11,0), "0") -> 7131.14 | F10: =SUMIF([2]unimed!$AL:$AL,B10,[2]unimed!$AJ:$AJ) -> #VALUE! | G10: =SUMIF([2]unimed!$AL:$AL,B10,[2]unimed!$AQ:$AQ) -> #VALUE! | H10: =SUMIF([2]unimed!$AL:$AL,B10,[2]unimed!$AP:$AP) -> #VALUE! | I10: =IFERROR(VLOOKUP(B10,uniodonto!$B$3:$F$339,5,0),0) -> 168.76 | J10: =IF(E10>=0,IF(AND(E10>tabelas!$C$4,E10<=tabelas!$C$5),I10*tabelas!$E$4,IF(AND(E10>=tabelas!$C$5,E10<=tabelas!$C$6),I10*tabelas!$E$5,IF(AND(E10>=tabelas!$C$6,E10<=tabelas!$C$7),I10*tabelas!$E$6,IF(AND(E10>0,E10>tabelas!$C$7),I10*tabelas!$E$7,0))))) -> 25.314 | K10: =I10-J10 -> 143.446 | L10: =SUMIF(caju!$A$4:$A$562,total!B10,caju!$C$4:$C$2900) -> 500 | M10: =IF(E10>=0,IF(AND(E10>tabelas!$C$11,E10<=tabelas!$C$12),L10*tabelas!$E$11,IF(AND(E10>=tabelas!$C$12,E10<=tabelas!$C$13),L10*tabelas!$E$12,IF(AND(E10>=tabelas!$C$13,E10<=tabelas!$C$14),L10*tabelas!$E$13,IF(AND(E10>0,E10>tabelas!$C$14),L10*tabelas!$E$14,0))))) -> 30 | N10: =L10-M10 -> 470 | O10: =IFERROR(VLOOKUP(B10,segurodevida!$B$4:$E$588,4,0),0) -> 22.783992 | P10: =O10/2 -> 11.391996 | Q10: =O10-P10 -> 11.391996 | V10: =IFERROR(VLOOKUP(B10,#REF!,3,0),0) -> 0 | W10: =SUMIF(#REF!,total!B10,#REF!) -> #REF! | X10: =IFERROR(VLOOKUP(B10,#REF!,4,0),0) -> 0 | Y10: =IFERROR(VLOOKUP(B10,#REF!,5,0),0) -> 0 | Z10: =IFERROR(X10-Y10,0) -> 0 | AA10: =IFERROR(VLOOKUP(B10,#REF!,3,0),0) -> 0 | AB10: =IFERROR(VLOOKUP(B10,#REF!,3,0),0) -> 0 | AC10: =IFERROR(VLOOKUP(B10,#REF!,5,0),0) -> 0 | AD10: 275 | AE10: =IFERROR(VLOOKUP(B10,#REF!,3,0),0) -> 0 | AF10: =IFERROR(VLOOKUP(B10,#REF!,3,0),0) -> 0 | AG10: =IFERROR(VLOOKUP(B10,#REF!,3,0),0) -> 0 | AK10: =IFERROR(VLOOKUP(B10,#REF!,3,0),0) -> 0 | AL10: =IFERROR(VLOOKUP(B10,ingles!$A$2:$C$673,3,0),"-") -> 165 | AM10: =ROUNDUP(IFERROR(AL10*39.39%,"0"),1) -> 65 | AN10: =IFERROR(AL10-AM10,"-") -> 100 | AO10: =SUMIFS(zenklub!I:I,zenklub!A:A,total!B10) -> 90.566667 | AP10: =SUMIF(zenklub!$A$49:$A$106,total!B10,zenklub!$I$49:$I$106) -> 23.9 | AQ10: =AO10-AP10 -> 66.666667 | AR10: =SUMIF([3]bradesco!$C:$C,B10,[3]bradesco!$M:$M) -> #VALUE! | AS10: =SUMIF([3]bradesco!$C:$C,B10,[3]bradesco!$V:$V) -> #VALUE! | AT10: =IFERROR(SUMIF([3]bradesco!$C:$C,B10,[3]bradesco!$Y:$Y),0) -> 0 | AU10: =SUMIF([4]bradesco!$C:$C,B10,[4]bradesco!$M:$M) -> #VALUE! | AV10: =SUMIF([4]bradesco!$C:$C,B10,[4]bradesco!$V:$V) -> #VALUE! | AW10: =AU10-AV10 -> #VALUE! | AX10: =IFERROR(VLOOKUP(B10,#REF!,3,0),0) -> 0 | AY10: =IFERROR(VLOOKUP(B10,#REF!,3,0),0) -> 0 | AZ10: =IFERROR(VLOOKUP(B10,#REF!,3,0),0) -> 0 | BA10: 0 | BB10: =IFERROR(VLOOKUP(B10,#REF!,3,0),0) -> 0 | BC10: =IF(E10>=0,IF(AND(E10>tabelas!$C$11,E10<=tabelas!$C$12),BB10*tabelas!$E$11,IF(AND(E10>=tabelas!$C$12,E10<=tabelas!$C$13),BB10*tabelas!$E$12,IF(AND(E10>=tabelas!$C$13,E10<=tabelas!$C$14),BB10*tabelas!$E$13,IF(AND(E10>0,E10>tabelas!$C$14),BB10*tabelas!$E$14,0))))) -> 0 | BD10: =BB10-BC10 -> 0 | BE10: =SUMIF(open_english!A:A,total!B10,open_english!C:C) -> 138.88889 | BF10: =SUMIF(open_english!A:A,total!B10,open_english!D:D) -> 96.56 | BG10: =SUMIF(open_english!A:A,total!B10,open_english!E:E) -> 42.328889 | BH10: =IFERROR(VLOOKUP(B10,gympass!$A$2:$F$527,6,0),"-") -> 166.66667 | BI10: =IFERROR(VLOOKUP(B10,#REF!,4,0),"-") -> - | BJ10: =IFERROR(VLOOKUP(B10,#REF!,3,0),0) -> 0 | BK10: =IF(E10>=0,IF(AND(E10>tabelas!$C$11,E10<=tabelas!$C$12),BJ10*tabelas!$E$11,IF(AND(E10>=tabelas!$C$12,E10<=tabelas!$C$13),BJ10*tabelas!$E$12,IF(AND(E10>=tabelas!$C$13,E10<=tabelas!$C$14),BJ10*tabelas!$E$13,IF(AND(E10>0,E10>tabelas!$C$14),BJ10*tabelas!$E$14,0))))) -> 0 | BL10: =BJ10-BK10 -> 0 | BM10: =IFERROR(INDEX(dif_sistel!L:L,MATCH(total!B10,dif_sistel!D:D,0)),0)+IFERROR(INDEX(dif_sistel!N:N,MATCH(total!B10,dif_sistel!D:D,0)),0) -> 0 | BN10: =IFERROR(VLOOKUP(B10,dif_sistel!$D$3:$X$257,21,0),0) -> 0 | BO10: =IFERROR(SUMIF(#REF!,total!B10,#REF!),"0") -> 0 | BP10: =IFERROR(SUMIF(#REF!,total!B10,#REF!),"0") -> 0
B11: 8 | C11: =VLOOKUP(B11,salario!$A$3:$C$195,2,0) -> ATIVO | D11: =VLOOKUP(B11,salario!$A$3:$C$195,3,0) -> Colaborador 8 | E11: =IFERROR(VLOOKUP(B11,salario!$A$3:$K$854,11,0), "0") -> 5245.5 | F11: =SUMIF([2]unimed!$AL:$AL,B11,[2]unimed!$AJ:$AJ) -> #VALUE! | G11: =SUMIF([2]unimed!$AL:$AL,B11,[2]unimed!$AQ:$AQ) -> #VALUE! | H11: =SUMIF([2]unimed!$AL:$AL,B11,[2]unimed!$AP:$AP) -> #VALUE! | I11: =IFERROR(VLOOKUP(B11,uniodonto!$B$3:$F$339,5,0),0) -> 168.76 | J11: =IF(E11>=0,IF(AND(E11>tabelas!$C$4,E11<=tabelas!$C$5),I11*tabelas!$E$4,IF(AND(E11>=tabelas!$C$5,E11<=tabelas!$C$6),I11*tabelas!$E$5,IF(AND(E11>=tabelas!$C$6,E11<=tabelas!$C$7),I11*tabelas!$E$6,IF(AND(E11>0,E11>tabelas!$C$7),I11*tabelas!$E$7,0))))) -> 25.314 | K11: =I11-J11 -> 143.446 | L11: =SUMIF(caju!$A$4:$A$562,total!B11,caju!$C$4:$C$2900) -> 500 | M11: =IF(E11>=0,IF(AND(E11>tabelas!$C$11,E11<=tabelas!$C$12),L11*tabelas!$E$11,IF(AND(E11>=tabelas!$C$12,E11<=tabelas!$C$13),L11*tabelas!$E$12,IF(AND(E11>=tabelas!$C$13,E11<=tabelas!$C$14),L11*tabelas!$E$13,IF(AND(E11>0,E11>tabelas!$C$14),L11*tabelas!$E$14,0))))) -> 30 | N11: =L11-M11 -> 470 | O11: =IFERROR(VLOOKUP(B11,segurodevida!$B$4:$E$588,4,0),0) -> 16.759373 | P11: =O11/2 -> 8.3796863 | Q11: =O11-P11 -> 8.3796863 | V11: =IFERROR(VLOOKUP(B11,#REF!,3,0),0) -> 0 | W11: =SUMIF(#REF!,total!B11,#REF!) -> #REF! | X11: =IFERROR(VLOOKUP(B11,#REF!,4,0),0) -> 0 | Y11: =IFERROR(VLOOKUP(B11,#REF!,5,0),0) -> 0 | Z11: =IFERROR(X11-Y11,0) -> 0 | AA11: =IFERROR(VLOOKUP(B11,#REF!,3,0),0) -> 0 | AB11: =IFERROR(VLOOKUP(B11,#REF!,3,0),0) -> 0 | AC11: =IFERROR(VLOOKUP(B11,#REF!,5,0),0) -> 0 | AD11: 275 | AE11: =IFERROR(VLOOKUP(B11,#REF!,3,0),0) -> 0 | AF11: =IFERROR(VLOOKUP(B11,#REF!,3,0),0) -> 0 | AG11: =IFERROR(VLOOKUP(B11,#REF!,3,0),0) -> 0 | AK11: =IFERROR(VLOOKUP(B11,#REF!,3,0),0) -> 0 | AL11: =IFERROR(VLOOKUP(B11,ingles!$A$2:$C$673,3,0),"-") -> 165 | AM11: =ROUNDUP(IFERROR(AL11*39.39%,"0"),1) -> 65 | AN11: =IFERROR(AL11-AM11,"-") -> 100 | AO11: =SUMIFS(zenklub!I:I,zenklub!A:A,total!B11) -> 90.566667 | AP11: =SUMIF(zenklub!$A$49:$A$106,total!B11,zenklub!$I$49:$I$106) -> 23.9 | AQ11: =AO11-AP11 -> 66.666667 | AR11: =SUMIF([3]bradesco!$C:$C,B11,[3]bradesco!$M:$M) -> #VALUE! | AS11: =SUMIF([3]bradesco!$C:$C,B11,[3]bradesco!$V:$V) -> #VALUE! | AT11: =IFERROR(SUMIF([3]bradesco!$C:$C,B11,[3]bradesco!$Y:$Y),0) -> 0 | AU11: =SUMIF([4]bradesco!$C:$C,B11,[4]bradesco!$M:$M) -> #VALUE! | AV11: =SUMIF([4]bradesco!$C:$C,B11,[4]bradesco!$V:$V) -> #VALUE! | AW11: =AU11-AV11 -> #VALUE! | AX11: =IFERROR(VLOOKUP(B11,#REF!,3,0),0) -> 0 | AY11: =IFERROR(VLOOKUP(B11,#REF!,3,0),0) -> 0 | AZ11: =IFERROR(VLOOKUP(B11,#REF!,3,0),0) -> 0 | BA11: 0 | BB11: =IFERROR(VLOOKUP(B11,#REF!,3,0),0) -> 0 | BC11: =IF(E11>=0,IF(AND(E11>tabelas!$C$11,E11<=tabelas!$C$12),BB11*tabelas!$E$11,IF(AND(E11>=tabelas!$C$12,E11<=tabelas!$C$13),BB11*tabelas!$E$12,IF(AND(E11>=tabelas!$C$13,E11<=tabelas!$C$14),BB11*tabelas!$E$13,IF(AND(E11>0,E11>tabelas!$C$14),BB11*tabelas!$E$14,0))))) -> 0 | BD11: =BB11-BC11 -> 0 | BE11: =SUMIF(open_english!A:A,total!B11,open_english!C:C) -> 138.88889 | BF11: =SUMIF(open_english!A:A,total!B11,open_english!D:D) -> 96.56 | BG11: =SUMIF(open_english!A:A,total!B11,open_english!E:E) -> 42.328889 | BH11: =IFERROR(VLOOKUP(B11,gympass!$A$2:$F$527,6,0),"-") -> 166.66667 | BI11: =IFERROR(VLOOKUP(B11,#REF!,4,0),"-") -> - | BJ11: =IFERROR(VLOOKUP(B11,#REF!,3,0),0) -> 0 | BK11: =IF(E11>=0,IF(AND(E11>tabelas!$C$11,E11<=tabelas!$C$12),BJ11*tabelas!$E$11,IF(AND(E11>=tabelas!$C$12,E11<=tabelas!$C$13),BJ11*tabelas!$E$12,IF(AND(E11>=tabelas!$C$13,E11<=tabelas!$C$14),BJ11*tabelas!$E$13,IF(AND(E11>0,E11>tabelas!$C$14),BJ11*tabelas!$E$14,0))))) -> 0 | BL11: =BJ11-BK11 -> 0 | BM11: =IFERROR(INDEX(dif_sistel!L:L,MATCH(total!B11,dif_sistel!D:D,0)),0)+IFERROR(INDEX(dif_sistel!N:N,MATCH(total!B11,dif_sistel!D:D,0)),0) -> 0 | BN11: =IFERROR(VLOOKUP(B11,dif_sistel!$D$3:$X$257,21,0),0) -> 0 | BO11: =IFERROR(SUMIF(#REF!,total!B11,#REF!),"0") -> 0 | BP11: =IFERROR(SUMIF(#REF!,total!B11,#REF!),"0") -> 0
B12: 9 | C12: =VLOOKUP(B12,salario!$A$3:$C$195,2,0) -> ATIVO | D12: =VLOOKUP(B12,salario!$A$3:$C$195,3,0) -> Colaborador 9 | E12: =IFERROR(VLOOKUP(B12,salario!$A$3:$K$854,11,0), "0") -> 4229.32 | F12: =SUMIF([2]unimed!$AL:$AL,B12,[2]unimed!$AJ:$AJ) -> #VALUE! | G12: =SUMIF([2]unimed!$AL:$AL,B12,[2]unimed!$AQ:$AQ) -> #VALUE! | H12: =SUMIF([2]unimed!$AL:$AL,B12,[2]unimed!$AP:$AP) -> #VALUE! | I12: =IFERROR(VLOOKUP(B12,uniodonto!$B$3:$F$339,5,0),0) -> 126.57 | J12: =IF(E12>=0,IF(AND(E12>tabelas!$C$4,E12<=tabelas!$C$5),I12*tabelas!$E$4,IF(AND(E12>=tabelas!$C$5,E12<=tabelas!$C$6),I12*tabelas!$E$5,IF(AND(E12>=tabelas!$C$6,E12<=tabelas!$C$7),I12*tabelas!$E$6,IF(AND(E12>0,E12>tabelas!$C$7),I12*tabelas!$E$7,0))))) -> 18.9855 | K12: =I12-J12 -> 107.5845 | L12: =SUMIF(caju!$A$4:$A$562,total!B12,caju!$C$4:$C$2900) -> 500 | M12: =IF(E12>=0,IF(AND(E12>tabelas!$C$11,E12<=tabelas!$C$12),L12*tabelas!$E$11,IF(AND(E12>=tabelas!$C$12,E12<=tabelas!$C$13),L12*tabelas!$E$12,IF(AND(E12>=tabelas!$C$13,E12<=tabelas!$C$14),L12*tabelas!$E$13,IF(AND(E12>0,E12>tabelas!$C$14),L12*tabelas!$E$14,0))))) -> 30 | N12: =L12-M12 -> 470 | O12: =IFERROR(VLOOKUP(B12,segurodevida!$B$4:$E$588,4,0),0) -> 13.512677 | P12: =O12/2 -> 6.7563387 | Q12: =O12-P12 -> 6.7563387 | V12: =IFERROR(VLOOKUP(B12,#REF!,3,0),0) -> 0 | W12: =SUMIF(#REF!,total!B12,#REF!) -> #REF! | X12: =IFERROR(VLOOKUP(B12,#REF!,4,0),0) -> 0 | Y12: =IFERROR(VLOOKUP(B12,#REF!,5,0),0) -> 0 | Z12: =IFERROR(X12-Y12,0) -> 0 | AA12: =IFERROR(VLOOKUP(B12,#REF!,3,0),0) -> 0 | AB12: =IFERROR(VLOOKUP(B12,#REF!,3,0),0) -> 0 | AC12: =IFERROR(VLOOKUP(B12,#REF!,5,0),0) -> 0 | AD12: 275 | AE12: =IFERROR(VLOOKUP(B12,#REF!,3,0),0) -> 0 | AF12: =IFERROR(VLOOKUP(B12,#REF!,3,0),0) -> 0 | AG12: =IFERROR(VLOOKUP(B12,#REF!,3,0),0) -> 0 | AK12: =IFERROR(VLOOKUP(B12,#REF!,3,0),0) -> 0 | AL12: =IFERROR(VLOOKUP(B12,ingles!$A$2:$C$673,3,0),"-") -> - | AM12: =ROUNDUP(IFERROR(AL12*39.39%,"0"),1) -> 0 | AN12: =IFERROR(AL12-AM12,"-") -> - | AO12: =SUMIFS(zenklub!I:I,zenklub!A:A,total!B12) -> 90.566667 | AP12: =SUMIF(zenklub!$A$49:$A$106,total!B12,zenklub!$I$49:$I$106) -> 23.9 | AQ12: =AO12-AP12 -> 66.666667 | AR12: =SUMIF([3]bradesco!$C:$C,B12,[3]bradesco!$M:$M) -> #VALUE! | AS12: =SUMIF([3]bradesco!$C:$C,B12,[3]bradesco!$V:$V) -> #VALUE! | AT12: =IFERROR(SUMIF([3]bradesco!$C:$C,B12,[3]bradesco!$Y:$Y),0) -> 0 | AU12: =SUMIF([4]bradesco!$C:$C,B12,[4]bradesco!$M:$M) -> #VALUE! | AV12: =SUMIF([4]bradesco!$C:$C,B12,[4]bradesco!$V:$V) -> #VALUE! | AW12: =AU12-AV12 -> #VALUE! | AX12: =IFERROR(VLOOKUP(B12,#REF!,3,0),0) -> 0 | AY12: =IFERROR(VLOOKUP(B12,#REF!,3,0),0) -> 0 | AZ12: =IFERROR(VLOOKUP(B12,#REF!,3,0),0) -> 0 | BA12: 0 | BB12: =IFERROR(VLOOKUP(B12,#REF!,3,0),0) -> 0 | BC12: =IF(E12>=0,IF(AND(E12>tabelas!$C$11,E12<=tabelas!$C$12),BB12*tabelas!$E$11,IF(AND(E12>=tabelas!$C$12,E12<=tabelas!$C$13),BB12*tabelas!$E$12,IF(AND(E12>=tabelas!$C$13,E12<=tabelas!$C$14),BB12*tabelas!$E$13,IF(AND(E12>0,E12>tabelas!$C$14),BB12*tabelas!$E$14,0))))) -> 0 | BD12: =BB12-BC12 -> 0 | BE12: =SUMIF(open_english!A:A,total!B12,open_english!C:C) -> 138.88889 | BF12: =SUMIF(open_english!A:A,total!B12,open_english!D:D) -> 96.56 | BG12: =SUMIF(open_english!A:A,total!B12,open_english!E:E) -> 42.328889 | BH12: =IFERROR(VLOOKUP(B12,gympass!$A$2:$F$527,6,0),"-") -> 166.66667 | BI12: =IFERROR(VLOOKUP(B12,#REF!,4,0),"-") -> - | BJ12: =IFERROR(VLOOKUP(B12,#REF!,3,0),0) -> 0 | BK12: =IF(E12>=0,IF(AND(E12>tabelas!$C$11,E12<=tabelas!$C$12),BJ12*tabelas!$E$11,IF(AND(E12>=tabelas!$C$12,E12<=tabelas!$C$13),BJ12*tabelas!$E$12,IF(AND(E12>=tabelas!$C$13,E12<=tabelas!$C$14),BJ12*tabelas!$E$13,IF(AND(E12>0,E12>tabelas!$C$14),BJ12*tabelas!$E$14,0))))) -> 0 | BL12: =BJ12-BK12 -> 0 | BM12: =IFERROR(INDEX(dif_sistel!L:L,MATCH(total!B12,dif_sistel!D:D,0)),0)+IFERROR(INDEX(dif_sistel!N:N,MATCH(total!B12,dif_sistel!D:D,0)),0) -> 0 | BN12: =IFERROR(VLOOKUP(B12,dif_sistel!$D$3:$X$257,21,0),0) -> 0 | BO12: =IFERROR(SUMIF(#REF!,total!B12,#REF!),"0") -> 0 | BP12: =IFERROR(SUMIF(#REF!,total!B12,#REF!),"0") -> 0
B13: 10 | C13: =VLOOKUP(B13,salario!$A$3:$C$195,2,0) -> ATIVO | D13: =VLOOKUP(B13,salario!$A$3:$C$195,3,0) -> Colaborador 10 | E13: =IFERROR(VLOOKUP(B13,salario!$A$3:$K$854,11,0), "0") -> 2404.84 | F13: =SUMIF([2]unimed!$AL:$AL,B13,[2]unimed!$AJ:$AJ) -> #VALUE! | G13: =SUMIF([2]unimed!$AL:$AL,B13,[2]unimed!$AQ:$AQ) -> #VALUE! | H13: =SUMIF([2]unimed!$AL:$AL,B13,[2]unimed!$AP:$AP) -> #VALUE! | I13: =IFERROR(VLOOKUP(B13,uniodonto!$B$3:$F$339,5,0),0) -> 126.57 | J13: =IF(E13>=0,IF(AND(E13>tabelas!$C$4,E13<=tabelas!$C$5),I13*tabelas!$E$4,IF(AND(E13>=tabelas!$C$5,E13<=tabelas!$C$6),I13*tabelas!$E$5,IF(AND(E13>=tabelas!$C$6,E13<=tabelas!$C$7),I13*tabelas!$E$6,IF(AND(E13>0,E13>tabelas!$C$7),I13*tabelas!$E$7,0))))) -> 8.8599 | K13: =I13-J13 -> 117.7101 | L13: =SUMIF(caju!$A$4:$A$562,total!B13,caju!$C$4:$C$2900) -> 500 | M13: =IF(E13>=0,IF(AND(E13>tabelas!$C$11,E13<=tabelas!$C$12),L13*tabelas!$E$11,IF(AND(E13>=tabelas!$C$12,E13<=tabelas!$C$13),L13*tabelas!$E$12,IF(AND(E13>=tabelas!$C$13,E13<=tabelas!$C$14),L13*tabelas!$E$13,IF(AND(E13>0,E13>tabelas!$C$14),L13*tabelas!$E$14,0))))) -> 10 | N13: =L13-M13 -> 490 | O13: =IFERROR(VLOOKUP(B13,segurodevida!$B$4:$E$588,4,0),0) -> 7.6834638 | P13: =O13/2 -> 3.8417319 | Q13: =O13-P13 -> 3.8417319 | V13: =IFERROR(VLOOKUP(B13,#REF!,3,0),0) -> 0 | W13: =SUMIF(#REF!,total!B13,#REF!) -> #REF! | X13: =IFERROR(VLOOKUP(B13,#REF!,4,0),0) -> 0 | Y13: =IFERROR(VLOOKUP(B13,#REF!,5,0),0) -> 0 | Z13: =IFERROR(X13-Y13,0) -> 0 | AA13: =IFERROR(VLOOKUP(B13,#REF!,3,0),0) -> 0 | AB13: =IFERROR(VLOOKUP(B13,#REF!,3,0),0) -> 0 | AC13: =IFERROR(VLOOKUP(B13,#REF!,5,0),0) -> 0 | AD13: 275 | AE13: =IFERROR(VLOOKUP(B13,#REF!,3,0),0) -> 0 | AF13: =IFERROR(VLOOKUP(B13,#REF!,3,0),0) -> 0 | AG13: =IFERROR(VLOOKUP(B13,#REF!,3,0),0) -> 0 | AK13: =IFERROR(VLOOKUP(B13,#REF!,3,0),0) -> 0 | AL13: =IFERROR(VLOOKUP(B13,ingles!$A$2:$C$673,3,0),"-") -> - | AM13: =ROUNDUP(IFERROR(AL13*39.39%,"0"),1) -> 0 | AN13: =IFERROR(AL13-AM13,"-") -> - | AO13: =SUMIFS(zenklub!I:I,zenklub!A:A,total!B13) -> 90.566667 | AP13: =SUMIF(zenklub!$A$49:$A$106,total!B13,zenklub!$I$49:$I$106) -> 23.9 | AQ13: =AO13-AP13 -> 66.666667 | AR13: =SUMIF([3]bradesco!$C:$C,B13,[3]bradesco!$M:$M) -> #VALUE! | AS13: =SUMIF([3]bradesco!$C:$C,B13,[3]bradesco!$V:$V) -> #VALUE! | AT13: =IFERROR(SUMIF([3]bradesco!$C:$C,B13,[3]bradesco!$Y:$Y),0) -> 0 | AU13: =SUMIF([4]bradesco!$C:$C,B13,[4]bradesco!$M:$M) -> #VALUE! | AV13: =SUMIF([4]bradesco!$C:$C,B13,[4]bradesco!$V:$V) -> #VALUE! | AW13: =AU13-AV13 -> #VALUE! | AX13: =IFERROR(VLOOKUP(B13,#REF!,3,0),0) -> 0 | AY13: =IFERROR(VLOOKUP(B13,#REF!,3,0),0) -> 0 | AZ13: =IFERROR(VLOOKUP(B13,#REF!,3,0),0) -> 0 | BA13: 0 | BB13: =IFERROR(VLOOKUP(B13,#REF!,3,0),0) -> 0 | BC13: =IF(E13>=0,IF(AND(E13>tabelas!$C$11,E13<=tabelas!$C$12),BB13*tabelas!$E$11,IF(AND(E13>=tabelas!$C$12,E13<=tabelas!$C$13),BB13*tabelas!$E$12,IF(AND(E13>=tabelas!$C$13,E13<=tabelas!$C$14),BB13*tabelas!$E$13,IF(AND(E13>0,E13>tabelas!$C$14),BB13*tabelas!$E$14,0))))) -> 0 | BD13: =BB13-BC13 -> 0 | BE13: =SUMIF(open_english!A:A,total!B13,open_english!C:C) -> 138.88889 | BF13: =SUMIF(open_english!A:A,total!B13,open_english!D:D) -> 96.56 | BG13: =SUMIF(open_english!A:A,total!B13,open_english!E:E) -> 42.328889 | BH13: =IFERROR(VLOOKUP(B13,gympass!$A$2:$F$527,6,0),"-") -> 166.66667 | BI13: =IFERROR(VLOOKUP(B13,#REF!,4,0),"-") -> - | BJ13: =IFERROR(VLOOKUP(B13,#REF!,3,0),0) -> 0 | BK13: =IF(E13>=0,IF(AND(E13>tabelas!$C$11,E13<=tabelas!$C$12),BJ13*tabelas!$E$11,IF(AND(E13>=tabelas!$C$12,E13<=tabelas!$C$13),BJ13*tabelas!$E$12,IF(AND(E13>=tabelas!$C$13,E13<=tabelas!$C$14),BJ13*tabelas!$E$13,IF(AND(E13>0,E13>tabelas!$C$14),BJ13*tabelas!$E$14,0))))) -> 0 | BL13: =BJ13-BK13 -> 0 | BM13: =IFERROR(INDEX(dif_sistel!L:L,MATCH(total!B13,dif_sistel!D:D,0)),0)+IFERROR(INDEX(dif_sistel!N:N,MATCH(total!B13,dif_sistel!D:D,0)),0) -> 0 | BN13: =IFERROR(VLOOKUP(B13,dif_sistel!$D$3:$X$257,21,0),0) -> 0 | BO13: =IFERROR(SUMIF(#REF!,total!B13,#REF!),"0") -> 0 | BP13: =IFERROR(SUMIF(#REF!,total!B13,#REF!),"0") -> 0
B14: 11 | C14: =VLOOKUP(B14,salario!$A$3:$C$195,2,0) -> ATIVO | D14: =VLOOKUP(B14,salario!$A$3:$C$195,3,0) -> Colaborador 11 | E14: =IFERROR(VLOOKUP(B14,salario!$A$3:$K$854,11,0), "0") -> 2335.03 | F14: =SUMIF([2]unimed!$AL:$AL,B14,[2]unimed!$AJ:$AJ) -> #VALUE! | G14: =SUMIF([2]unimed!$AL:$AL,B14,[2]unimed!$AQ:$AQ) -> #VALUE! | H14: =SUMIF([2]unimed!$AL:$AL,B14,[2]unimed!$AP:$AP) -> #VALUE! | I14: =IFERROR(VLOOKUP(B14,uniodonto!$B$3:$F$339,5,0),0) -> 126.57 | J14: =IF(E14>=0,IF(AND(E14>tabelas!$C$4,E14<=tabelas!$C$5),I14*tabelas!$E$4,IF(AND(E14>=tabelas!$C$5,E14<=tabelas!$C$6),I14*tabelas!$E$5,IF(AND(E14>=tabelas!$C$6,E14<=tabelas!$C$7),I14*tabelas!$E$6,IF(AND(E14>0,E14>tabelas!$C$7),I14*tabelas!$E$7,0))))) -> 8.8599 | K14: =I14-J14 -> 117.7101 | L14: =SUMIF(caju!$A$4:$A$562,total!B14,caju!$C$4:$C$2900) -> 500 | M14: =IF(E14>=0,IF(AND(E14>tabelas!$C$11,E14<=tabelas!$C$12),L14*tabelas!$E$11,IF(AND(E14>=tabelas!$C$12,E14<=tabelas!$C$13),L14*tabelas!$E$12,IF(AND(E14>=tabelas!$C$13,E14<=tabelas!$C$14),L14*tabelas!$E$13,IF(AND(E14>0,E14>tabelas!$C$14),L14*tabelas!$E$14,0))))) -> 10 | N14: =L14-M14 -> 490 | O14: =IFERROR(VLOOKUP(B14,segurodevida!$B$4:$E$588,4,0),0) -> 7.4604209 | P14: =O14/2 -> 3.7302104 | Q14: =O14-P14 -> 3.7302104 | V14: =IFERROR(VLOOKUP(B14,#REF!,3,0),0) -> 0 | W14: =SUMIF(#REF!,total!B14,#REF!) -> #REF! | X14: =IFERROR(VLOOKUP(B14,#REF!,4,0),0) -> 0 | Y14: =IFERROR(VLOOKUP(B14,#REF!,5,0),0) -> 0 | Z14: =IFERROR(X14-Y14,0) -> 0 | AA14: =IFERROR(VLOOKUP(B14,#REF!,3,0),0) -> 0 | AB14: =IFERROR(VLOOKUP(B14,#REF!,3,0),0) -> 0 | AC14: =IFERROR(VLOOKUP(B14,#REF!,5,0),0) -> 0 | AD14: 275 | AE14: =IFERROR(VLOOKUP(B14,#REF!,3,0),0) -> 0 | AF14: =IFERROR(VLOOKUP(B14,#REF!,3,0),0) -> 0 | AG14: =IFERROR(VLOOKUP(B14,#REF!,3,0),0) -> 0 | AK14: =IFERROR(VLOOKUP(B14,#REF!,3,0),0) -> 0 | AL14: =IFERROR(VLOOKUP(B14,ingles!$A$2:$C$673,3,0),"-") -> - | AM14: =ROUNDUP(IFERROR(AL14*39.39%,"0"),1) -> 0 | AN14: =IFERROR(AL14-AM14,"-") -> - | AO14: =SUMIFS(zenklub!I:I,zenklub!A:A,total!B14) -> 90.566667 | AP14: =SUMIF(zenklub!$A$49:$A$106,total!B14,zenklub!$I$49:$I$106) -> 23.9 | AQ14: =AO14-AP14 -> 66.666667 | AR14: =SUMIF([3]bradesco!$C:$C,B14,[3]bradesco!$M:$M) -> #VALUE! | AS14: =SUMIF([3]bradesco!$C:$C,B14,[3]bradesco!$V:$V) -> #VALUE! | AT14: =IFERROR(SUMIF([3]bradesco!$C:$C,B14,[3]bradesco!$Y:$Y),0) -> 0 | AU14: =SUMIF([4]bradesco!$C:$C,B14,[4]bradesco!$M:$M) -> #VALUE! | AV14: =SUMIF([4]bradesco!$C:$C,B14,[4]bradesco!$V:$V) -> #VALUE! | AW14: =AU14-AV14 -> #VALUE! | AX14: =IFERROR(VLOOKUP(B14,#REF!,3,0),0) -> 0 | AY14: =IFERROR(VLOOKUP(B14,#REF!,3,0),0) -> 0 | AZ14: =IFERROR(VLOOKUP(B14,#REF!,3,0),0) -> 0 | BA14: 0 | BB14: =IFERROR(VLOOKUP(B14,#REF!,3,0),0) -> 0 | BC14: =IF(E14>=0,IF(AND(E14>tabelas!$C$11,E14<=tabelas!$C$12),BB14*tabelas!$E$11,IF(AND(E14>=tabelas!$C$12,E14<=tabelas!$C$13),BB14*tabelas!$E$12,IF(AND(E14>=tabelas!$C$13,E14<=tabelas!$C$14),BB14*tabelas!$E$13,IF(AND(E14>0,E14>tabelas!$C$14),BB14*tabelas!$E$14,0))))) -> 0 | BD14: =BB14-BC14 -> 0 | BE14: =SUMIF(open_english!A:A,total!B14,open_english!C:C) -> 138.88889 | BF14: =SUMIF(open_english!A:A,total!B14,open_english!D:D) -> 96.56 | BG14: =SUMIF(open_english!A:A,total!B14,open_english!E:E) -> 42.328889 | BH14: =IFERROR(VLOOKUP(B14,gympass!$A$2:$F$527,6,0),"-") -> 166.66667 | BI14: =IFERROR(VLOOKUP(B14,#REF!,4,0),"-") -> - | BJ14: =IFERROR(VLOOKUP(B14,#REF!,3,0),0) -> 0 | BK14: =IF(E14>=0,IF(AND(E14>tabelas!$C$11,E14<=tabelas!$C$12),BJ14*tabelas!$E$11,IF(AND(E14>=tabelas!$C$12,E14<=tabelas!$C$13),BJ14*tabelas!$E$12,IF(AND(E14>=tabelas!$C$13,E14<=tabelas!$C$14),BJ14*tabelas!$E$13,IF(AND(E14>0,E14>tabelas!$C$14),BJ14*tabelas!$E$14,0))))) -> 0 | BL14: =BJ14-BK14 -> 0 | BM14: =IFERROR(INDEX(dif_sistel!L:L,MATCH(total!B14,dif_sistel!D:D,0)),0)+IFERROR(INDEX(dif_sistel!N:N,MATCH(total!B14,dif_sistel!D:D,0)),0) -> 0 | BN14: =IFERROR(VLOOKUP(B14,dif_sistel!$D$3:$X$257,21,0),0) -> 0 | BO14: =IFERROR(SUMIF(#REF!,total!B14,#REF!),"0") -> 0 | BP14: =IFERROR(SUMIF(#REF!,total!B14,#REF!),"0") -> 0
B15: 12 | C15: =VLOOKUP(B15,salario!$A$3:$C$195,2,0) -> ATIVO | D15: =VLOOKUP(B15,salario!$A$3:$C$195,3,0) -> Colaborador 12 | E15: =IFERROR(VLOOKUP(B15,salario!$A$3:$K$854,11,0), "0") -> 3290.79 | F15: =SUMIF([2]unimed!$AL:$AL,B15,[2]unimed!$AJ:$AJ) -> #VALUE! | G15: =SUMIF([2]unimed!$AL:$AL,B15,[2]unimed!$AQ:$AQ) -> #VALUE! | H15: =SUMIF([2]unimed!$AL:$AL,B15,[2]unimed!$AP:$AP) -> #VALUE! | I15: =IFERROR(VLOOKUP(B15,uniodonto!$B$3:$F$339,5,0),0) -> 42.19 | J15: =IF(E15>=0,IF(AND(E15>tabelas!$C$4,E15<=tabelas!$C$5),I15*tabelas!$E$4,IF(AND(E15>=tabelas!$C$5,E15<=tabelas!$C$6),I15*tabelas!$E$5,IF(AND(E15>=tabelas!$C$6,E15<=tabelas!$C$7),I15*tabelas!$E$6,IF(AND(E15>0,E15>tabelas!$C$7),I15*tabelas!$E$7,0))))) -> 2.9533 | K15: =I15-J15 -> 39.2367 | L15: =SUMIF(caju!$A$4:$A$562,total!B15,caju!$C$4:$C$2900) -> 500 | M15: =IF(E15>=0,IF(AND(E15>tabelas!$C$11,E15<=tabelas!$C$12),L15*tabelas!$E$11,IF(AND(E15>=tabelas!$C$12,E15<=tabelas!$C$13),L15*tabelas!$E$12,IF(AND(E15>=tabelas!$C$13,E15<=tabelas!$C$14),L15*tabelas!$E$13,IF(AND(E15>0,E15>tabelas!$C$14),L15*tabelas!$E$14,0))))) -> 10 | N15: =L15-M15 -> 490 | O15: =IFERROR(VLOOKUP(B15,segurodevida!$B$4:$E$588,4,0),0) -> 10.514074 | P15: =O15/2 -> 5.257037 | Q15: =O15-P15 -> 5.257037 | V15: =IFERROR(VLOOKUP(B15,#REF!,3,0),0) -> 0 | W15: =SUMIF(#REF!,total!B15,#REF!) -> #REF! | X15: =IFERROR(VLOOKUP(B15,#REF!,4,0),0) -> 0 | Y15: =IFERROR(VLOOKUP(B15,#REF!,5,0),0) -> 0 | Z15: =IFERROR(X15-Y15,0) -> 0 | AA15: =IFERROR(VLOOKUP(B15,#REF!,3,0),0) -> 0 | AB15: =IFERROR(VLOOKUP(B15,#REF!,3,0),0) -> 0 | AC15: =IFERROR(VLOOKUP(B15,#REF!,5,0),0) -> 0 | AD15: 275 | AE15: =IFERROR(VLOOKUP(B15,#REF!,3,0),0) -> 0 | AF15: =IFERROR(VLOOKUP(B15,#REF!,3,0),0) -> 0 | AG15: =IFERROR(VLOOKUP(B15,#REF!,3,0),0) -> 0 | AK15: =IFERROR(VLOOKUP(B15,#REF!,3,0),0) -> 0 | AL15: =IFERROR(VLOOKUP(B15,ingles!$A$2:$C$673,3,0),"-") -> - | AM15: =ROUNDUP(IFERROR(AL15*39.39%,"0"),1) -> 0 | AN15: =IFERROR(AL15-AM15,"-") -> - | AO15: =SUMIFS(zenklub!I:I,zenklub!A:A,total!B15) -> 90.566667 | AP15: =SUMIF(zenklub!$A$49:$A$106,total!B15,zenklub!$I$49:$I$106) -> 23.9 | AQ15: =AO15-AP15 -> 66.666667 | AR15: =SUMIF([3]bradesco!$C:$C,B15,[3]bradesco!$M:$M) -> #VALUE! | AS15: =SUMIF([3]bradesco!$C:$C,B15,[3]bradesco!$V:$V) -> #VALUE! | AT15: =IFERROR(SUMIF([3]bradesco!$C:$C,B15,[3]bradesco!$Y:$Y),0) -> 0 | AU15: =SUMIF([4]bradesco!$C:$C,B15,[4]bradesco!$M:$M) -> #VALUE! | AV15: =SUMIF([4]bradesco!$C:$C,B15,[4]bradesco!$V:$V) -> #VALUE! | AW15: =AU15-AV15 -> #VALUE! | AX15: =IFERROR(VLOOKUP(B15,#REF!,3,0),0) -> 0 | AY15: =IFERROR(VLOOKUP(B15,#REF!,3,0),0) -> 0 | AZ15: =IFERROR(VLOOKUP(B15,#REF!,3,0),0) -> 0 | BA15: 0 | BB15: =IFERROR(VLOOKUP(B15,#REF!,3,0),0) -> 0 | BC15: =IF(E15>=0,IF(AND(E15>tabelas!$C$11,E15<=tabelas!$C$12),BB15*tabelas!$E$11,IF(AND(E15>=tabelas!$C$12,E15<=tabelas!$C$13),BB15*tabelas!$E$12,IF(AND(E15>=tabelas!$C$13,E15<=tabelas!$C$14),BB15*tabelas!$E$13,IF(AND(E15>0,E15>tabelas!$C$14),BB15*tabelas!$E$14,0))))) -> 0 | BD15: =BB15-BC15 -> 0 | BE15: =SUMIF(open_english!A:A,total!B15,open_english!C:C) -> 138.88889 | BF15: =SUMIF(open_english!A:A,total!B15,open_english!D:D) -> 96.56 | BG15: =SUMIF(open_english!A:A,total!B15,open_english!E:E) -> 42.328889 | BH15: =IFERROR(VLOOKUP(B15,gympass!$A$2:$F$527,6,0),"-") -> 166.66667 | BI15: =IFERROR(VLOOKUP(B15,#REF!,4,0),"-") -> - | BJ15: =IFERROR(VLOOKUP(B15,#REF!,3,0),0) -> 0 | BK15: =IF(E15>=0,IF(AND(E15>tabelas!$C$11,E15<=tabelas!$C$12),BJ15*tabelas!$E$11,IF(AND(E15>=tabelas!$C$12,E15<=tabelas!$C$13),BJ15*tabelas!$E$12,IF(AND(E15>=tabelas!$C$13,E15<=tabelas!$C$14),BJ15*tabelas!$E$13,IF(AND(E15>0,E15>tabelas!$C$14),BJ15*tabelas!$E$14,0))))) -> 0 | BL15: =BJ15-BK15 -> 0 | BM15: =IFERROR(INDEX(dif_sistel!L:L,MATCH(total!B15,dif_sistel!D:D,0)),0)+IFERROR(INDEX(dif_sistel!N:N,MATCH(total!B15,dif_sistel!D:D,0)),0) -> 0 | BN15: =IFERROR(VLOOKUP(B15,dif_sistel!$D$3:$X$257,21,0),0) -> 0 | BO15: =IFERROR(SUMIF(#REF!,total!B15,#REF!),"0") -> 0 | BP15: =IFERROR(SUMIF(#REF!,total!B15,#REF!),"0") -> 0
B16: 13 | C16: =VLOOKUP(B16,salario!$A$3:$C$195,2,0) -> ATIVO | D16: =VLOOKUP(B16,salario!$A$3:$C$195,3,0) -> Colaborador 13 | E16: =IFERROR(VLOOKUP(B16,salario!$A$3:$K$854,11,0), "0") -> 1102.16 | F16: =SUMIF([2]unimed!$AL:$AL,B16,[2]unimed!$AJ:$AJ) -> #VALUE! | G16: =SUMIF([2]unimed!$AL:$AL,B16,[2]unimed!$AQ:$AQ) -> #VALUE! | H16: =SUMIF([2]unimed!$AL:$AL,B16,[2]unimed!$AP:$AP) -> #VALUE! | I16: =IFERROR(VLOOKUP(B16,uniodonto!$B$3:$F$339,5,0),0) -> 210.95 | J16: =IF(E16>=0,IF(AND(E16>tabelas!$C$4,E16<=tabelas!$C$5),I16*tabelas!$E$4,IF(AND(E16>=tabelas!$C$5,E16<=tabelas!$C$6),I16*tabelas!$E$5,IF(AND(E16>=tabelas!$C$6,E16<=tabelas!$C$7),I16*tabelas!$E$6,IF(AND(E16>0,E16>tabelas!$C$7),I16*tabelas!$E$7,0))))) -> 14.7665 | K16: =I16-J16 -> 196.1835 | L16: =SUMIF(caju!$A$4:$A$562,total!B16,caju!$C$4:$C$2900) -> 500 | M16: =IF(E16>=0,IF(AND(E16>tabelas!$C$11,E16<=tabelas!$C$12),L16*tabelas!$E$11,IF(AND(E16>=tabelas!$C$12,E16<=tabelas!$C$13),L16*tabelas!$E$12,IF(AND(E16>=tabelas!$C$13,E16<=tabelas!$C$14),L16*tabelas!$E$13,IF(AND(E16>0,E16>tabelas!$C$14),L16*tabelas!$E$14,0))))) -> 10 | N16: =L16-M16 -> 490 | O16: =IFERROR(VLOOKUP(B16,segurodevida!$B$4:$E$588,4,0),0) -> 3.5214012 | P16: =O16/2 -> 1.7607006 | Q16: =O16-P16 -> 1.7607006 | V16: =IFERROR(VLOOKUP(B16,#REF!,3,0),0) -> 0 | W16: =SUMIF(#REF!,total!B16,#REF!) -> #REF! | X16: =IFERROR(VLOOKUP(B16,#REF!,4,0),0) -> 0 | Y16: =IFERROR(VLOOKUP(B16,#REF!,5,0),0) -> 0 | Z16: =IFERROR(X16-Y16,0) -> 0 | AA16: =IFERROR(VLOOKUP(B16,#REF!,3,0),0) -> 0 | AB16: =IFERROR(VLOOKUP(B16,#REF!,3,0),0) -> 0 | AC16: =IFERROR(VLOOKUP(B16,#REF!,5,0),0) -> 0 | AD16: 275 | AE16: =IFERROR(VLOOKUP(B16,#REF!,3,0),0) -> 0 | AF16: =IFERROR(VLOOKUP(B16,#REF!,3,0),0) -> 0 | AG16: =IFERROR(VLOOKUP(B16,#REF!,3,0),0) -> 0 | AK16: =IFERROR(VLOOKUP(B16,#REF!,3,0),0) -> 0 | AL16: =IFERROR(VLOOKUP(B16,ingles!$A$2:$C$673,3,0),"-") -> 165 | AM16: =ROUNDUP(IFERROR(AL16*39.39%,"0"),1) -> 65 | AN16: =IFERROR(AL16-AM16,"-") -> 100 | AO16: =SUMIFS(zenklub!I:I,zenklub!A:A,total!B16) -> 90.566667 | AP16: =SUMIF(zenklub!$A$49:$A$106,total!B16,zenklub!$I$49:$I$106) -> 23.9 | AQ16: =AO16-AP16 -> 66.666667 | AR16: =SUMIF([3]bradesco!$C:$C,B16,[3]bradesco!$M:$M) -> #VALUE! | AS16: =SUMIF([3]bradesco!$C:$C,B16,[3]bradesco!$V:$V) -> #VALUE! | AT16: =IFERROR(SUMIF([3]bradesco!$C:$C,B16,[3]bradesco!$Y:$Y),0) -> 0 | AU16: =SUMIF([4]bradesco!$C:$C,B16,[4]bradesco!$M:$M) -> #VALUE! | AV16: =SUMIF([4]bradesco!$C:$C,B16,[4]bradesco!$V:$V) -> #VALUE! | AW16: =AU16-AV16 -> #VALUE! | AX16: =IFERROR(VLOOKUP(B16,#REF!,3,0),0) -> 0 | AY16: =IFERROR(VLOOKUP(B16,#REF!,3,0),0) -> 0 | AZ16: =IFERROR(VLOOKUP(B16,#REF!,3,0),0) -> 0 | BA16: 0 | BB16: =IFERROR(VLOOKUP(B16,#REF!,3,0),0) -> 0 | BC16: =IF(E16>=0,IF(AND(E16>tabelas!$C$11,E16<=tabelas!$C$12),BB16*tabelas!$E$11,IF(AND(E16>=tabelas!$C$12,E16<=tabelas!$C$13),BB16*tabelas!$E$12,IF(AND(E16>=tabelas!$C$13,E16<=tabelas!$C$14),BB16*tabelas!$E$13,IF(AND(E16>0,E16>tabelas!$C$14),BB16*tabelas!$E$14,0))))) -> 0 | BD16: =BB16-BC16 -> 0 | BE16: =SUMIF(open_english!A:A,total!B16,open_english!C:C) -> 138.88889 | BF16: =SUMIF(open_english!A:A,total!B16,open_english!D:D) -> 96.56 | BG16: =SUMIF(open_english!A:A,total!B16,open_english!E:E) -> 42.328889 | BH16: =IFERROR(VLOOKUP(B16,gympass!$A$2:$F$527,6,0),"-") -> 166.66667 | BI16: =IFERROR(VLOOKUP(B16,#REF!,4,0),"-") -> - | BJ16: =IFERROR(VLOOKUP(B16,#REF!,3,0),0) -> 0 | BK16: =IF(E16>=0,IF(AND(E16>tabelas!$C$11,E16<=tabelas!$C$12),BJ16*tabelas!$E$11,IF(AND(E16>=tabelas!$C$12,E16<=tabelas!$C$13),BJ16*tabelas!$E$12,IF(AND(E16>=tabelas!$C$13,E16<=tabelas!$C$14),BJ16*tabelas!$E$13,IF(AND(E16>0,E16>tabelas!$C$14),BJ16*tabelas!$E$14,0))))) -> 0 | BL16: =BJ16-BK16 -> 0 | BM16: =IFERROR(INDEX(dif_sistel!L:L,MATCH(total!B16,dif_sistel!D:D,0)),0)+IFERROR(INDEX(dif_sistel!N:N,MATCH(total!B16,dif_sistel!D:D,0)),0)+dif_sistel!R9 -> 0 | BN16: =IFERROR(VLOOKUP(B16,dif_sistel!$D$3:$X$257,21,0),0) -> 0 | BO16: =IFERROR(SUMIF(#REF!,total!B16,#REF!),"0") -> 0 | BP16: =IFERROR(SUMIF(#REF!,total!B16,#REF!),"0") -> 0
B17: 14 | C17: =VLOOKUP(B17,salario!$A$3:$C$195,2,0) -> ATIVO | D17: =VLOOKUP(B17,salario!$A$3:$C$195,3,0) -> Colaborador 14 | E17: =IFERROR(VLOOKUP(B17,salario!$A$3:$K$854,11,0), "0") -> 5617.18 | F17: =SUMIF([2]unimed!$AL:$AL,B17,[2]unimed!$AJ:$AJ) -> #VALUE! | G17: =SUMIF([2]unimed!$AL:$AL,B17,[2]unimed!$AQ:$AQ) -> #VALUE! | H17: =SUMIF([2]unimed!$AL:$AL,B17,[2]unimed!$AP:$AP) -> #VALUE! | I17: =IFERROR(VLOOKUP(B17,uniodonto!$B$3:$F$339,5,0),0) -> 210.95 | J17: =IF(E17>=0,IF(AND(E17>tabelas!$C$4,E17<=tabelas!$C$5),I17*tabelas!$E$4,IF(AND(E17>=tabelas!$C$5,E17<=tabelas!$C$6),I17*tabelas!$E$5,IF(AND(E17>=tabelas!$C$6,E17<=tabelas!$C$7),I17*tabelas!$E$6,IF(AND(E17>0,E17>tabelas!$C$7),I17*tabelas!$E$7,0))))) -> 31.6425 | K17: =I17-J17 -> 179.3075 | L17: =SUMIF(caju!$A$4:$A$562,total!B17,caju!$C$4:$C$2900) -> 550 | M17: =IF(E17>=0,IF(AND(E17>tabelas!$C$11,E17<=tabelas!$C$12),L17*tabelas!$E$11,IF(AND(E17>=tabelas!$C$12,E17<=tabelas!$C$13),L17*tabelas!$E$12,IF(AND(E17>=tabelas!$C$13,E17<=tabelas!$C$14),L17*tabelas!$E$13,IF(AND(E17>0,E17>tabelas!$C$14),L17*tabelas!$E$14,0))))) -> 33 | N17: =L17-M17 -> 517 | O17: =IFERROR(VLOOKUP(B17,segurodevida!$B$4:$E$588,4,0),0) -> 17.94689 | P17: =O17/2 -> 8.9734451 | Q17: =O17-P17 -> 8.9734451 | V17: =IFERROR(VLOOKUP(B17,#REF!,3,0),0) -> 0 | W17: =SUMIF(#REF!,total!B17,#REF!) -> #REF! | X17: =IFERROR(VLOOKUP(B17,#REF!,4,0),0) -> 0 | Y17: =IFERROR(VLOOKUP(B17,#REF!,5,0),0) -> 0 | Z17: =IFERROR(X17-Y17,0) -> 0 | AA17: =IFERROR(VLOOKUP(B17,#REF!,3,0),0) -> 0 | AB17: =IFERROR(VLOOKUP(B17,#REF!,3,0),0) -> 0 | AC17: =IFERROR(VLOOKUP(B17,#REF!,5,0),0) -> 0 | AD17: 275 | AE17: =IFERROR(VLOOKUP(B17,#REF!,3,0),0) -> 0 | AF17: =IFERROR(VLOOKUP(B17,#REF!,3,0),0) -> 0 | AG17: =IFERROR(VLOOKUP(B17,#REF!,3,0),0) -> 0 | AK17: =IFERROR(VLOOKUP(B17,#REF!,3,0),0) -> 0 | AL17: =IFERROR(VLOOKUP(B17,ingles!$A$2:$C$673,3,0),"-") -> 165 | AM17: =ROUNDUP(IFERROR(AL17*39.39%,"0"),1) -> 65 | AN17: =IFERROR(AL17-AM17,"-") -> 100 | AO17: =SUMIFS(zenklub!I:I,zenklub!A:A,total!B17) -> 90.566667 | AP17: =SUMIF(zenklub!$A$49:$A$106,total!B17,zenklub!$I$49:$I$106) -> 23.9 | AQ17: =AO17-AP17 -> 66.666667 | AR17: =SUMIF([3]bradesco!$C:$C,B17,[3]bradesco!$M:$M) -> #VALUE! | AS17: =SUMIF([3]bradesco!$C:$C,B17,[3]bradesco!$V:$V) -> #VALUE! | AT17: =IFERROR(SUMIF([3]bradesco!$C:$C,B17,[3]bradesco!$Y:$Y),0) -> 0 | AU17: =SUMIF([4]bradesco!$C:$C,B17,[4]bradesco!$M:$M) -> #VALUE! | AV17: =SUMIF([4]bradesco!$C:$C,B17,[4]bradesco!$V:$V) -> #VALUE! | AW17: =AU17-AV17 -> #VALUE! | AX17: =IFERROR(VLOOKUP(B17,#REF!,3,0),0) -> 0 | AY17: =IFERROR(VLOOKUP(B17,#REF!,3,0),0) -> 0 | AZ17: =IFERROR(VLOOKUP(B17,#REF!,3,0),0) -> 0 | BA17: 0 | BB17: =IFERROR(VLOOKUP(B17,#REF!,3,0),0) -> 0 | BC17: =IF(E17>=0,IF(AND(E17>tabelas!$C$11,E17<=tabelas!$C$12),BB17*tabelas!$E$11,IF(AND(E17>=tabelas!$C$12,E17<=tabelas!$C$13),BB17*tabelas!$E$12,IF(AND(E17>=tabelas!$C$13,E17<=tabelas!$C$14),BB17*tabelas!$E$13,IF(AND(E17>0,E17>tabelas!$C$14),BB17*tabelas!$E$14,0))))) -> 0 | BD17: =BB17-BC17 -> 0 | BE17: =SUMIF(open_english!A:A,total!B17,open_english!C:C) -> 138.88889 | BF17: =SUMIF(open_english!A:A,total!B17,open_english!D:D) -> 96.56 | BG17: =SUMIF(open_english!A:A,total!B17,open_english!E:E) -> 42.328889 | BH17: =IFERROR(VLOOKUP(B17,gympass!$A$2:$F$527,6,0),"-") -> 166.66667 | BI17: =IFERROR(VLOOKUP(B17,#REF!,4,0),"-") -> - | BJ17: =IFERROR(VLOOKUP(B17,#REF!,3,0),0) -> 0 | BK17: =IF(E17>=0,IF(AND(E17>tabelas!$C$11,E17<=tabelas!$C$12),BJ17*tabelas!$E$11,IF(AND(E17>=tabelas!$C$12,E17<=tabelas!$C$13),BJ17*tabelas!$E$12,IF(AND(E17>=tabelas!$C$13,E17<=tabelas!$C$14),BJ17*tabelas!$E$13,IF(AND(E17>0,E17>tabelas!$C$14),BJ17*tabelas!$E$14,0))))) -> 0 | BL17: =BJ17-BK17 -> 0 | BM17: =IFERROR(INDEX(dif_sistel!L:L,MATCH(total!B17,dif_sistel!D:D,0)),0)+IFERROR(INDEX(dif_sistel!N:N,MATCH(total!B17,dif_sistel!D:D,0)),0) -> 0 | BN17: =IFERROR(VLOOKUP(B17,dif_sistel!$D$3:$X$257,21,0),0) -> 0 | BO17: =IFERROR(SUMIF(#REF!,total!B17,#REF!),"0") -> 0 | BP17: =IFERROR(SUMIF(#REF!,total!B17,#REF!),"0") -> 0
